Workbook

Sheet Rekapitulace stavby
A1: Export Komplet | BA1: 2.0 | BB1: ZAMOK | BT1: False | BU1: False | BV1: {a19f1804-530b-42b9-90bc-e9b855663be3}
BS2: 0,01 | BT2: 21
BS3: 0,01 | BT3: 15
D4: REKAPITULACE STAVBY | AS4: v --- níže se nacházejí doplnkové a pomocné údaje k sestavám --- v | BE4: Návod na vyplnění | BS4: 0,001
D5: Kód: | K5: Z2021126 | BE5: Měnit lze pouze buňky se žlutým podbarvením!_x000D_ _x000D_ 1) na prvním listu Rekapitulace stavby vyplňte v sestavě_x000D_ _x000D_ a) Souhrnný list_x000D_ - údaje o Uchazeči_x000D_ (přenesou se do ostatních sestav i v jiných listech)_x000D_ _x000D_ b) Rekapitulace objektů_x000D_ - potřebné Ostatní náklady_x000D_ _x000D_ 2) na vybraných listech vyplňte v sestavě_x000D_ _x000D_ a) Krycí list_x000D_ - údaje o Uchazeči, pokud se liší od údajů o Uchazeči na Souhrnném listu_x000D_ (údaje se přenesou do ostatních sestav v daném listu)_x000D_ _x000D_ b) Rekapitulace rozpočtu_x000D_ - potřebné Ostatní náklady_x000D_ _x000D_ c) Celkové náklady za stavbu_x000D_ - ceny u položek_x000D_ - množství, pokud má žluté podbarvení_x000D_ - a v případě potřeby poznámku (ta je ve skrytém sloupci) | BS5: 0,01
D6: Stavba: | K6: Bytový soubor Libuše | BS6: 0,01
D7: KSO: | AK7: CC-CZ: | BS7: 0,01
D8: Místo: | K8: Praha | AK8: Datum: | AN8: 45000 | BS8: 0,01
BS9: 0,01
D10: Zadavatel: | AK10: IČ: | BS10: 0,01
E11: VELTON REAL ESTATE | AK11: DIČ: | BS11: 0,01
BS12: 0,01
D13: Uchazeč: | AK13: IČ: | AN13: 08004013 | BS13: 0,01
E14: DMG Stav a.s. | AK14: DIČ: | AN14: CZ 08004013 | BS14: 0,01
BS15: False
D16: Projektant: | AK16: IČ: | BS16: False
E17: ABMV World s.r.o | AK17: DIČ: | BS17: True
BS18: 0,01
D19: Zpracovatel: | AK19: IČ: | BS19: 0,01
E20: QSB s.r.o. | AK20: DIČ: | BS20: True
D22: Poznámka:
D26: Cena bez DPH | AK26: =ROUND(AG94,2) -> 2.4903099e+08
L28: Sazba daně | W28: Základ daně | AK28: Výše daně
D29: DPH | F29: základní | L29: 0.21 | W29: =ROUND(AZ94,2) -> 2.3558309e+08 | AK29: =ROUND(AV94,2) -> 49472449
F30: snížená | L30: 0.15 | W30: =ROUND(BA94,2) -> 13447899 | AK30: =ROUND(AW94,2) -> 2017184.9
F31: zákl. přenesená | L31: 0.21 | W31: =ROUND(BB94,2) -> 0 | AK31: 0
F32: sníž. přenesená | L32: 0.15 | W32: =ROUND(BC94,2) -> 0 | AK32: 0
F33: nulová | L33: 0 | W33: =ROUND(BD94,2) -> 0 | AK33: 0
D35: Cena s DPH | T35: v | X35: CZK | AK35: =SUM(AK26:AK33) -> 3.0052063e+08
D49: Projektant | AH49: Zpracovatel
D60: Datum a podpis: | V60: Razítko | AH60: Datum a podpis: | AM60: Razítko
D64: Objednavatel | AH64: Uchazeč
D75: Datum a podpis: | V75: Razítko | AH75: Datum a podpis: | AM75: Razítko
C82: REKAPITULACE OBJEKTŮ STAVBY A SOUPISŮ PRACÍ
C84: Kód: | L84: =K5 -> Z2021126
C85: Stavba: | L85: =K6 -> Bytový soubor Libuše
C87: Místo: | L87: =IF(K8="","",K8) -> Praha | AI87: Datum: | AM87: =IF(AN8="","",AN8) -> 45000
C89: Zadavatel: | L89: =IF(E11="","",E11) -> VELTON REAL ESTATE | AI89: Projektant: | AM89: =IF(E17="","",E17) -> ABMV World s.r.o | AS89: Informatívní údaje z listů zakázek
C90: Uchazeč: | L90: =IF(E14="Vyplň údaj","",E14) -> DMG Stav a.s. | AI90: Zpracovatel: | AM90: =IF(E20="","",E20) -> QSB s.r.o.
C92: Kód | I92: Popis | AG92: Cena bez DPH [CZK] | AN92: Cena s DPH [CZK] | AQ92: Typ | AS92: z toho Ostat._x000D_ náklady [CZK] | AT92: DPH [CZK] | AU92: Normohodiny [h] | AV92: DPH základní [CZK] | AW92: DPH snížená [CZK] | AX92: DPH základní přenesená_x000D_ [CZK] | AY92: DPH snížená přenesená_x000D_ [CZK] | AZ92: Základna_x000D_ DPH základní | BA92: Základna_x000D_ DPH snížená | BB92: Základna_x000D_ DPH zákl. přenesená | BC92: Základna_x000D_ DPH sníž. přenesená | BD92: Základna_x000D_ DPH nulová
...

Sheet 00 - Vedlejší a ostatní n...
AT2: {ffb2632c-9a12-46c0-9a7a-cc4af88f22d9}
AT3: 2
D4: KRYCÍ LIST SOUPISU PRACÍ | M4: v --- níže se nacházejí doplnkové a pomocné údaje k sestavám --- v | AT4: False
D6: Stavba:
E7: ='Rekapitulace stavby'!K6 -> Bytový soubor Libuše
D8: Objekt:
E9: 00 - Vedlejší a ostatní náklady
D11: KSO: | I11: CC-CZ:
D12: Místo: | F12: Praha | I12: Datum: | J12: ='Rekapitulace stavby'!AN8 -> 45000
D14: Zadavatel: | I14: IČ:
E15: VELTON REAL ESTATE | I15: DIČ:
D17: Uchazeč: | I17: IČ: | J17: ='Rekapitulace stavby'!AN13 -> 08004013
E18: ='Rekapitulace stavby'!E14 -> DMG Stav a.s. | I18: DIČ: | J18: ='Rekapitulace stavby'!AN14 -> CZ 08004013
D20: Projektant: | I20: IČ:
E21: ABMV World s.r.o | I21: DIČ:
D23: Zpracovatel: | I23: IČ:
E24: QSB s.r.o. | I24: DIČ:
D26: Poznámka:
D30: Cena bez DPH | J30: =ROUND(J122,2) -> 9759000
F32: Základ daně | I32: Sazba daně | J32: Výše daně
D33: DPH | E33: základní | F33: =ROUND((SUM(BE122:BE147)),2) -> 9759000 | I33: 0.21 | J33: =ROUND(((SUM(BE122:BE147))*I33),2) -> 2049390
E34: snížená | F34: =ROUND((SUM(BF122:BF147)),2) -> 0 | I34: 0.15 | J34: =ROUND(((SUM(BF122:BF147))*I34),2) -> 0
E35: zákl. přenesená | F35: =ROUND((SUM(BG122:BG147)),2) -> 0 | I35: 0.21 | J35: =0 -> 0
E36: sníž. přenesená | F36: =ROUND((SUM(BH122:BH147)),2) -> 0 | I36: 0.15 | J36: =0 -> 0
E37: nulová | F37: =ROUND((SUM(BI122:BI147)),2) -> 0 | I37: 0 | J37: =0 -> 0
D39: Cena s DPH | G39: v | H39: CZK | J39: =SUM(J30:J37) -> 11808390
D50: Projektant | G50: Zpracovatel
D61: Datum a podpis: | F61: Razítko | G61: Datum a podpis: | J61: Razítko
D65: Objednavatel | G65: Uchazeč
D76: Datum a podpis: | F76: Razítko | G76: Datum a podpis: | J76: Razítko
C82: REKAPITULACE ČLENĚNÍ SOUPISU PRACÍ
C84: Stavba:
E85: =E7 -> Bytový soubor Libuše
C86: Objekt:
E87: =E9 -> 00 - Vedlejší a ostatní náklady
C89: Místo: | F89: =F12 -> Praha | I89: Datum: | J89: =IF(J12="","",J12) -> 45000
C91: Zadavatel: | F91: =E15 -> VELTON REAL ESTATE | I91: Projektant: | J91: =E21 -> ABMV World s.r.o
C92: Uchazeč: | F92: =IF(E18="","",E18) -> DMG Stav a.s. | I92: Zpracovatel: | J92: =E24 -> QSB s.r.o.
C94: Kód dílu - Popis | J94: Cena celkem [CZK]
C96: Náklady ze soupisu prací | J96: =J122 -> 9759000 | AU96: -1
...

Sheet 100 - Architektonicko-sta...
AT2: {519219ae-6ce4-40eb-a262-06e9229d6b1d} | AZ2: CF10 | BB2: m2 | BC2: 181,94 | BD2: 2
AT3: 2 | AZ3: FF10 | BB3: m2 | BC3: 1058,4 | BD3: 2
D4: KRYCÍ LIST SOUPISU PRACÍ | M4: v --- níže se nacházejí doplnkové a pomocné údaje k sestavám --- v | AT4: False | AZ4: FF20 | BB4: m2 | BC4: 405,86 | BD4: 2
AZ5: FF21 | BB5: m2 | BC5: 461,5 | BD5: 2
D6: Stavba: | AZ6: FF30 | BB6: m2 | BC6: 577,5 | BD6: 2
E7: ='Rekapitulace stavby'!K6 -> Bytový soubor Libuše | AZ7: FF31 | BB7: m2 | BC7: 1169,23 | BD7: 2
D8: Objekt: | AZ8: RF10 | BB8: m2 | BC8: 730,85 | BD8: 2
E9: 01 - Bytové domy A, B, C, D vč. podzemního podlaží | AZ9: RF11 | BB9: m2 | BC9: 247,51 | BD9: 2
D10: Soupis: | AZ10: RF12 | BB10: m2 | BC10: 431,26 | BD10: 2
E11: 100 - Architektonicko-stavební a konstrukční část | AZ11: RF13 | BB11: m2 | BC11: 44,6 | BD11: 2
AZ12: RF14 | BB12: m2 | BC12: 32,97 | BD12: 2
D13: KSO: | I13: CC-CZ: | AZ13: RF20 | BB13: m2 | BC13: 185,99 | BD13: 2
D14: Místo: | F14: Praha | I14: Datum: | J14: ='Rekapitulace stavby'!AN8 -> 45000 | AZ14: RF21 | BB14: m2 | BC14: 74,66 | BD14: 2
AZ15: RF22 | BB15: m2 | BC15: 30,14 | BD15: 2
D16: Zadavatel: | I16: IČ: | AZ16: vap_omi | BB16: m2 | BC16: 1217,07 | BD16: 2
E17: VELTON REAL ESTATE | I17: DIČ: | AZ17: WF02 | BB17: m2 | BC17: 281,062 | BD17: 2
AZ18: WF03 | BB18: m2 | BC18: 84,525 | BD18: 2
D19: Uchazeč: | I19: IČ: | J19: ='Rekapitulace stavby'!AN13 -> 08004013 | AZ19: WF17_omi | BB19: m2 | BC19: 71,016 | BD19: 2
E20: ='Rekapitulace stavby'!E14 -> DMG Stav a.s. | I20: DIČ: | J20: ='Rekapitulace stavby'!AN14 -> CZ 08004013 | AZ20: WF18_omi | BB20: m2 | BC20: 28,829 | BD20: 2
AZ21: WF19_omi | BB21: m2 | BC21: 12,862 | BD21: 2
D22: Projektant: | I22: IČ: | AZ22: WF22 | BB22: m2 | BC22: 183,6 | BD22: 2
E23: ABMV World s.r.o | I23: DIČ:
D25: Zpracovatel: | I25: IČ:
E26: QSB s.r.o. | I26: DIČ:
D28: Poznámka:
D32: Cena bez DPH | J32: =ROUND(J148,2) -> 1.8365574e+08
F34: Základ daně | I34: Sazba daně | J34: Výše daně
D35: DPH | E35: základní | F35: =ROUND((SUM(BE148:BE2681)),2) -> 1.8365574e+08 | I35: 0.21 | J35: =ROUND(((SUM(BE148:BE2681))*I35),2) -> 38567706
E36: snížená | F36: =ROUND((SUM(BF148:BF2681)),2) -> 0 | I36: 0.15 | J36: =ROUND(((SUM(BF148:BF2681))*I36),2) -> 0
E37: zákl. přenesená | F37: =ROUND((SUM(BG148:BG2681)),2) -> 0 | I37: 0.21 | J37: =0 -> 0
E38: sníž. přenesená | F38: =ROUND((SUM(BH148:BH2681)),2) -> 0 | I38: 0.15 | J38: =0 -> 0
E39: nulová | F39: =ROUND((SUM(BI148:BI2681)),2) -> 0 | I39: 0 | J39: =0 -> 0
D41: Cena s DPH | G41: v | H41: CZK | J41: =SUM(J32:J39) -> 2.2222345e+08
D50: Projektant | G50: Zpracovatel
D61: Datum a podpis: | F61: Razítko | G61: Datum a podpis: | J61: Razítko
D65: Objednavatel | G65: Uchazeč
D76: Datum a podpis: | F76: Razítko | G76: Datum a podpis: | J76: Razítko
C82: REKAPITULACE ČLENĚNÍ SOUPISU PRACÍ
C84: Stavba:
E85: =E7 -> Bytový soubor Libuše
...

Sheet D1.410 - ZTI - Kanalizace
AT2: {84a7c1b6-7f2a-49f5-be57-afab49f93126}
AT3: 2
D4: KRYCÍ LIST SOUPISU PRACÍ | M4: v --- níže se nacházejí doplnkové a pomocné údaje k sestavám --- v | AT4: False
D6: Stavba:
E7: ='Rekapitulace stavby'!K6 -> Bytový soubor Libuše
D8: Objekt:
E9: 01 - Bytové domy A, B, C, D vč. podzemního podlaží
D10: Soupis:
E11: D1.410 - ZTI - Kanalizace
D13: KSO: | I13: CC-CZ:
D14: Místo: | F14: Praha | I14: Datum: | J14: ='Rekapitulace stavby'!AN8 -> 45000
D16: Zadavatel: | I16: IČ:
E17: VELTON REAL ESTATE | I17: DIČ:
D19: Uchazeč: | I19: IČ: | J19: ='Rekapitulace stavby'!AN13 -> 08004013
E20: ='Rekapitulace stavby'!E14 -> DMG Stav a.s. | I20: DIČ: | J20: ='Rekapitulace stavby'!AN14 -> CZ 08004013
D22: Projektant: | I22: IČ:
E23: ABMV World s.r.o | I23: DIČ:
D25: Zpracovatel: | I25: IČ:
E26: QSB s.r.o. | I26: DIČ:
D28: Poznámka:
D32: Cena bez DPH | J32: =ROUND(J130,2) -> 5975260
F34: Základ daně | I34: Sazba daně | J34: Výše daně
D35: DPH | E35: základní | F35: =ROUND((SUM(BE130:BE191)),2) -> 5975260 | I35: 0.21 | J35: =ROUND(((SUM(BE130:BE191))*I35),2) -> 1254804.6
E36: snížená | F36: =ROUND((SUM(BF130:BF191)),2) -> 0 | I36: 0.15 | J36: =ROUND(((SUM(BF130:BF191))*I36),2) -> 0
E37: zákl. přenesená | F37: =ROUND((SUM(BG130:BG191)),2) -> 0 | I37: 0.21 | J37: =0 -> 0
E38: sníž. přenesená | F38: =ROUND((SUM(BH130:BH191)),2) -> 0 | I38: 0.15 | J38: =0 -> 0
E39: nulová | F39: =ROUND((SUM(BI130:BI191)),2) -> 0 | I39: 0 | J39: =0 -> 0
D41: Cena s DPH | G41: v | H41: CZK | J41: =SUM(J32:J39) -> 7230064.6
D50: Projektant | G50: Zpracovatel
D61: Datum a podpis: | F61: Razítko | G61: Datum a podpis: | J61: Razítko
D65: Objednavatel | G65: Uchazeč
D76: Datum a podpis: | F76: Razítko | G76: Datum a podpis: | J76: Razítko
C82: REKAPITULACE ČLENĚNÍ SOUPISU PRACÍ
C84: Stavba:
E85: =E7 -> Bytový soubor Libuše
C86: Objekt:
E87: 01 - Bytové domy A, B, C, D vč. podzemního podlaží
C88: Soupis:
E89: =E11 -> D1.410 - ZTI - Kanalizace
C91: Místo: | F91: =F14 -> Praha | I91: Datum: | J91: =IF(J14="","",J14) -> 45000
...

Sheet D1.420 - ZTI - Vodovod
AT2: {10486c3d-a2f1-46fb-9c38-f92f128710a0}
AT3: 2
D4: KRYCÍ LIST SOUPISU PRACÍ | M4: v --- níže se nacházejí doplnkové a pomocné údaje k sestavám --- v | AT4: False
D6: Stavba:
E7: ='Rekapitulace stavby'!K6 -> Bytový soubor Libuše
D8: Objekt:
E9: 01 - Bytové domy A, B, C, D vč. podzemního podlaží
D10: Soupis:
E11: D1.420 - ZTI - Vodovod
D13: KSO: | I13: CC-CZ:
D14: Místo: | F14: Praha | I14: Datum: | J14: ='Rekapitulace stavby'!AN8 -> 45000
D16: Zadavatel: | I16: IČ:
E17: VELTON REAL ESTATE | I17: DIČ:
D19: Uchazeč: | I19: IČ: | J19: ='Rekapitulace stavby'!AN13 -> 08004013
E20: ='Rekapitulace stavby'!E14 -> DMG Stav a.s. | I20: DIČ: | J20: ='Rekapitulace stavby'!AN14 -> CZ 08004013
D22: Projektant: | I22: IČ:
E23: ABMV World s.r.o | I23: DIČ:
D25: Zpracovatel: | I25: IČ:
E26: QSB s.r.o. | I26: DIČ:
D28: Poznámka:
D32: Cena bez DPH | J32: =ROUND(J124,2) -> 6593470
F34: Základ daně | I34: Sazba daně | J34: Výše daně
D35: DPH | E35: základní | F35: =ROUND((SUM(BE124:BE220)),2) -> 6593470 | I35: 0.21 | J35: =ROUND(((SUM(BE124:BE220))*I35),2) -> 1384628.7
E36: snížená | F36: =ROUND((SUM(BF124:BF220)),2) -> 0 | I36: 0.15 | J36: =ROUND(((SUM(BF124:BF220))*I36),2) -> 0
E37: zákl. přenesená | F37: =ROUND((SUM(BG124:BG220)),2) -> 0 | I37: 0.21 | J37: =0 -> 0
E38: sníž. přenesená | F38: =ROUND((SUM(BH124:BH220)),2) -> 0 | I38: 0.15 | J38: =0 -> 0
E39: nulová | F39: =ROUND((SUM(BI124:BI220)),2) -> 0 | I39: 0 | J39: =0 -> 0
D41: Cena s DPH | G41: v | H41: CZK | J41: =SUM(J32:J39) -> 7978098.7
D50: Projektant | G50: Zpracovatel
D61: Datum a podpis: | F61: Razítko | G61: Datum a podpis: | J61: Razítko
D65: Objednavatel | G65: Uchazeč
D76: Datum a podpis: | F76: Razítko | G76: Datum a podpis: | J76: Razítko
C82: REKAPITULACE ČLENĚNÍ SOUPISU PRACÍ
C84: Stavba:
E85: =E7 -> Bytový soubor Libuše
C86: Objekt:
E87: 01 - Bytové domy A, B, C, D vč. podzemního podlaží
C88: Soupis:
E89: =E11 -> D1.420 - ZTI - Vodovod
C91: Místo: | F91: =F14 -> Praha | I91: Datum: | J91: =IF(J14="","",J14) -> 45000
...

Sheet D1.430 - ZTI - Plynovod
AT2: {69e6767c-f311-4783-b791-3ac752473af5}
AT3: 2
D4: KRYCÍ LIST SOUPISU PRACÍ | M4: v --- níže se nacházejí doplnkové a pomocné údaje k sestavám --- v | AT4: False
D6: Stavba:
E7: ='Rekapitulace stavby'!K6 -> Bytový soubor Libuše
D8: Objekt:
E9: 01 - Bytové domy A, B, C, D vč. podzemního podlaží
D10: Soupis:
E11: D1.430 - ZTI - Plynovod
D13: KSO: | I13: CC-CZ:
D14: Místo: | F14: Praha | I14: Datum: | J14: ='Rekapitulace stavby'!AN8 -> 45000
D16: Zadavatel: | I16: IČ:
E17: VELTON REAL ESTATE | I17: DIČ:
D19: Uchazeč: | I19: IČ: | J19: ='Rekapitulace stavby'!AN13 -> 08004013
E20: ='Rekapitulace stavby'!E14 -> DMG Stav a.s. | I20: DIČ: | J20: ='Rekapitulace stavby'!AN14 -> CZ 08004013
D22: Projektant: | I22: IČ:
E23: ABMV World s.r.o | I23: DIČ:
D25: Zpracovatel: | I25: IČ:
E26: QSB s.r.o. | I26: DIČ:
D28: Poznámka:
D32: Cena bez DPH | J32: =ROUND(J122,2) -> 78000
F34: Základ daně | I34: Sazba daně | J34: Výše daně
D35: DPH | E35: základní | F35: =ROUND((SUM(BE122:BE164)),2) -> 78000 | I35: 0.21 | J35: =ROUND(((SUM(BE122:BE164))*I35),2) -> 16380
E36: snížená | F36: =ROUND((SUM(BF122:BF164)),2) -> 0 | I36: 0.15 | J36: =ROUND(((SUM(BF122:BF164))*I36),2) -> 0
E37: zákl. přenesená | F37: =ROUND((SUM(BG122:BG164)),2) -> 0 | I37: 0.21 | J37: =0 -> 0
E38: sníž. přenesená | F38: =ROUND((SUM(BH122:BH164)),2) -> 0 | I38: 0.15 | J38: =0 -> 0
E39: nulová | F39: =ROUND((SUM(BI122:BI164)),2) -> 0 | I39: 0 | J39: =0 -> 0
D41: Cena s DPH | G41: v | H41: CZK | J41: =SUM(J32:J39) -> 94380
D50: Projektant | G50: Zpracovatel
D61: Datum a podpis: | F61: Razítko | G61: Datum a podpis: | J61: Razítko
D65: Objednavatel | G65: Uchazeč
D76: Datum a podpis: | F76: Razítko | G76: Datum a podpis: | J76: Razítko
C82: REKAPITULACE ČLENĚNÍ SOUPISU PRACÍ
C84: Stavba:
E85: =E7 -> Bytový soubor Libuše
C86: Objekt:
E87: 01 - Bytové domy A, B, C, D vč. podzemního podlaží
C88: Soupis:
E89: =E11 -> D1.430 - ZTI - Plynovod
C91: Místo: | F91: =F14 -> Praha | I91: Datum: | J91: =IF(J14="","",J14) -> 45000
...

Sheet D1.510 - Vzduchotechnika
AT2: {c9dfe3ad-13fb-40cc-bd79-bc5ce546b322}
AT3: 2
D4: KRYCÍ LIST SOUPISU PRACÍ | M4: v --- níže se nacházejí doplnkové a pomocné údaje k sestavám --- v | AT4: False
D6: Stavba:
E7: ='Rekapitulace stavby'!K6 -> Bytový soubor Libuše
D8: Objekt:
E9: 01 - Bytové domy A, B, C, D vč. podzemního podlaží
D10: Soupis:
E11: D1.510 - Vzduchotechnika
D13: KSO: | I13: CC-CZ:
D14: Místo: | F14: Praha | I14: Datum: | J14: ='Rekapitulace stavby'!AN8 -> 45000
D16: Zadavatel: | I16: IČ:
E17: VELTON REAL ESTATE | I17: DIČ:
D19: Uchazeč: | I19: IČ: | J19: ='Rekapitulace stavby'!AN13 -> 08004013
E20: ='Rekapitulace stavby'!E14 -> DMG Stav a.s. | I20: DIČ: | J20: ='Rekapitulace stavby'!AN14 -> CZ 08004013
D22: Projektant: | I22: IČ:
E23: ABMV World s.r.o | I23: DIČ:
D25: Zpracovatel: | I25: IČ:
E26: QSB s.r.o. | I26: DIČ:
D28: Poznámka:
D32: Cena bez DPH | J32: =ROUND(J150,2) -> 3746900
F34: Základ daně | I34: Sazba daně | J34: Výše daně
D35: DPH | E35: základní | F35: =ROUND((SUM(BE150:BE427)),2) -> 3746900 | I35: 0.21 | J35: =ROUND(((SUM(BE150:BE427))*I35),2) -> 786849
E36: snížená | F36: =ROUND((SUM(BF150:BF427)),2) -> 0 | I36: 0.15 | J36: =ROUND(((SUM(BF150:BF427))*I36),2) -> 0
E37: zákl. přenesená | F37: =ROUND((SUM(BG150:BG427)),2) -> 0 | I37: 0.21 | J37: =0 -> 0
E38: sníž. přenesená | F38: =ROUND((SUM(BH150:BH427)),2) -> 0 | I38: 0.15 | J38: =0 -> 0
E39: nulová | F39: =ROUND((SUM(BI150:BI427)),2) -> 0 | I39: 0 | J39: =0 -> 0
D41: Cena s DPH | G41: v | H41: CZK | J41: =SUM(J32:J39) -> 4533749
D50: Projektant | G50: Zpracovatel
D61: Datum a podpis: | F61: Razítko | G61: Datum a podpis: | J61: Razítko
D65: Objednavatel | G65: Uchazeč
D76: Datum a podpis: | F76: Razítko | G76: Datum a podpis: | J76: Razítko
C82: REKAPITULACE ČLENĚNÍ SOUPISU PRACÍ
C84: Stavba:
E85: =E7 -> Bytový soubor Libuše
C86: Objekt:
E87: 01 - Bytové domy A, B, C, D vč. podzemního podlaží
C88: Soupis:
E89: =E11 -> D1.510 - Vzduchotechnika
C91: Místo: | F91: =F14 -> Praha | I91: Datum: | J91: =IF(J14="","",J14) -> 45000
...

Sheet D1.520 - Rozvody chladu
AT2: {8e6ed8be-8277-45a1-8ce1-1a62c411eb53}
AT3: 2
D4: KRYCÍ LIST SOUPISU PRACÍ | M4: v --- níže se nacházejí doplnkové a pomocné údaje k sestavám --- v | AT4: False
D6: Stavba:
E7: ='Rekapitulace stavby'!K6 -> Bytový soubor Libuše
D8: Objekt:
E9: 01 - Bytové domy A, B, C, D vč. podzemního podlaží
D10: Soupis:
E11: D1.520 - Rozvody chladu
D13: KSO: | I13: CC-CZ:
D14: Místo: | F14: Praha | I14: Datum: | J14: ='Rekapitulace stavby'!AN8 -> 45000
D16: Zadavatel: | I16: IČ:
E17: VELTON REAL ESTATE | I17: DIČ:
D19: Uchazeč: | I19: IČ: | J19: ='Rekapitulace stavby'!AN13 -> 08004013
E20: ='Rekapitulace stavby'!E14 -> DMG Stav a.s. | I20: DIČ: | J20: ='Rekapitulace stavby'!AN14 -> CZ 08004013
D22: Projektant: | I22: IČ:
E23: ABMV World s.r.o | I23: DIČ:
D25: Zpracovatel: | I25: IČ:
E26: QSB s.r.o. | I26: DIČ:
D28: Poznámka:
D32: Cena bez DPH | J32: =ROUND(J144,2) -> 5661300
F34: Základ daně | I34: Sazba daně | J34: Výše daně
D35: DPH | E35: základní | F35: =ROUND((SUM(BE144:BE330)),2) -> 5661300 | I35: 0.21 | J35: =ROUND(((SUM(BE144:BE330))*I35),2) -> 1188873
E36: snížená | F36: =ROUND((SUM(BF144:BF330)),2) -> 0 | I36: 0.15 | J36: =ROUND(((SUM(BF144:BF330))*I36),2) -> 0
E37: zákl. přenesená | F37: =ROUND((SUM(BG144:BG330)),2) -> 0 | I37: 0.21 | J37: =0 -> 0
E38: sníž. přenesená | F38: =ROUND((SUM(BH144:BH330)),2) -> 0 | I38: 0.15 | J38: =0 -> 0
E39: nulová | F39: =ROUND((SUM(BI144:BI330)),2) -> 0 | I39: 0 | J39: =0 -> 0
D41: Cena s DPH | G41: v | H41: CZK | J41: =SUM(J32:J39) -> 6850173
D50: Projektant | G50: Zpracovatel
D61: Datum a podpis: | F61: Razítko | G61: Datum a podpis: | J61: Razítko
D65: Objednavatel | G65: Uchazeč
D76: Datum a podpis: | F76: Razítko | G76: Datum a podpis: | J76: Razítko
C82: REKAPITULACE ČLENĚNÍ SOUPISU PRACÍ
C84: Stavba:
E85: =E7 -> Bytový soubor Libuše
C86: Objekt:
E87: 01 - Bytové domy A, B, C, D vč. podzemního podlaží
C88: Soupis:
E89: =E11 -> D1.520 - Rozvody chladu
C91: Místo: | F91: =F14 -> Praha | I91: Datum: | J91: =IF(J14="","",J14) -> 45000
...

Sheet D1.530 - ÚT - Rozvody tepla
AT2: {8d236109-306f-48c2-9595-75be6e0d0de9}
AT3: 2
D4: KRYCÍ LIST SOUPISU PRACÍ | M4: v --- níže se nacházejí doplnkové a pomocné údaje k sestavám --- v | AT4: False
D6: Stavba:
E7: ='Rekapitulace stavby'!K6 -> Bytový soubor Libuše
D8: Objekt:
E9: 01 - Bytové domy A, B, C, D vč. podzemního podlaží
D10: Soupis:
E11: D1.530 - ÚT - Rozvody tepla
D13: KSO: | I13: CC-CZ:
D14: Místo: | F14: Praha | I14: Datum: | J14: ='Rekapitulace stavby'!AN8 -> 45000
D16: Zadavatel: | I16: IČ:
E17: VELTON REAL ESTATE | I17: DIČ:
D19: Uchazeč: | I19: IČ: | J19: ='Rekapitulace stavby'!AN13 -> 08004013
E20: ='Rekapitulace stavby'!E14 -> DMG Stav a.s. | I20: DIČ: | J20: ='Rekapitulace stavby'!AN14 -> CZ 08004013
D22: Projektant: | I22: IČ:
E23: ABMV World s.r.o | I23: DIČ:
D25: Zpracovatel: | I25: IČ:
E26: QSB s.r.o. | I26: DIČ:
D28: Poznámka:
D32: Cena bez DPH | J32: =ROUND(J150,2) -> 3569260
F34: Základ daně | I34: Sazba daně | J34: Výše daně
D35: DPH | E35: základní | F35: =ROUND((SUM(BE150:BE309)),2) -> 3569260 | I35: 0.21 | J35: =ROUND(((SUM(BE150:BE309))*I35),2) -> 749544.6
E36: snížená | F36: =ROUND((SUM(BF150:BF309)),2) -> 0 | I36: 0.15 | J36: =ROUND(((SUM(BF150:BF309))*I36),2) -> 0
E37: zákl. přenesená | F37: =ROUND((SUM(BG150:BG309)),2) -> 0 | I37: 0.21 | J37: =0 -> 0
E38: sníž. přenesená | F38: =ROUND((SUM(BH150:BH309)),2) -> 0 | I38: 0.15 | J38: =0 -> 0
E39: nulová | F39: =ROUND((SUM(BI150:BI309)),2) -> 0 | I39: 0 | J39: =0 -> 0
D41: Cena s DPH | G41: v | H41: CZK | J41: =SUM(J32:J39) -> 4318804.6
D50: Projektant | G50: Zpracovatel
D61: Datum a podpis: | F61: Razítko | G61: Datum a podpis: | J61: Razítko
D65: Objednavatel | G65: Uchazeč
D76: Datum a podpis: | F76: Razítko | G76: Datum a podpis: | J76: Razítko
C82: REKAPITULACE ČLENĚNÍ SOUPISU PRACÍ
C84: Stavba:
E85: =E7 -> Bytový soubor Libuše
C86: Objekt:
E87: 01 - Bytové domy A, B, C, D vč. podzemního podlaží
C88: Soupis:
E89: =E11 -> D1.530 - ÚT - Rozvody tepla
C91: Místo: | F91: =F14 -> Praha | I91: Datum: | J91: =IF(J14="","",J14) -> 45000
...

Sheet D1.610 - Uzemnění a hromo...
AT2: {d671aba4-2fad-4021-b32b-2947f8570988}
AT3: 1
D4: KRYCÍ LIST SOUPISU PRACÍ | M4: v --- níže se nacházejí doplnkové a pomocné údaje k sestavám --- v | AT4: False
D6: Stavba:
E7: ='Rekapitulace stavby'!K6 -> Bytový soubor Libuše
D8: Objekt:
E9: 01 - Bytové domy A, B, C, D vč. podzemního podlaží
D10: Soupis:
E11: D1.610 - Uzemnění a hromosvod
D13: KSO: | I13: CC-CZ:
D14: Místo: | F14: Praha | I14: Datum: | J14: ='Rekapitulace stavby'!AN8 -> 45000
D16: Zadavatel: | I16: IČ:
E17: VELTON REAL ESTATE | I17: DIČ:
D19: Uchazeč: | I19: IČ: | J19: ='Rekapitulace stavby'!AN13 -> 08004013
E20: ='Rekapitulace stavby'!E14 -> DMG Stav a.s. | I20: DIČ: | J20: ='Rekapitulace stavby'!AN14 -> CZ 08004013
D22: Projektant: | I22: IČ:
E23: ABMV World s.r.o | I23: DIČ:
D25: Zpracovatel: | I25: IČ:
E26: QSB s.r.o. | I26: DIČ:
D28: Poznámka:
D32: Cena bez DPH | J32: =ROUND(J122,2) -> 472890
F34: Základ daně | I34: Sazba daně | J34: Výše daně
D35: DPH | E35: základní | F35: =ROUND((SUM(BE122:BE146)),2) -> 0 | I35: 0.21 | J35: =ROUND(((SUM(BE122:BE146))*I35),2) -> 0
E36: snížená | F36: =ROUND((SUM(BF122:BF146)),2) -> 472890 | I36: 0.15 | J36: =ROUND(((SUM(BF122:BF146))*I36),2) -> 70933.5
E37: zákl. přenesená | F37: =ROUND((SUM(BG122:BG146)),2) -> 0 | I37: 0.21 | J37: =0 -> 0
E38: sníž. přenesená | F38: =ROUND((SUM(BH122:BH146)),2) -> 0 | I38: 0.15 | J38: =0 -> 0
E39: nulová | F39: =ROUND((SUM(BI122:BI146)),2) -> 0 | I39: 0 | J39: =0 -> 0
D41: Cena s DPH | G41: v | H41: CZK | J41: =SUM(J32:J39) -> 543823.5
D50: Projektant | G50: Zpracovatel
D61: Datum a podpis: | F61: Razítko | G61: Datum a podpis: | J61: Razítko
D65: Objednavatel | G65: Uchazeč
D76: Datum a podpis: | F76: Razítko | G76: Datum a podpis: | J76: Razítko
C82: REKAPITULACE ČLENĚNÍ SOUPISU PRACÍ
C84: Stavba:
E85: =E7 -> Bytový soubor Libuše
C86: Objekt:
E87: 01 - Bytové domy A, B, C, D vč. podzemního podlaží
C88: Soupis:
E89: =E11 -> D1.610 - Uzemnění a hromosvod
C91: Místo: | F91: =F14 -> Praha | I91: Datum: | J91: =IF(J14="","",J14) -> 45000
...

Sheet D1.620 - Silnoproudá elek...
AT2: {0ca3e164-1671-4e26-bdbc-699a382a27b7}
AT3: 1
D4: KRYCÍ LIST SOUPISU PRACÍ | M4: v --- níže se nacházejí doplnkové a pomocné údaje k sestavám --- v | AT4: False
D6: Stavba:
E7: ='Rekapitulace stavby'!K6 -> Bytový soubor Libuše
D8: Objekt:
E9: 01 - Bytové domy A, B, C, D vč. podzemního podlaží
D10: Soupis:
E11: D1.620 - Silnoproudá elektroinstalace
D13: KSO: | I13: CC-CZ:
D14: Místo: | F14: Praha | I14: Datum: | J14: ='Rekapitulace stavby'!AN8 -> 45000
D16: Zadavatel: | I16: IČ:
E17: VELTON REAL ESTATE | I17: DIČ:
D19: Uchazeč: | I19: IČ: | J19: ='Rekapitulace stavby'!AN13 -> 08004013
E20: ='Rekapitulace stavby'!E14 -> DMG Stav a.s. | I20: DIČ: | J20: ='Rekapitulace stavby'!AN14 -> CZ 08004013
D22: Projektant: | I22: IČ:
E23: ABMV World s.r.o | I23: DIČ:
D25: Zpracovatel: | I25: IČ:
E26: QSB s.r.o. | I26: DIČ:
D28: Poznámka:
D32: Cena bez DPH | J32: =ROUND(J127,2) -> 12086552
F34: Základ daně | I34: Sazba daně | J34: Výše daně
D35: DPH | E35: základní | F35: =ROUND((SUM(BE127:BE275)),2) -> 0 | I35: 0.21 | J35: =ROUND(((SUM(BE127:BE275))*I35),2) -> 0
E36: snížená | F36: =ROUND((SUM(BF127:BF275)),2) -> 12086552 | I36: 0.15 | J36: =ROUND(((SUM(BF127:BF275))*I36),2) -> 1812982.8
E37: zákl. přenesená | F37: =ROUND((SUM(BG127:BG275)),2) -> 0 | I37: 0.21 | J37: =0 -> 0
E38: sníž. přenesená | F38: =ROUND((SUM(BH127:BH275)),2) -> 0 | I38: 0.15 | J38: =0 -> 0
E39: nulová | F39: =ROUND((SUM(BI127:BI275)),2) -> 0 | I39: 0 | J39: =0 -> 0
D41: Cena s DPH | G41: v | H41: CZK | J41: =SUM(J32:J39) -> 13899535
D50: Projektant | G50: Zpracovatel
D61: Datum a podpis: | F61: Razítko | G61: Datum a podpis: | J61: Razítko
D65: Objednavatel | G65: Uchazeč
D76: Datum a podpis: | F76: Razítko | G76: Datum a podpis: | J76: Razítko
C82: REKAPITULACE ČLENĚNÍ SOUPISU PRACÍ
C84: Stavba:
E85: =E7 -> Bytový soubor Libuše
C86: Objekt:
E87: 01 - Bytové domy A, B, C, D vč. podzemního podlaží
C88: Soupis:
E89: =E11 -> D1.620 - Silnoproudá elektroinstalace
C91: Místo: | F91: =F14 -> Praha | I91: Datum: | J91: =IF(J14="","",J14) -> 45000
...

Sheet D1.700 - Slaboproudé elek...
AT2: {c76b0c4d-0920-43f0-9a54-66b7c9076d38}
AT3: 2
D4: KRYCÍ LIST SOUPISU PRACÍ | M4: v --- níže se nacházejí doplnkové a pomocné údaje k sestavám --- v | AT4: False
D6: Stavba:
E7: ='Rekapitulace stavby'!K6 -> Bytový soubor Libuše
D8: Objekt:
E9: 01 - Bytové domy A, B, C, D vč. podzemního podlaží
D10: Soupis:
E11: D1.700 - Slaboproudé elektroinstalace
D13: KSO: | I13: CC-CZ:
D14: Místo: | F14: Praha | I14: Datum: | J14: ='Rekapitulace stavby'!AN8 -> 45000
D16: Zadavatel: | I16: IČ:
E17: VELTON REAL ESTATE | I17: DIČ:
D19: Uchazeč: | I19: IČ: | J19: ='Rekapitulace stavby'!AN13 -> 08004013
E20: ='Rekapitulace stavby'!E14 -> DMG Stav a.s. | I20: DIČ: | J20: ='Rekapitulace stavby'!AN14 -> CZ 08004013
D22: Projektant: | I22: IČ:
E23: ABMV World s.r.o | I23: DIČ:
D25: Zpracovatel: | I25: IČ:
E26: QSB s.r.o. | I26: DIČ:
D28: Poznámka:
D32: Cena bez DPH | J32: =ROUND(J147,2) -> 3885503
F34: Základ daně | I34: Sazba daně | J34: Výše daně
D35: DPH | E35: základní | F35: =ROUND((SUM(BE147:BE264)),2) -> 3885503 | I35: 0.21 | J35: =ROUND(((SUM(BE147:BE264))*I35),2) -> 815955.63
E36: snížená | F36: =ROUND((SUM(BF147:BF264)),2) -> 0 | I36: 0.15 | J36: =ROUND(((SUM(BF147:BF264))*I36),2) -> 0
E37: zákl. přenesená | F37: =ROUND((SUM(BG147:BG264)),2) -> 0 | I37: 0.21 | J37: =0 -> 0
E38: sníž. přenesená | F38: =ROUND((SUM(BH147:BH264)),2) -> 0 | I38: 0.15 | J38: =0 -> 0
E39: nulová | F39: =ROUND((SUM(BI147:BI264)),2) -> 0 | I39: 0 | J39: =0 -> 0
D41: Cena s DPH | G41: v | H41: CZK | J41: =SUM(J32:J39) -> 4701458.6
D50: Projektant | G50: Zpracovatel
D61: Datum a podpis: | F61: Razítko | G61: Datum a podpis: | J61: Razítko
D65: Objednavatel | G65: Uchazeč
D76: Datum a podpis: | F76: Razítko | G76: Datum a podpis: | J76: Razítko
C82: REKAPITULACE ČLENĚNÍ SOUPISU PRACÍ
C84: Stavba:
E85: =E7 -> Bytový soubor Libuše
C86: Objekt:
E87: 01 - Bytové domy A, B, C, D vč. podzemního podlaží
C88: Soupis:
E89: =E11 -> D1.700 - Slaboproudé elektroinstalace
C91: Místo: | F91: =F14 -> Praha | I91: Datum: | J91: =IF(J14="","",J14) -> 45000
...

Sheet D1.901 - Osobní výtahy
AT2: {85b3d44d-510f-4c25-af05-03fe096574e7}
AT3: 2
D4: KRYCÍ LIST SOUPISU PRACÍ | M4: v --- níže se nacházejí doplnkové a pomocné údaje k sestavám --- v | AT4: False
D6: Stavba:
E7: ='Rekapitulace stavby'!K6 -> Bytový soubor Libuše
D8: Objekt:
E9: 01 - Bytové domy A, B, C, D vč. podzemního podlaží
D10: Soupis:
E11: D1.901 - Osobní výtahy
D13: KSO: | I13: CC-CZ:
D14: Místo: | F14: Praha | I14: Datum: | J14: ='Rekapitulace stavby'!AN8 -> 45000
D16: Zadavatel: | I16: IČ:
E17: VELTON REAL ESTATE | I17: DIČ:
D19: Uchazeč: | I19: IČ: | J19: ='Rekapitulace stavby'!AN13 -> 08004013
E20: ='Rekapitulace stavby'!E14 -> DMG Stav a.s. | I20: DIČ: | J20: ='Rekapitulace stavby'!AN14 -> CZ 08004013
D22: Projektant: | I22: IČ:
E23: ABMV World s.r.o | I23: DIČ:
D25: Zpracovatel: | I25: IČ:
E26: QSB s.r.o. | I26: DIČ:
D28: Poznámka:
D32: Cena bez DPH | J32: =ROUND(J122,2) -> 4200000
F34: Základ daně | I34: Sazba daně | J34: Výše daně
D35: DPH | E35: základní | F35: =ROUND((SUM(BE122:BE128)),2) -> 4200000 | I35: 0.21 | J35: =ROUND(((SUM(BE122:BE128))*I35),2) -> 882000
E36: snížená | F36: =ROUND((SUM(BF122:BF128)),2) -> 0 | I36: 0.15 | J36: =ROUND(((SUM(BF122:BF128))*I36),2) -> 0
E37: zákl. přenesená | F37: =ROUND((SUM(BG122:BG128)),2) -> 0 | I37: 0.21 | J37: =0 -> 0
E38: sníž. přenesená | F38: =ROUND((SUM(BH122:BH128)),2) -> 0 | I38: 0.15 | J38: =0 -> 0
E39: nulová | F39: =ROUND((SUM(BI122:BI128)),2) -> 0 | I39: 0 | J39: =0 -> 0
D41: Cena s DPH | G41: v | H41: CZK | J41: =SUM(J32:J39) -> 5082000
D50: Projektant | G50: Zpracovatel
D61: Datum a podpis: | F61: Razítko | G61: Datum a podpis: | J61: Razítko
D65: Objednavatel | G65: Uchazeč
D76: Datum a podpis: | F76: Razítko | G76: Datum a podpis: | J76: Razítko
C82: REKAPITULACE ČLENĚNÍ SOUPISU PRACÍ
C84: Stavba:
E85: =E7 -> Bytový soubor Libuše
C86: Objekt:
E87: 01 - Bytové domy A, B, C, D vč. podzemního podlaží
C88: Soupis:
E89: =E11 -> D1.901 - Osobní výtahy
C91: Místo: | F91: =F14 -> Praha | I91: Datum: | J91: =IF(J14="","",J14) -> 45000
...

Sheet D1.902 - Vnitřní dopravní...
AT2: {153d72b2-6802-4da7-b53b-e87be3a458ca}
AT3: 2
D4: KRYCÍ LIST SOUPISU PRACÍ | M4: v --- níže se nacházejí doplnkové a pomocné údaje k sestavám --- v | AT4: False
D6: Stavba:
E7: ='Rekapitulace stavby'!K6 -> Bytový soubor Libuše
D8: Objekt:
E9: 01 - Bytové domy A, B, C, D vč. podzemního podlaží
D10: Soupis:
E11: D1.902 - Vnitřní dopravní značení
D13: KSO: | I13: CC-CZ:
D14: Místo: | F14: Praha | I14: Datum: | J14: ='Rekapitulace stavby'!AN8 -> 45000
D16: Zadavatel: | I16: IČ:
E17: VELTON REAL ESTATE | I17: DIČ:
D19: Uchazeč: | I19: IČ: | J19: ='Rekapitulace stavby'!AN13 -> 08004013
E20: ='Rekapitulace stavby'!E14 -> DMG Stav a.s. | I20: DIČ: | J20: ='Rekapitulace stavby'!AN14 -> CZ 08004013
D22: Projektant: | I22: IČ:
E23: ABMV World s.r.o | I23: DIČ:
D25: Zpracovatel: | I25: IČ:
E26: QSB s.r.o. | I26: DIČ:
D28: Poznámka:
D32: Cena bez DPH | J32: =ROUND(J123,2) -> 187492.73
F34: Základ daně | I34: Sazba daně | J34: Výše daně
D35: DPH | E35: základní | F35: =ROUND((SUM(BE123:BE161)),2) -> 187492.73 | I35: 0.21 | J35: =ROUND(((SUM(BE123:BE161))*I35),2) -> 39373.47
E36: snížená | F36: =ROUND((SUM(BF123:BF161)),2) -> 0 | I36: 0.15 | J36: =ROUND(((SUM(BF123:BF161))*I36),2) -> 0
E37: zákl. přenesená | F37: =ROUND((SUM(BG123:BG161)),2) -> 0 | I37: 0.21 | J37: =0 -> 0
E38: sníž. přenesená | F38: =ROUND((SUM(BH123:BH161)),2) -> 0 | I38: 0.15 | J38: =0 -> 0
E39: nulová | F39: =ROUND((SUM(BI123:BI161)),2) -> 0 | I39: 0 | J39: =0 -> 0
D41: Cena s DPH | G41: v | H41: CZK | J41: =SUM(J32:J39) -> 226866.2
D50: Projektant | G50: Zpracovatel
D61: Datum a podpis: | F61: Razítko | G61: Datum a podpis: | J61: Razítko
D65: Objednavatel | G65: Uchazeč
D76: Datum a podpis: | F76: Razítko | G76: Datum a podpis: | J76: Razítko
C82: REKAPITULACE ČLENĚNÍ SOUPISU PRACÍ
C84: Stavba:
E85: =E7 -> Bytový soubor Libuše
C86: Objekt:
E87: 01 - Bytové domy A, B, C, D vč. podzemního podlaží
C88: Soupis:
E89: =E11 -> D1.902 - Vnitřní dopravní značení
C91: Místo: | F91: =F14 -> Praha | I91: Datum: | J91: =IF(J14="","",J14) -> 45000
...

Sheet IO01 - Přípojka vodovodu
AT2: {bd75a83a-2a19-4b60-a90b-74b51b17b035}
AT3: 2
D4: KRYCÍ LIST SOUPISU PRACÍ | M4: v --- níže se nacházejí doplnkové a pomocné údaje k sestavám --- v | AT4: False
D6: Stavba:
E7: ='Rekapitulace stavby'!K6 -> Bytový soubor Libuše
D8: Objekt:
E9: 02 - Venkovní objekty a přípojky
D10: Soupis:
E11: IO - Přípojky
D12: Úroveň 3:
E13: IO01 - Přípojka vodovodu
D15: KSO: | I15: CC-CZ:
D16: Místo: | F16: Praha | I16: Datum: | J16: ='Rekapitulace stavby'!AN8 -> 45000
D18: Zadavatel: | I18: IČ:
E19: VELTON REAL ESTATE | I19: DIČ:
D21: Uchazeč: | I21: IČ: | J21: ='Rekapitulace stavby'!AN13 -> 08004013
E22: ='Rekapitulace stavby'!E14 -> DMG Stav a.s. | I22: DIČ: | J22: ='Rekapitulace stavby'!AN14 -> CZ 08004013
D24: Projektant: | I24: IČ:
E25: ABMV World s.r.o | I25: DIČ:
D27: Zpracovatel: | I27: IČ:
E28: QSB s.r.o. | I28: DIČ:
D30: Poznámka:
D34: Cena bez DPH | J34: =ROUND(J132,2) -> 78350
F36: Základ daně | I36: Sazba daně | J36: Výše daně
D37: DPH | E37: základní | F37: =ROUND((SUM(BE132:BE169)),2) -> 78350 | I37: 0.21 | J37: =ROUND(((SUM(BE132:BE169))*I37),2) -> 16453.5
E38: snížená | F38: =ROUND((SUM(BF132:BF169)),2) -> 0 | I38: 0.15 | J38: =ROUND(((SUM(BF132:BF169))*I38),2) -> 0
E39: zákl. přenesená | F39: =ROUND((SUM(BG132:BG169)),2) -> 0 | I39: 0.21 | J39: =0 -> 0
E40: sníž. přenesená | F40: =ROUND((SUM(BH132:BH169)),2) -> 0 | I40: 0.15 | J40: =0 -> 0
E41: nulová | F41: =ROUND((SUM(BI132:BI169)),2) -> 0 | I41: 0 | J41: =0 -> 0
D43: Cena s DPH | G43: v | H43: CZK | J43: =SUM(J34:J41) -> 94803.5
D50: Projektant | G50: Zpracovatel
D61: Datum a podpis: | F61: Razítko | G61: Datum a podpis: | J61: Razítko
D65: Objednavatel | G65: Uchazeč
D76: Datum a podpis: | F76: Razítko | G76: Datum a podpis: | J76: Razítko
C82: REKAPITULACE ČLENĚNÍ SOUPISU PRACÍ
C84: Stavba:
E85: =E7 -> Bytový soubor Libuše
C86: Objekt:
E87: 02 - Venkovní objekty a přípojky
C88: Soupis:
...

Sheet IO02 - Přípojka plynovodu
AT2: {4a27c019-c402-4276-9969-e3927108a50f}
AT3: 2
D4: KRYCÍ LIST SOUPISU PRACÍ | M4: v --- níže se nacházejí doplnkové a pomocné údaje k sestavám --- v | AT4: False
D6: Stavba:
E7: ='Rekapitulace stavby'!K6 -> Bytový soubor Libuše
D8: Objekt:
E9: 02 - Venkovní objekty a přípojky
D10: Soupis:
E11: IO - Přípojky
D12: Úroveň 3:
E13: IO02 - Přípojka plynovodu
D15: KSO: | I15: CC-CZ:
D16: Místo: | F16: Praha | I16: Datum: | J16: ='Rekapitulace stavby'!AN8 -> 45000
D18: Zadavatel: | I18: IČ:
E19: VELTON REAL ESTATE | I19: DIČ:
D21: Uchazeč: | I21: IČ: | J21: ='Rekapitulace stavby'!AN13 -> 08004013
E22: ='Rekapitulace stavby'!E14 -> DMG Stav a.s. | I22: DIČ: | J22: ='Rekapitulace stavby'!AN14 -> CZ 08004013
D24: Projektant: | I24: IČ:
E25: ABMV World s.r.o | I25: DIČ:
D27: Zpracovatel: | I27: IČ:
E28: QSB s.r.o. | I28: DIČ:
D30: Poznámka:
D34: Cena bez DPH | J34: =ROUND(J125,2) -> 40877
F36: Základ daně | I36: Sazba daně | J36: Výše daně
D37: DPH | E37: základní | F37: =ROUND((SUM(BE125:BE149)),2) -> 40877 | I37: 0.21 | J37: =ROUND(((SUM(BE125:BE149))*I37),2) -> 8584.17
E38: snížená | F38: =ROUND((SUM(BF125:BF149)),2) -> 0 | I38: 0.15 | J38: =ROUND(((SUM(BF125:BF149))*I38),2) -> 0
E39: zákl. přenesená | F39: =ROUND((SUM(BG125:BG149)),2) -> 0 | I39: 0.21 | J39: =0 -> 0
E40: sníž. přenesená | F40: =ROUND((SUM(BH125:BH149)),2) -> 0 | I40: 0.15 | J40: =0 -> 0
E41: nulová | F41: =ROUND((SUM(BI125:BI149)),2) -> 0 | I41: 0 | J41: =0 -> 0
D43: Cena s DPH | G43: v | H43: CZK | J43: =SUM(J34:J41) -> 49461.17
D50: Projektant | G50: Zpracovatel
D61: Datum a podpis: | F61: Razítko | G61: Datum a podpis: | J61: Razítko
D65: Objednavatel | G65: Uchazeč
D76: Datum a podpis: | F76: Razítko | G76: Datum a podpis: | J76: Razítko
C82: REKAPITULACE ČLENĚNÍ SOUPISU PRACÍ
C84: Stavba:
E85: =E7 -> Bytový soubor Libuše
C86: Objekt:
E87: 02 - Venkovní objekty a přípojky
C88: Soupis:
...

Sheet IO03 - Přípojka dešťové k...
AT2: {2f31af83-109f-4628-8cfe-d13fec123a40}
AT3: 2
D4: KRYCÍ LIST SOUPISU PRACÍ | M4: v --- níže se nacházejí doplnkové a pomocné údaje k sestavám --- v | AT4: False
D6: Stavba:
E7: ='Rekapitulace stavby'!K6 -> Bytový soubor Libuše
D8: Objekt:
E9: 02 - Venkovní objekty a přípojky
D10: Soupis:
E11: IO - Přípojky
D12: Úroveň 3:
E13: IO03 - Přípojka dešťové kanalizace
D15: KSO: | I15: CC-CZ:
D16: Místo: | F16: Praha | I16: Datum: | J16: ='Rekapitulace stavby'!AN8 -> 45000
D18: Zadavatel: | I18: IČ:
E19: VELTON REAL ESTATE | I19: DIČ:
D21: Uchazeč: | I21: IČ: | J21: ='Rekapitulace stavby'!AN13 -> 08004013
E22: ='Rekapitulace stavby'!E14 -> DMG Stav a.s. | I22: DIČ: | J22: ='Rekapitulace stavby'!AN14 -> CZ 08004013
D24: Projektant: | I24: IČ:
E25: ABMV World s.r.o | I25: DIČ:
D27: Zpracovatel: | I27: IČ:
E28: QSB s.r.o. | I28: DIČ:
D30: Poznámka:
D34: Cena bez DPH | J34: =ROUND(J131,2) -> 143500
F36: Základ daně | I36: Sazba daně | J36: Výše daně
D37: DPH | E37: základní | F37: =ROUND((SUM(BE131:BE156)),2) -> 143500 | I37: 0.21 | J37: =ROUND(((SUM(BE131:BE156))*I37),2) -> 30135
E38: snížená | F38: =ROUND((SUM(BF131:BF156)),2) -> 0 | I38: 0.15 | J38: =ROUND(((SUM(BF131:BF156))*I38),2) -> 0
E39: zákl. přenesená | F39: =ROUND((SUM(BG131:BG156)),2) -> 0 | I39: 0.21 | J39: =0 -> 0
E40: sníž. přenesená | F40: =ROUND((SUM(BH131:BH156)),2) -> 0 | I40: 0.15 | J40: =0 -> 0
E41: nulová | F41: =ROUND((SUM(BI131:BI156)),2) -> 0 | I41: 0 | J41: =0 -> 0
D43: Cena s DPH | G43: v | H43: CZK | J43: =SUM(J34:J41) -> 173635
D50: Projektant | G50: Zpracovatel
D61: Datum a podpis: | F61: Razítko | G61: Datum a podpis: | J61: Razítko
D65: Objednavatel | G65: Uchazeč
D76: Datum a podpis: | F76: Razítko | G76: Datum a podpis: | J76: Razítko
C82: REKAPITULACE ČLENĚNÍ SOUPISU PRACÍ
C84: Stavba:
E85: =E7 -> Bytový soubor Libuše
C86: Objekt:
E87: 02 - Venkovní objekty a přípojky
C88: Soupis:
...

Sheet IO04 - Přípojka splaškové...
AT2: {83066047-6971-48cf-8e2e-2224f3f05ae9}
AT3: 2
D4: KRYCÍ LIST SOUPISU PRACÍ | M4: v --- níže se nacházejí doplnkové a pomocné údaje k sestavám --- v | AT4: False
D6: Stavba:
E7: ='Rekapitulace stavby'!K6 -> Bytový soubor Libuše
D8: Objekt:
E9: 02 - Venkovní objekty a přípojky
D10: Soupis:
E11: IO - Přípojky
D12: Úroveň 3:
E13: IO04 - Přípojka splaškové kanalizace
D15: KSO: | I15: CC-CZ:
D16: Místo: | F16: Praha | I16: Datum: | J16: ='Rekapitulace stavby'!AN8 -> 45000
D18: Zadavatel: | I18: IČ:
E19: VELTON REAL ESTATE | I19: DIČ:
D21: Uchazeč: | I21: IČ: | J21: ='Rekapitulace stavby'!AN13 -> 08004013
E22: ='Rekapitulace stavby'!E14 -> DMG Stav a.s. | I22: DIČ: | J22: ='Rekapitulace stavby'!AN14 -> CZ 08004013
D24: Projektant: | I24: IČ:
E25: ABMV World s.r.o | I25: DIČ:
D27: Zpracovatel: | I27: IČ:
E28: QSB s.r.o. | I28: DIČ:
D30: Poznámka:
D34: Cena bez DPH | J34: =ROUND(J131,2) -> 406490
F36: Základ daně | I36: Sazba daně | J36: Výše daně
D37: DPH | E37: základní | F37: =ROUND((SUM(BE131:BE156)),2) -> 406490 | I37: 0.21 | J37: =ROUND(((SUM(BE131:BE156))*I37),2) -> 85362.9
E38: snížená | F38: =ROUND((SUM(BF131:BF156)),2) -> 0 | I38: 0.15 | J38: =ROUND(((SUM(BF131:BF156))*I38),2) -> 0
E39: zákl. přenesená | F39: =ROUND((SUM(BG131:BG156)),2) -> 0 | I39: 0.21 | J39: =0 -> 0
E40: sníž. přenesená | F40: =ROUND((SUM(BH131:BH156)),2) -> 0 | I40: 0.15 | J40: =0 -> 0
E41: nulová | F41: =ROUND((SUM(BI131:BI156)),2) -> 0 | I41: 0 | J41: =0 -> 0
D43: Cena s DPH | G43: v | H43: CZK | J43: =SUM(J34:J41) -> 491852.9
D50: Projektant | G50: Zpracovatel
D61: Datum a podpis: | F61: Razítko | G61: Datum a podpis: | J61: Razítko
D65: Objednavatel | G65: Uchazeč
D76: Datum a podpis: | F76: Razítko | G76: Datum a podpis: | J76: Razítko
C82: REKAPITULACE ČLENĚNÍ SOUPISU PRACÍ
C84: Stavba:
E85: =E7 -> Bytový soubor Libuše
C86: Objekt:
E87: 02 - Venkovní objekty a přípojky
C88: Soupis:
...

Sheet IO05 - PRE
AT2: {7bc87533-6e77-43ff-961c-2db2df70c57e}
AT3: 2
D4: KRYCÍ LIST SOUPISU PRACÍ | M4: v --- níže se nacházejí doplnkové a pomocné údaje k sestavám --- v | AT4: False
D6: Stavba:
E7: ='Rekapitulace stavby'!K6 -> Bytový soubor Libuše
D8: Objekt:
E9: 02 - Venkovní objekty a přípojky
D10: Soupis:
E11: IO - Přípojky
D12: Úroveň 3:
E13: IO05 - PRE
D15: KSO: | I15: CC-CZ:
D16: Místo: | F16: Praha | I16: Datum: | J16: ='Rekapitulace stavby'!AN8 -> 45000
D18: Zadavatel: | I18: IČ:
E19: VELTON REAL ESTATE | I19: DIČ:
D21: Uchazeč: | I21: IČ: | J21: ='Rekapitulace stavby'!AN13 -> 08004013
E22: ='Rekapitulace stavby'!E14 -> DMG Stav a.s. | I22: DIČ: | J22: ='Rekapitulace stavby'!AN14 -> CZ 08004013
D24: Projektant: | I24: IČ:
E25: ABMV World s.r.o | I25: DIČ:
D27: Zpracovatel: | I27: IČ:
E28: QSB s.r.o. | I28: DIČ:
D30: Poznámka:
D34: Cena bez DPH | J34: =ROUND(J125,2) -> 0
F36: Základ daně | I36: Sazba daně | J36: Výše daně
D37: DPH | E37: základní | F37: =ROUND((SUM(BE125:BE127)),2) -> 0 | I37: 0.21 | J37: =ROUND(((SUM(BE125:BE127))*I37),2) -> 0
E38: snížená | F38: =ROUND((SUM(BF125:BF127)),2) -> 0 | I38: 0.15 | J38: =ROUND(((SUM(BF125:BF127))*I38),2) -> 0
E39: zákl. přenesená | F39: =ROUND((SUM(BG125:BG127)),2) -> 0 | I39: 0.21 | J39: =0 -> 0
E40: sníž. přenesená | F40: =ROUND((SUM(BH125:BH127)),2) -> 0 | I40: 0.15 | J40: =0 -> 0
E41: nulová | F41: =ROUND((SUM(BI125:BI127)),2) -> 0 | I41: 0 | J41: =0 -> 0
D43: Cena s DPH | G43: v | H43: CZK | J43: =SUM(J34:J41) -> 0
D50: Projektant | G50: Zpracovatel
D61: Datum a podpis: | F61: Razítko | G61: Datum a podpis: | J61: Razítko
D65: Objednavatel | G65: Uchazeč
D76: Datum a podpis: | F76: Razítko | G76: Datum a podpis: | J76: Razítko
C82: REKAPITULACE ČLENĚNÍ SOUPISU PRACÍ
C84: Stavba:
E85: =E7 -> Bytový soubor Libuše
C86: Objekt:
E87: 02 - Venkovní objekty a přípojky
C88: Soupis:
...

Sheet IO06 - CETIN
AT2: {ce514360-396b-472e-a9f9-cbff4ff495bf}
AT3: 2
D4: KRYCÍ LIST SOUPISU PRACÍ | M4: v --- níže se nacházejí doplnkové a pomocné údaje k sestavám --- v | AT4: False
D6: Stavba:
E7: ='Rekapitulace stavby'!K6 -> Bytový soubor Libuše
D8: Objekt:
E9: 02 - Venkovní objekty a přípojky
D10: Soupis:
E11: IO - Přípojky
D12: Úroveň 3:
E13: IO06 - CETIN
D15: KSO: | I15: CC-CZ:
D16: Místo: | F16: Praha | I16: Datum: | J16: ='Rekapitulace stavby'!AN8 -> 45000
D18: Zadavatel: | I18: IČ:
E19: VELTON REAL ESTATE | I19: DIČ:
D21: Uchazeč: | I21: IČ: | J21: ='Rekapitulace stavby'!AN13 -> 08004013
E22: ='Rekapitulace stavby'!E14 -> DMG Stav a.s. | I22: DIČ: | J22: ='Rekapitulace stavby'!AN14 -> CZ 08004013
D24: Projektant: | I24: IČ:
E25: ABMV World s.r.o | I25: DIČ:
D27: Zpracovatel: | I27: IČ:
E28: QSB s.r.o. | I28: DIČ:
D30: Poznámka:
D34: Cena bez DPH | J34: =ROUND(J125,2) -> 0
F36: Základ daně | I36: Sazba daně | J36: Výše daně
D37: DPH | E37: základní | F37: =ROUND((SUM(BE125:BE127)),2) -> 0 | I37: 0.21 | J37: =ROUND(((SUM(BE125:BE127))*I37),2) -> 0
E38: snížená | F38: =ROUND((SUM(BF125:BF127)),2) -> 0 | I38: 0.15 | J38: =ROUND(((SUM(BF125:BF127))*I38),2) -> 0
E39: zákl. přenesená | F39: =ROUND((SUM(BG125:BG127)),2) -> 0 | I39: 0.21 | J39: =0 -> 0
E40: sníž. přenesená | F40: =ROUND((SUM(BH125:BH127)),2) -> 0 | I40: 0.15 | J40: =0 -> 0
E41: nulová | F41: =ROUND((SUM(BI125:BI127)),2) -> 0 | I41: 0 | J41: =0 -> 0
D43: Cena s DPH | G43: v | H43: CZK | J43: =SUM(J34:J41) -> 0
D50: Projektant | G50: Zpracovatel
D61: Datum a podpis: | F61: Razítko | G61: Datum a podpis: | J61: Razítko
D65: Objednavatel | G65: Uchazeč
D76: Datum a podpis: | F76: Razítko | G76: Datum a podpis: | J76: Razítko
C82: REKAPITULACE ČLENĚNÍ SOUPISU PRACÍ
C84: Stavba:
E85: =E7 -> Bytový soubor Libuše
C86: Objekt:
E87: 02 - Venkovní objekty a přípojky
C88: Soupis:
...

Sheet IO07 - Veřejné osvětlení
AT2: {0f893789-fb0d-4ac6-8f20-40252bef8e60}
AT3: 1
D4: KRYCÍ LIST SOUPISU PRACÍ | M4: v --- níže se nacházejí doplnkové a pomocné údaje k sestavám --- v | AT4: False
D6: Stavba:
E7: ='Rekapitulace stavby'!K6 -> Bytový soubor Libuše
D8: Objekt:
E9: 02 - Venkovní objekty a přípojky
D10: Soupis:
E11: IO - Přípojky
D12: Úroveň 3:
E13: IO07 - Veřejné osvětlení
D15: KSO: | I15: CC-CZ:
D16: Místo: | F16: Praha | I16: Datum: | J16: ='Rekapitulace stavby'!AN8 -> 45000
D18: Zadavatel: | I18: IČ:
E19: VELTON REAL ESTATE | I19: DIČ:
D21: Uchazeč: | I21: IČ: | J21: ='Rekapitulace stavby'!AN13 -> 08004013
E22: ='Rekapitulace stavby'!E14 -> DMG Stav a.s. | I22: DIČ: | J22: ='Rekapitulace stavby'!AN14 -> CZ 08004013
D24: Projektant: | I24: IČ:
E25: ABMV World s.r.o | I25: DIČ:
D27: Zpracovatel: | I27: IČ:
E28: QSB s.r.o. | I28: DIČ:
D30: Poznámka:
D34: Cena bez DPH | J34: =ROUND(J131,2) -> 357757.14
F36: Základ daně | I36: Sazba daně | J36: Výše daně
D37: DPH | E37: základní | F37: =ROUND((SUM(BE131:BE170)),2) -> 0 | I37: 0.21 | J37: =ROUND(((SUM(BE131:BE170))*I37),2) -> 0
E38: snížená | F38: =ROUND((SUM(BF131:BF170)),2) -> 357757.14 | I38: 0.15 | J38: =ROUND(((SUM(BF131:BF170))*I38),2) -> 53663.57
E39: zákl. přenesená | F39: =ROUND((SUM(BG131:BG170)),2) -> 0 | I39: 0.21 | J39: =0 -> 0
E40: sníž. přenesená | F40: =ROUND((SUM(BH131:BH170)),2) -> 0 | I40: 0.15 | J40: =0 -> 0
E41: nulová | F41: =ROUND((SUM(BI131:BI170)),2) -> 0 | I41: 0 | J41: =0 -> 0
D43: Cena s DPH | G43: v | H43: CZK | J43: =SUM(J34:J41) -> 411420.71
D50: Projektant | G50: Zpracovatel
D61: Datum a podpis: | F61: Razítko | G61: Datum a podpis: | J61: Razítko
D65: Objednavatel | G65: Uchazeč
D76: Datum a podpis: | F76: Razítko | G76: Datum a podpis: | J76: Razítko
C82: REKAPITULACE ČLENĚNÍ SOUPISU PRACÍ
C84: Stavba:
E85: =E7 -> Bytový soubor Libuše
C86: Objekt:
E87: 02 - Venkovní objekty a přípojky
C88: Soupis:
...

Sheet IOX - Přeložky
AT2: {376ee8c7-f9a0-484d-b2f6-95e352eb46c4}
AT3: 2
D4: KRYCÍ LIST SOUPISU PRACÍ | M4: v --- níže se nacházejí doplnkové a pomocné údaje k sestavám --- v | AT4: False
D6: Stavba:
E7: ='Rekapitulace stavby'!K6 -> Bytový soubor Libuše
D8: Objekt:
E9: 02 - Venkovní objekty a přípojky
D10: Soupis:
E11: IOX - Přeložky
D13: KSO: | I13: CC-CZ:
D14: Místo: | F14: Praha | I14: Datum: | J14: ='Rekapitulace stavby'!AN8 -> 45000
D16: Zadavatel: | I16: IČ:
E17: VELTON REAL ESTATE | I17: DIČ:
D19: Uchazeč: | I19: IČ: | J19: ='Rekapitulace stavby'!AN13 -> 08004013
E20: ='Rekapitulace stavby'!E14 -> DMG Stav a.s. | I20: DIČ: | J20: ='Rekapitulace stavby'!AN14 -> CZ 08004013
D22: Projektant: | I22: IČ:
E23: ABMV World s.r.o | I23: DIČ:
D25: Zpracovatel: | I25: IČ:
E26: QSB s.r.o. | I26: DIČ:
D28: Poznámka:
D32: Cena bez DPH | J32: =ROUND(J128,2) -> 821450
F34: Základ daně | I34: Sazba daně | J34: Výše daně
D35: DPH | E35: základní | F35: =ROUND((SUM(BE128:BE164)),2) -> 821450 | I35: 0.21 | J35: =ROUND(((SUM(BE128:BE164))*I35),2) -> 172504.5
E36: snížená | F36: =ROUND((SUM(BF128:BF164)),2) -> 0 | I36: 0.15 | J36: =ROUND(((SUM(BF128:BF164))*I36),2) -> 0
E37: zákl. přenesená | F37: =ROUND((SUM(BG128:BG164)),2) -> 0 | I37: 0.21 | J37: =0 -> 0
E38: sníž. přenesená | F38: =ROUND((SUM(BH128:BH164)),2) -> 0 | I38: 0.15 | J38: =0 -> 0
E39: nulová | F39: =ROUND((SUM(BI128:BI164)),2) -> 0 | I39: 0 | J39: =0 -> 0
D41: Cena s DPH | G41: v | H41: CZK | J41: =SUM(J32:J39) -> 993954.5
D50: Projektant | G50: Zpracovatel
D61: Datum a podpis: | F61: Razítko | G61: Datum a podpis: | J61: Razítko
D65: Objednavatel | G65: Uchazeč
D76: Datum a podpis: | F76: Razítko | G76: Datum a podpis: | J76: Razítko
C82: REKAPITULACE ČLENĚNÍ SOUPISU PRACÍ
C84: Stavba:
E85: =E7 -> Bytový soubor Libuše
C86: Objekt:
E87: 02 - Venkovní objekty a přípojky
C88: Soupis:
E89: =E11 -> IOX - Přeložky
C91: Místo: | F91: =F14 -> Praha | I91: Datum: | J91: =IF(J14="","",J14) -> 45000
...

Sheet IOX05 - přeložka PRE
AT2: {14ded061-1eb3-4004-b549-96c3ed41977a}
AT3: 2
D4: KRYCÍ LIST SOUPISU PRACÍ | M4: v --- níže se nacházejí doplnkové a pomocné údaje k sestavám --- v | AT4: False
D6: Stavba:
E7: ='Rekapitulace stavby'!K6 -> Bytový soubor Libuše
D8: Objekt:
E9: 02 - Venkovní objekty a přípojky
D10: Soupis:
E11: IOX05 - přeložka PRE
D13: KSO: | I13: CC-CZ:
D14: Místo: | F14: Praha | I14: Datum: | J14: ='Rekapitulace stavby'!AN8 -> 45000
D16: Zadavatel: | I16: IČ:
E17: VELTON REAL ESTATE | I17: DIČ:
D19: Uchazeč: | I19: IČ: | J19: ='Rekapitulace stavby'!AN13 -> 08004013
E20: ='Rekapitulace stavby'!E14 -> DMG Stav a.s. | I20: DIČ: | J20: ='Rekapitulace stavby'!AN14 -> CZ 08004013
D22: Projektant: | I22: IČ:
E23: ABMV World s.r.o | I23: DIČ:
D25: Zpracovatel: | I25: IČ:
E26: QSB s.r.o. | I26: DIČ:
D28: Poznámka:
D32: Cena bez DPH | J32: =ROUND(J121,2) -> 0
F34: Základ daně | I34: Sazba daně | J34: Výše daně
D35: DPH | E35: základní | F35: =ROUND((SUM(BE121:BE123)),2) -> 0 | I35: 0.21 | J35: =ROUND(((SUM(BE121:BE123))*I35),2) -> 0
E36: snížená | F36: =ROUND((SUM(BF121:BF123)),2) -> 0 | I36: 0.15 | J36: =ROUND(((SUM(BF121:BF123))*I36),2) -> 0
E37: zákl. přenesená | F37: =ROUND((SUM(BG121:BG123)),2) -> 0 | I37: 0.21 | J37: =0 -> 0
E38: sníž. přenesená | F38: =ROUND((SUM(BH121:BH123)),2) -> 0 | I38: 0.15 | J38: =0 -> 0
E39: nulová | F39: =ROUND((SUM(BI121:BI123)),2) -> 0 | I39: 0 | J39: =0 -> 0
D41: Cena s DPH | G41: v | H41: CZK | J41: =SUM(J32:J39) -> 0
D50: Projektant | G50: Zpracovatel
D61: Datum a podpis: | F61: Razítko | G61: Datum a podpis: | J61: Razítko
D65: Objednavatel | G65: Uchazeč
D76: Datum a podpis: | F76: Razítko | G76: Datum a podpis: | J76: Razítko
C82: REKAPITULACE ČLENĚNÍ SOUPISU PRACÍ
C84: Stavba:
E85: =E7 -> Bytový soubor Libuše
C86: Objekt:
E87: 02 - Venkovní objekty a přípojky
C88: Soupis:
E89: =E11 -> IOX05 - přeložka PRE
C91: Místo: | F91: =F14 -> Praha | I91: Datum: | J91: =IF(J14="","",J14) -> 45000
...

Sheet IOX06 - přeložka CETIN
AT2: {30623bd4-7672-46ea-882c-02b564c57c07}
AT3: 2
D4: KRYCÍ LIST SOUPISU PRACÍ | M4: v --- níže se nacházejí doplnkové a pomocné údaje k sestavám --- v | AT4: False
D6: Stavba:
E7: ='Rekapitulace stavby'!K6 -> Bytový soubor Libuše
D8: Objekt:
E9: 02 - Venkovní objekty a přípojky
D10: Soupis:
E11: IOX06 - přeložka CETIN
D13: KSO: | I13: CC-CZ:
D14: Místo: | F14: Praha | I14: Datum: | J14: ='Rekapitulace stavby'!AN8 -> 45000
D16: Zadavatel: | I16: IČ:
E17: VELTON REAL ESTATE | I17: DIČ:
D19: Uchazeč: | I19: IČ: | J19: ='Rekapitulace stavby'!AN13 -> 08004013
E20: ='Rekapitulace stavby'!E14 -> DMG Stav a.s. | I20: DIČ: | J20: ='Rekapitulace stavby'!AN14 -> CZ 08004013
D22: Projektant: | I22: IČ:
E23: ABMV World s.r.o | I23: DIČ:
D25: Zpracovatel: | I25: IČ:
E26: QSB s.r.o. | I26: DIČ:
D28: Poznámka:
D32: Cena bez DPH | J32: =ROUND(J121,2) -> 0
F34: Základ daně | I34: Sazba daně | J34: Výše daně
D35: DPH | E35: základní | F35: =ROUND((SUM(BE121:BE123)),2) -> 0 | I35: 0.21 | J35: =ROUND(((SUM(BE121:BE123))*I35),2) -> 0
E36: snížená | F36: =ROUND((SUM(BF121:BF123)),2) -> 0 | I36: 0.15 | J36: =ROUND(((SUM(BF121:BF123))*I36),2) -> 0
E37: zákl. přenesená | F37: =ROUND((SUM(BG121:BG123)),2) -> 0 | I37: 0.21 | J37: =0 -> 0
E38: sníž. přenesená | F38: =ROUND((SUM(BH121:BH123)),2) -> 0 | I38: 0.15 | J38: =0 -> 0
E39: nulová | F39: =ROUND((SUM(BI121:BI123)),2) -> 0 | I39: 0 | J39: =0 -> 0
D41: Cena s DPH | G41: v | H41: CZK | J41: =SUM(J32:J39) -> 0
D50: Projektant | G50: Zpracovatel
D61: Datum a podpis: | F61: Razítko | G61: Datum a podpis: | J61: Razítko
D65: Objednavatel | G65: Uchazeč
D76: Datum a podpis: | F76: Razítko | G76: Datum a podpis: | J76: Razítko
C82: REKAPITULACE ČLENĚNÍ SOUPISU PRACÍ
C84: Stavba:
E85: =E7 -> Bytový soubor Libuše
C86: Objekt:
E87: 02 - Venkovní objekty a přípojky
C88: Soupis:
E89: =E11 -> IOX06 - přeložka CETIN
C91: Místo: | F91: =F14 -> Praha | I91: Datum: | J91: =IF(J14="","",J14) -> 45000
...

Sheet S041 - Sadové úpravy a ká...
AT2: {c68ff8eb-ced9-4701-a990-a7c95f576625}
AT3: 2
D4: KRYCÍ LIST SOUPISU PRACÍ | M4: v --- níže se nacházejí doplnkové a pomocné údaje k sestavám --- v | AT4: False
D6: Stavba:
E7: ='Rekapitulace stavby'!K6 -> Bytový soubor Libuše
D8: Objekt:
E9: 02 - Venkovní objekty a přípojky
D10: Soupis:
E11: S041 - Sadové úpravy a kácení
D13: KSO: | I13: CC-CZ:
D14: Místo: | F14: Praha | I14: Datum: | J14: ='Rekapitulace stavby'!AN8 -> 45000
D16: Zadavatel: | I16: IČ:
E17: VELTON REAL ESTATE | I17: DIČ:
D19: Uchazeč: | I19: IČ: | J19: ='Rekapitulace stavby'!AN13 -> 08004013
E20: ='Rekapitulace stavby'!E14 -> DMG Stav a.s. | I20: DIČ: | J20: ='Rekapitulace stavby'!AN14 -> CZ 08004013
D22: Projektant: | I22: IČ:
E23: ABMV World s.r.o | I23: DIČ:
D25: Zpracovatel: | I25: IČ:
E26: QSB s.r.o. | I26: DIČ:
D28: Poznámka:
D32: Cena bez DPH | J32: =ROUND(J122,2) -> 1552321.9
F34: Základ daně | I34: Sazba daně | J34: Výše daně
D35: DPH | E35: základní | F35: =ROUND((SUM(BE122:BE171)),2) -> 1552321.9 | I35: 0.21 | J35: =ROUND(((SUM(BE122:BE171))*I35),2) -> 325987.61
E36: snížená | F36: =ROUND((SUM(BF122:BF171)),2) -> 0 | I36: 0.15 | J36: =ROUND(((SUM(BF122:BF171))*I36),2) -> 0
E37: zákl. přenesená | F37: =ROUND((SUM(BG122:BG171)),2) -> 0 | I37: 0.21 | J37: =0 -> 0
E38: sníž. přenesená | F38: =ROUND((SUM(BH122:BH171)),2) -> 0 | I38: 0.15 | J38: =0 -> 0
E39: nulová | F39: =ROUND((SUM(BI122:BI171)),2) -> 0 | I39: 0 | J39: =0 -> 0
D41: Cena s DPH | G41: v | H41: CZK | J41: =SUM(J32:J39) -> 1878309.6
D50: Projektant | G50: Zpracovatel
D61: Datum a podpis: | F61: Razítko | G61: Datum a podpis: | J61: Razítko
D65: Objednavatel | G65: Uchazeč
D76: Datum a podpis: | F76: Razítko | G76: Datum a podpis: | J76: Razítko
C82: REKAPITULACE ČLENĚNÍ SOUPISU PRACÍ
C84: Stavba:
E85: =E7 -> Bytový soubor Libuše
C86: Objekt:
E87: 02 - Venkovní objekty a přípojky
C88: Soupis:
E89: =E11 -> S041 - Sadové úpravy a kácení
C91: Místo: | F91: =F14 -> Praha | I91: Datum: | J91: =IF(J14="","",J14) -> 45000
...

Sheet S044 - Drobná venkovná ar...
AT2: {dd358f9e-ad25-4fe8-895c-b0a5cb6aa627}
AT3: 2
D4: KRYCÍ LIST SOUPISU PRACÍ | M4: v --- níže se nacházejí doplnkové a pomocné údaje k sestavám --- v | AT4: False
D6: Stavba:
E7: ='Rekapitulace stavby'!K6 -> Bytový soubor Libuše
D8: Objekt:
E9: 02 - Venkovní objekty a přípojky
D10: Soupis:
E11: S044 - Drobná venkovná architektura
D13: KSO: | I13: CC-CZ:
D14: Místo: | F14: Praha | I14: Datum: | J14: ='Rekapitulace stavby'!AN8 -> 45000
D16: Zadavatel: | I16: IČ:
E17: VELTON REAL ESTATE | I17: DIČ:
D19: Uchazeč: | I19: IČ: | J19: ='Rekapitulace stavby'!AN13 -> 08004013
E20: ='Rekapitulace stavby'!E14 -> DMG Stav a.s. | I20: DIČ: | J20: ='Rekapitulace stavby'!AN14 -> CZ 08004013
D22: Projektant: | I22: IČ:
E23: ABMV World s.r.o | I23: DIČ:
D25: Zpracovatel: | I25: IČ:
E26: QSB s.r.o. | I26: DIČ:
D28: Poznámka:
D32: Cena bez DPH | J32: =ROUND(J121,2) -> 2080855
F34: Základ daně | I34: Sazba daně | J34: Výše daně
D35: DPH | E35: základní | F35: =ROUND((SUM(BE121:BE152)),2) -> 2080855 | I35: 0.21 | J35: =ROUND(((SUM(BE121:BE152))*I35),2) -> 436979.55
E36: snížená | F36: =ROUND((SUM(BF121:BF152)),2) -> 0 | I36: 0.15 | J36: =ROUND(((SUM(BF121:BF152))*I36),2) -> 0
E37: zákl. přenesená | F37: =ROUND((SUM(BG121:BG152)),2) -> 0 | I37: 0.21 | J37: =0 -> 0
E38: sníž. přenesená | F38: =ROUND((SUM(BH121:BH152)),2) -> 0 | I38: 0.15 | J38: =0 -> 0
E39: nulová | F39: =ROUND((SUM(BI121:BI152)),2) -> 0 | I39: 0 | J39: =0 -> 0
D41: Cena s DPH | G41: v | H41: CZK | J41: =SUM(J32:J39) -> 2517834.5
D50: Projektant | G50: Zpracovatel
D61: Datum a podpis: | F61: Razítko | G61: Datum a podpis: | J61: Razítko
D65: Objednavatel | G65: Uchazeč
D76: Datum a podpis: | F76: Razítko | G76: Datum a podpis: | J76: Razítko
C82: REKAPITULACE ČLENĚNÍ SOUPISU PRACÍ
C84: Stavba:
E85: =E7 -> Bytový soubor Libuše
C86: Objekt:
E87: 02 - Venkovní objekty a přípojky
C88: Soupis:
E89: =E11 -> S044 - Drobná venkovná architektura
C91: Místo: | F91: =F14 -> Praha | I91: Datum: | J91: =IF(J14="","",J14) -> 45000
...

Sheet SO10 - Komunikace, zpevně...
AT2: {c403ff3a-58cd-4272-a7c4-bc3c622904d3}
AT3: 2
D4: KRYCÍ LIST SOUPISU PRACÍ | M4: v --- níže se nacházejí doplnkové a pomocné údaje k sestavám --- v | AT4: False
D6: Stavba:
E7: ='Rekapitulace stavby'!K6 -> Bytový soubor Libuše
D8: Objekt:
E9: 02 - Venkovní objekty a přípojky
D10: Soupis:
E11: SO10 - Komunikace, zpevněné plochy a dopravní značení
D13: KSO: | I13: CC-CZ:
D14: Místo: | F14: Praha | I14: Datum: | J14: ='Rekapitulace stavby'!AN8 -> 45000
D16: Zadavatel: | I16: IČ:
E17: VELTON REAL ESTATE | I17: DIČ:
D19: Uchazeč: | I19: IČ: | J19: ='Rekapitulace stavby'!AN13 -> 08004013
E20: ='Rekapitulace stavby'!E14 -> DMG Stav a.s. | I20: DIČ: | J20: ='Rekapitulace stavby'!AN14 -> CZ 08004013
D22: Projektant: | I22: IČ:
E23: ABMV World s.r.o | I23: DIČ:
D25: Zpracovatel: | I25: IČ:
E26: QSB s.r.o. | I26: DIČ:
D28: Poznámka:
D32: Cena bez DPH | J32: =ROUND(J126,2) -> 2726480.5
F34: Základ daně | I34: Sazba daně | J34: Výše daně
D35: DPH | E35: základní | F35: =ROUND((SUM(BE126:BE367)),2) -> 2726480.5 | I35: 0.21 | J35: =ROUND(((SUM(BE126:BE367))*I35),2) -> 572560.9
E36: snížená | F36: =ROUND((SUM(BF126:BF367)),2) -> 0 | I36: 0.15 | J36: =ROUND(((SUM(BF126:BF367))*I36),2) -> 0
E37: zákl. přenesená | F37: =ROUND((SUM(BG126:BG367)),2) -> 0 | I37: 0.21 | J37: =0 -> 0
E38: sníž. přenesená | F38: =ROUND((SUM(BH126:BH367)),2) -> 0 | I38: 0.15 | J38: =0 -> 0
E39: nulová | F39: =ROUND((SUM(BI126:BI367)),2) -> 0 | I39: 0 | J39: =0 -> 0
D41: Cena s DPH | G41: v | H41: CZK | J41: =SUM(J32:J39) -> 3299041.4
D50: Projektant | G50: Zpracovatel
D61: Datum a podpis: | F61: Razítko | G61: Datum a podpis: | J61: Razítko
D65: Objednavatel | G65: Uchazeč
D76: Datum a podpis: | F76: Razítko | G76: Datum a podpis: | J76: Razítko
C82: REKAPITULACE ČLENĚNÍ SOUPISU PRACÍ
C84: Stavba:
E85: =E7 -> Bytový soubor Libuše
C86: Objekt:
E87: 02 - Venkovní objekty a přípojky
C88: Soupis:
E89: =E11 -> SO10 - Komunikace, zpevněné plochy a dopravní značení
C91: Místo: | F91: =F14 -> Praha | I91: Datum: | J91: =IF(J14="","",J14) -> 45000
...

Sheet SO21 - Venkovní osvětlení
AT2: {919e6489-5d9b-4aa4-a5ea-2d087705e48e}
AT3: 1
D4: KRYCÍ LIST SOUPISU PRACÍ | M4: v --- níže se nacházejí doplnkové a pomocné údaje k sestavám --- v | AT4: False
D6: Stavba:
E7: ='Rekapitulace stavby'!K6 -> Bytový soubor Libuše
D8: Objekt:
E9: 02 - Venkovní objekty a přípojky
D10: Soupis:
E11: SO21 - Venkovní osvětlení
D13: KSO: | I13: CC-CZ:
D14: Místo: | F14: Praha | I14: Datum: | J14: ='Rekapitulace stavby'!AN8 -> 45000
D16: Zadavatel: | I16: IČ:
E17: VELTON REAL ESTATE | I17: DIČ:
D19: Uchazeč: | I19: IČ: | J19: ='Rekapitulace stavby'!AN13 -> 08004013
E20: ='Rekapitulace stavby'!E14 -> DMG Stav a.s. | I20: DIČ: | J20: ='Rekapitulace stavby'!AN14 -> CZ 08004013
D22: Projektant: | I22: IČ:
E23: ABMV World s.r.o | I23: DIČ:
D25: Zpracovatel: | I25: IČ:
E26: QSB s.r.o. | I26: DIČ:
D28: Poznámka:
D32: Cena bez DPH | J32: =ROUND(J125,2) -> 530700
F34: Základ daně | I34: Sazba daně | J34: Výše daně
D35: DPH | E35: základní | F35: =ROUND((SUM(BE125:BE148)),2) -> 0 | I35: 0.21 | J35: =ROUND(((SUM(BE125:BE148))*I35),2) -> 0
E36: snížená | F36: =ROUND((SUM(BF125:BF148)),2) -> 530700 | I36: 0.15 | J36: =ROUND(((SUM(BF125:BF148))*I36),2) -> 79605
E37: zákl. přenesená | F37: =ROUND((SUM(BG125:BG148)),2) -> 0 | I37: 0.21 | J37: =0 -> 0
E38: sníž. přenesená | F38: =ROUND((SUM(BH125:BH148)),2) -> 0 | I38: 0.15 | J38: =0 -> 0
E39: nulová | F39: =ROUND((SUM(BI125:BI148)),2) -> 0 | I39: 0 | J39: =0 -> 0
D41: Cena s DPH | G41: v | H41: CZK | J41: =SUM(J32:J39) -> 610305
D50: Projektant | G50: Zpracovatel
D61: Datum a podpis: | F61: Razítko | G61: Datum a podpis: | J61: Razítko
D65: Objednavatel | G65: Uchazeč
D76: Datum a podpis: | F76: Razítko | G76: Datum a podpis: | J76: Razítko
C82: REKAPITULACE ČLENĚNÍ SOUPISU PRACÍ
C84: Stavba:
E85: =E7 -> Bytový soubor Libuše
C86: Objekt:
E87: 02 - Venkovní objekty a přípojky
C88: Soupis:
E89: =E11 -> SO21 - Venkovní osvětlení
C91: Místo: | F91: =F14 -> Praha | I91: Datum: | J91: =IF(J14="","",J14) -> 45000
...

Sheet SO31 - Příprava území
AT2: {bf81bd70-02b3-46d9-94f0-3e80ee027c41}
AT3: 2
D4: KRYCÍ LIST SOUPISU PRACÍ | M4: v --- níže se nacházejí doplnkové a pomocné údaje k sestavám --- v | AT4: False
D6: Stavba:
E7: ='Rekapitulace stavby'!K6 -> Bytový soubor Libuše
D8: Objekt:
E9: 02 - Venkovní objekty a přípojky
D10: Soupis:
E11: SO31 - Příprava území
D13: KSO: | I13: CC-CZ:
D14: Místo: | F14: Praha | I14: Datum: | J14: ='Rekapitulace stavby'!AN8 -> 45000
D16: Zadavatel: | I16: IČ:
E17: VELTON REAL ESTATE | I17: DIČ:
D19: Uchazeč: | I19: IČ: | J19: ='Rekapitulace stavby'!AN13 -> 08004013
E20: ='Rekapitulace stavby'!E14 -> DMG Stav a.s. | I20: DIČ: | J20: ='Rekapitulace stavby'!AN14 -> CZ 08004013
D22: Projektant: | I22: IČ:
E23: ABMV World s.r.o | I23: DIČ:
D25: Zpracovatel: | I25: IČ:
E26: QSB s.r.o. | I26: DIČ:
D28: Poznámka:
D32: Cena bez DPH | J32: =ROUND(J123,2) -> 420840
F34: Základ daně | I34: Sazba daně | J34: Výše daně
D35: DPH | E35: základní | F35: =ROUND((SUM(BE123:BE141)),2) -> 420840 | I35: 0.21 | J35: =ROUND(((SUM(BE123:BE141))*I35),2) -> 88376.4
E36: snížená | F36: =ROUND((SUM(BF123:BF141)),2) -> 0 | I36: 0.15 | J36: =ROUND(((SUM(BF123:BF141))*I36),2) -> 0
