Workbook

Sheet systém kódování
A1: stavební objekt / building object: | B1: BYTOVÝ SOUBOR LIBUŠE | F1: revize dokumentu / document revision: | G1: 01
A2: dokument / document: | B2: TABULKA SKLADEB A POVRCHŮ / SURFACES AND STRUCTURES TABLE | F2: aktuální stav ke dni / current situation at: | G2: 30/11/2021
A4: SYSTÉM KÓDOVÁNÍ / CODING SYSTEM
A7: Tvar kódu POVRCHU / FINISH Code type
B8: F-00
A10: Tvar kódu SKLADEB PODLAH / FLOOR STRUCTURE Code type
B11: FF-00
B13: ozn. Typu / type mark
B15: číselník (2 číslice) / number
A18: Tvar kódu SKLADEB STĚN / WALL STRUCTURE Code type
B19: WF-00
A21: Tvar kódu SKLADEB STŘECH / ROOF STRUCTURE Code type
B22: RF-00
A24: Tvar kódu SKLADEB PODHLEDŮ / SUSPENDED CEILING STRUCTURE Code type
B25: CF-00
A27: PŘÍLOHY / ANNEXES
A30: POZNÁMKA / NOTE
A31: UVEDENÉ ROZMĚRY A POZICE (KONSTRUKCÍ, ROZVODŮ, TZB..) JSOU JEN ORIENTAČNÍ, ZHOTOVITEL JE POVINEN ZAMĚŘIT SKUTEČNÝ STAV NA MÍSTĚ STAVBY. TATO PROJEKTOVÁ DOKUMENTACE SLOUŽÍ PRO POTŘEBY REALIZACE DÍLA, OVŠEM NENAHRAZUJE DÍLENSKOU DOKUMENTACI. V PŘÍPADĚ ZMĚNY PODKLADŮ, ČI VZNIKU NOVÝCH SKUTEČNOSTÍ JE NUTNÉ INFORMOVAT PROJEKTANTA A DÁLE POSTUPOVAT AŽ PO KOORDINACI, VYDÁNÍ A SCHVÁLENÍ ZMĚNY V PROJEKTOVÉ DOKUMENTACI. V PŘÍPADĚ ROZPORU MEZI JEDNOTLIVÝMI PŘÍLOHAMI V PROJEKTOVÉ DOKUMENTACI JE POTŘEBNÉ NA TENTO ROZPOR UPOZORNIT A VYŽÁDAT SI OFICIÁLNÍ STANOVISKO PROJEKTANTA. DOKUMENTACE BYLA ZPRACOVÁNA NA ZÁKLADĚ INFORMACÍ, PODKLADŮ A ZNALOSTÍ PLATNÝCH KE DNI VYDÁNÍ DOKUMENTACE. DODAVATEL STAVBY MUSÍ DBÁT NA DODRŽOVÁNÍ MONTÁŽNÍCH A TECHNOLOGICKÝCH POKYNŮ PŘÍSLUŠNÝCH VÝROBCŮ STAVEBNÍCH PRVKŮ A KONSTRUKCÍ UVEDENÝCH V TÉTO DOKUMENTACI. DOKUMENTACI JE MOŽNÉ UŽÍVAT VÝHRADNĚ A BEZ VYJÍMKY VE SMYSLU SMLOUVY O DÍLO. DOKUMENTACE JE POVAŽOVÁNA ZA RELEVANTNÍ JEN JAKO CELEK PODLE PLATNÉHO SEZNAMU DOKUMENTACE. NAVRŽENÉ VÝROBKY A MATERIÁLY BUDOU ZHOTOVITELEM PŘEDLOŽENÉ KE SCHVÁLENÍ V RÁMCI VZORKOVÁNÍ. PŘESNÉ UMÍSTĚNÍ KONCOVÝCH PRVKŮ V PODHLEDECH BUDE REALIZOVANÉ PODLE VÝKRESU PODHLEDŮ V ARCHITEKTONICKO-STAVEBNÍ ČÁSTI. PROJEKT INTERIÉRU JE ŘEŠEN SAMOSTATNOU DOKUMENTACÍ.

Sheet povrchy
A1: stavebný objekt / building objects: | C1: ='systém kódování'!B1 -> BYTOVÝ SOUBOR LIBUŠE | E1: revize dokumentu / document revision: | F1: ='systém kódování'!$G$1 -> 01
A2: dokument / document: | C2: ='systém kódování'!B2 -> TABULKA SKLADEB A POVRCHŮ / SURFACES AND STRUCTURES TABLE | E2: aktuální stav ke dni / current situation at: | F2: ='systém kódování'!$G$2 -> 30/11/2021
A4: Kód / Code | C4: Pořadí vrstev / Order of layers | D4: Tloušťka / Thickness (mm) | E4: Technická specifikace / Technical specifications | F4: Referenční výrobek / Reference product
A5: Povrch podlahy 1PP - vjezdová rampa
A6: F | B6: 0 | C6: Penetrační nátěr a vsyp | D6: 2 | E6: vsyp pro pancéřové betonové podlahy se střední a vyšší provozní zátěží, směs speciálních cementů, kompatibilních chemických přísad a tříděných tvrdých plniv s vyšším obsahem zrn vysokého lesku, prováděno ve dvou krocích. Celkové množství vsypu 5kg/m2, povrch zdrsněn metličkovou úpravou. Vsyp vč. ošetření čerstvé směsi akrylátovým nátěrem (0,1-0,2l/m2). Zvýšená odolnost povrchu proti vsakování ropných látek a silničních solí. Systémové uzavření dilatačních spar v ploše a na obvodu. Odolnost v obrusu max. 0,04mm. | F6: např.Sika CZ
A7: Povrch podlahy - společné prostory - nadzemní část
A8: F | B8: 1 | C8: Keramická dlažba | D8: 10 | E8: Slinutá keramická dlažba; formát 600x1200mm; tmavě šedá; protiskluznost tř. R 10 ; dlažba s vysokou pevností v tlaku a ohybu, odolností proti chemikáliím (kyselinám i louhům) a odolností proti hloubkovému opotřebení, , součinitel tření μ≥0,5, spáry vyplněné vhodnou spárovací hmotou, vč. soklu 80mm a dilatačních profilů, dilatační spáry max. 6x6 m; dekor viz. architekt | F8: např. Rako Extra
C9: Lepidlo | D9: 5 | E9: Flexibilní cementové lepidlou pro lepení keramických dlažeb | F9: např. Cemix lepidlo flex extra 045
C10: Penetrace | D10: - | E10: Dle použitého sytému | F10: např. Cemix penetrace H
A11: Povrch podlahy - bytové jednotky - chodby a obchodní jednotky
A12: F | B12: 2 | C12: Keramická dlažba | D12: 10 | E12: Slinutá keramická dlažba; formát 600x600mm; světle šedá; protiskluznost tř. R 10 ; dlažba s vysokou pevností v tlaku a ohybu, odolností proti chemikáliím (kyselinám i louhům) a odolností proti hloubkovému opotřebení, součinitel tření μ≥0,5, spáry vyplněné vhodnou spárovací hmotou, vč. soklu 80mm a dilatačních profilů; dilatační spáry max. 6x6 m; dekor viz. architekt | F12: např. Rako Extra
C13: Lepidlo | D13: 5 | E13: Flexibilní cementové lepidlou pro lepení keramických dlažeb | F13: např. Cemix lepidlo flex extra 045
C14: Penetrace | D14: - | E14: Dle použitého sytému | F14: např. Cemix penetrace H
A15: Povrch podlahy - bytové jednotky - pobytové místnosti
A16: F | B16: 3 | C16: Vinylové dílce | D16: 2.5 | E16: Vinylové dílce lepené; rozměr 230 x 1500 mm; protiskluznost tř. R 10; třída reakce na oheň B; třída zátěže min. 31; vč. soklové lišty bílé, dekor viz. architekt | F16: např. Gerfloor Creation 55
C17: Lepidlo | D17: - | E17: Celoplošné přilepení.Universální disperzní lepidlo. | F17: např. Weberfloor 4815
C18: Penetrace | D18: - | E18: Dle použitého sytému | F18: např. Cemix penetrace H
C19: Vyrovnávací vrstva | D19: 4.5 | E19: Jednosložková samonivelační hmota na bázi cementu; pevnost v tlaku min. 20MPa | F19: např. Cemix 060
A20: Povrch stěn - společné chodby a schodiště
A21: F | B21: 4 | C21: Otěruvzdorný nátěr | D21: 1 | E21: Vnitřní disperzní malířský nátěr e 2 vrstvách; světle šedý; barevný odstín viz. architekt | F21: např. Primalex Inspiro
C22: Penetrace | D22: - | E22: Penetrační nátěr pro disperzní nátěry | F22: např. Primalex univerzální penetrace
C23: Sádrová omítka | D23: 10 | E23: Sádrová omítka zrnitosti do 0,4mm, zahlazen nerezovým hladítkem, přechody mezi různými materiály a rohy vyztužit síťovinou | F23: např. Cemix 016 j
C24: Můstek | D24: - | E24: Dle použitého systému | F24: např. Cemix spojovací můstek
A25: Povrch stěn a stropů - bytové jednotky - pobytové místnosti a obchodní jednotky
A26: F | B26: 5 | C26: Otěruvzdorný nátěr | D26: 1 | E26: Vnitřní disperzní malířský nátěr e 2 vrstvách; bílý; odstín viz. architekt | F26: např. Primalex Polar
C27: Penetrace | D27: - | E27: Penetrační nátěr pro disperzní nátěry | F27: např. Primalex univerzální penetrace
C28: Sádrová omítka | D28: 10 | E28: Sádrová omítka zrnitosti do 0,4mm, zahlazen nerezovým hladítkem, přechody mezi různými materiály a rohy vyztužit síťovinou | F28: např. Cemix 016 j
C29: Můstek | D29: - | E29: Dle použitého systému | F29: např. Cemix spojovací můstek
A30: Povrch stěn - bytové jednotky - koupelny a wc
A31: F | B31: 6 | C31: Keramický obklad | D31: 10 | E31: Slinutý keramický obklad 30x60cm, formát 600x1200mm, bílá, vnější rohy opatřit nerezovou rohovou lištou a horní hrany opatřit nerezovou ukončovací lištou; hydroizolační stěrka vytažená 300mm nad podklahu, za sprchovým koutem do výšky 2000mm nad podlahu, dekor viz. architekt | F31: např. Rako Extra
C32: Lepidlo | D32: 5 | E32: Flexibilní cementové lepidlo. | F32: např. Cemix Flex Extra Plus 045
C33: Hydroizolace | D33: - | E33: Jednosložková disperzní hydroizoalční stěrka. Hydroizolační stěrku vytáhnout min. 300 mm nad podlahu a zároveň po celé výšce za sprchpvým koutem a vanou. | F33: např. Cemix Cemelastik IN
C34: Penetrace | D34: - | E34: Dle použitého sytému. | F34: např. Cemix penetrace H
C35: Jádrová omítka | D35: 10 | E35: Jemná jádrová omítka zrnitosti do 1,2mm, povrch zahlazen filcovým hladítkem, max. nerovnosti povrchu do 3mm | F35: např. Cemix 082 j
A36: Povrch podlahy exteriérový - balkóny
A37: F | B37: 7 | C37: Keramická dlažba exteriérová | D37: 20 | E37: Slinutá keramická dlažba kalibrovaná 600x600mm; protiskluznost tř. R 11; Světle šedá; dekor viz. architekt | F37: např. Rako Quarzit Outdoor
C38: Rektifikovatelné terče pod dlažbu | D38: 18 | E38: Teleskopické plastové terče pro dlažbu na pryžových podložkách. | F38: GUTTA
A39: Povrch fasády - obklad
A40: F | B40: 8 | C40: Keramické obkladové pásky | D40: 25 | E40: Ražený keramický obkladový pásek formát 215 x 65mm, vč. spárovací hmoty, dle výběru architekta | F40: např. Terca + Polyblend S
C41: Lepidlo | D41: 5 | E41: Tenkostěná mrazuvzdorná cementová lepící malta pro obkladové pásky. | F41: např. Terca Excelbond, C2TE S1
...

Sheet skladby_podlah
A1: stavebný objekt / building objects: | C1: ='systém kódování'!B1 -> BYTOVÝ SOUBOR LIBUŠE | F1: revize dokumentu / document revision: | G1: ='systém kódování'!$G$1 -> 01
A2: dokument / document: | C2: ='systém kódování'!B2 -> TABULKA SKLADEB A POVRCHŮ / SURFACES AND STRUCTURES TABLE | F2: aktuální stav ke dni / current situation at: | G2: ='systém kódování'!$G$2 -> 30/11/2021
A4: Kód / Code | C4: Pořadí vrstev / Order of layers | D4: Tloušťka / Thickness (mm) | E4: Celková tl.. / Total thickness (mm) | F4: Technická specifikace / Technical specifications | G4: Referenční výrobek / Reference product
A5: podlaha na terénu
A6: FF | B6: 1 | C6: Povrchová úprava | D6: 3.8 | E6: =SUM(D6:D8) -> 3.8 | F6: viz Tabulka povrchů
C7: Železobetonová deska | F7: viz Stavebně-konstrukční část projektu
C8: Podkladní beton | F8: beton C12/15 X0
A9: rampa do garáže
A10: FF | B10: 2 | C10: Povrchová úprava | D10: 2 | E10: =SUM(D10:D12) -> 2 | F10: viz Tabulka povrchů
C11: Železobetonová pojížděná deska | F11: viz Stavebně-konstrukční část projektu
C12: Podkladní beton | F12: beton C12/15 X0
A13: podlaha na terénu s hydroizolací proti radonu
A14: FF | B14: 3 | C14: Povrchová úprava | D14: 3.8 | E14: =SUM(D14:D19) -> 11.8 | F14: viz Tabulka povrchů
C15: Železobetonová deska | F15: viz Stavebně-konstrukční část projektu
C16: Ochranná vrstva hydroizolace proti radonu | D16: 4 | F16: Povlaková hydroizolace min. z jedné vrstvy asfaltového pásu | G16: např. GLASTEK 40 SPECIAL MINERAL
C17: Hydroizolační vrstva proti radonu | D17: 4 | F17: Povlaková hydroizolace min. z jedné vrstvy asfaltového pásu, hydroizolační vrstvu je nutné provést s přesahem do okolních místností do vzdálenosti 1,0m od úrovně vnějšího líce zdiva vymezující prostor společných prostor | G17: např. GLASTEK 40 SPECIAL MINERAL
C18: Penetrace | D18: 0 | F18: Asfaltová penetrační emulze | G18: např. Dekprimer
C19: Podkladní beton | F19: beton C12/15 X0
A20: podlaha nad exteriérem
A21: FF | B21: 10 | C21: Povrchová úprava | D21: 10 | E21: =SUM(D21:D27) -> 130 | F21: viz Tabulka povrchů
C22: Roznášecí vrstva s kari sítí | D22: 55 | F22: Cementový potěr třídy pevnosti v tahu při ohybu F5 podle EN 13813, pevnost v tlaku 25 MPa, kari síť 150/150/4, vč. dilatační okrajové pásky, dilatovat v roztečích max. 6x6m nebo při proměru stran větších než 1:2. | G22: např. Cemix 020
C23: Separece | D23: - | F23: PE folie | G23: např. Deksepar
C24: Kročejová izolace | D24: 25 | F24: Minerální hydrofobizovaná vlna, dynamická tuhost 23MN/m3 | G24: např. Isover N
C25: Instalační vrstva | D25: 40 | F25: Polysterén beton PSB 50; max. 400 kg/m3 (v suchém stavu)
C26: Železebetonová deska | F26: viz Stavebně-konstrukční část projektu
C27: Tepelná izolace z minerální vlny | F27: izolační fasádní desky s minerální čedičové vlny,Čedičová vlna λ = 0,040, Pevnost v tahu TR 30 kPa | G27: ISOVER Top V Final
A28: podlaha nad suterénem - dlažba
A29: FF | B29: 20 | C29: Povrchová úprava | D29: 15 | E29: =SUM(D29:D35) -> 130 | F29: viz Tabulka povrchů
C30: Roznášecí vrstva s kari sítí | D30: 50 | F30: Cementový potěr třídy pevnosti v tahu při ohybu F5 podle EN 13813, pevnost v tlaku 25 MPa, kari síť 150/150/4, vč. dilatační okrajové pásky, dilatovat v roztečích max. 6x6m nebo při proměru stran větších než 1:2. | G30: např. Cemix 020
C31: Separece | D31: - | F31: PE folie | G31: např. Deksepar
C32: Kročejová izolace | D32: 25 | F32: Minerální hydrofobizovaná vlna, dynamická tuhost 23MN/m3 | G32: např. Isover N
C33: Instalační vrstva | D33: 40 | F33: Polysterén beton PSB 50; max. 400 kg/m3 (v suchém stavu)
C34: Železebetonová deska | F34: viz Stavebně-konstrukční část projektu
C35: Povrchová úprava | F35: viz Tabulka povrchů
A36: podlaha nad suterénem - vinyl
A37: FF | B37: 21 | C37: Povrchová úprava | D37: 7 | E37: =SUM(D37:D43) -> 130 | F37: viz Tabulka povrchů
C38: Roznášecí vrstva s kari sítí | D38: 58 | F38: Cementový potěr třídy pevnosti v tahu při ohybu F5 podle EN 13813, pevnost v tlaku 25 MPa, kari síť 150/150/4, vč. dilatační okrajové pásky, dilatovat v roztečích max. 6x6m nebo při proměru stran větších než 1:2. | G38: např. Cemix 020
C39: Separece | D39: - | F39: PE folie | G39: např. Deksepar
C40: Kročejová izolace | D40: 25 | F40: Minerální hydrofobizovaná vlna, dynamická tuhost 23MN/m3 | G40: např. Isover N
C41: Instalační vrstva | D41: 40 | F41: Polysterén beton PSB 50; max. 400 kg/m3 (v suchém stavu) | G41: Liapor Mix
...

Sheet skladby sten
A1: stavebný objekt / building objects: | C1: ='systém kódování'!B1 -> BYTOVÝ SOUBOR LIBUŠE | F1: revize dokumentu / document revision: | G1: ='systém kódování'!$G$1 -> 01
A2: dokument / document: | C2: ='systém kódování'!B2 -> TABULKA SKLADEB A POVRCHŮ / SURFACES AND STRUCTURES TABLE | F2: aktuální stav ke dni / current situation at: | G2: ='systém kódování'!$G$2 -> 30/11/2021
A4: Kód / Code | C4: Pořadí vrstev / Order of layers | D4: Tloušťka / Thickness (mm) | E4: Celková tl.. / Total thickness (mm) | F4: Technická specifikace / Technical specifications | G4: Referenční výrobek / Reference product
A5: suterenní obvodová stěna
A6: WF | B6: 01 | C6: Zásyp stavební jámy | D6: - | E6: =SUM(D6:D8) -> 250
C7: Železobeton | D7: 250 | F7: Vodostavebný železobeton, viz Stavebně-konstrukční část projektu
C8: Povrchová úprava | D8: - | F8: viz Tabulka Místností a Tabulka Povrchů
A9: suterenní obvodová stěna - podsoklová část (1,0m pod terén)
A10: WF | B10: 2 | C10: Ochranná vrstva | D10: 3 | E10: =SUM(D10:D15) -> 337 | F10: Netkaná geotextilie 300g/m2 | G10: např. Filtek 300
C11: Tepelná izolace | D11: 80 | F11: Extrudovaný polystaren (XPS) nenasákavý, min. součinitel tel. vodivosti λ = 0,034 W/mK | G11: např. DEKPERIMETER SD 150
C12: Hydroizolační vrstva | D12: 4 | F12: Modifikovaný SBS asfaltový pás s nosnou vložkou ze skelné tkaniny | G12: např. Glastek 40
C13: Penetrace | D13: 0 | F13: Adhézní spojovací můstek | G13: např. Cemix Kontakt
C14: Železobeton | D14: 250 | F14: Vodostavebný železobeton, viz Stavebně-konstrukční část projektu
C15: Povrchová úprava | D15: - | F15: viz Tabulka Místností a Tabulka Povrchů
A16: nadzemní obvodová stěna - soklové zdivo
A17: WF | B17: 03 | C17: Cihelné pásky | D17: 25 | E17: =SUM(D17:D25) -> 485 | F17: viz Tabulka povrchů
C18: Lepidlo | D18: 5 | F18: viz Tabulka povrchů
C19: Výztužná vrstva | D19: 4 | F19: Lepící a stěrková hmota vč. výztužné tkaniny | G19: např. Cemix Comfort 135
C20: Tepelná izolace | D20: 60 | F20: Extrudovaný polystaren (XPS) nenasákavý, min. součinitel tel. vodivosti λ = 0,034 W/mK | G20: např. DEKPERIMETER SD 150
C21: Lepidlo | D21: 4 | F21: Lepící hmota
C22: Hydroizolační vrstva | D22: 4 | F22: SBS asfaltový pás | G22: např. Glastek 40
C23: Penetrace | D23: 0 | F23: Asfaltová penetrační emulze | G23: např. Dekprimer
C24: Cementový postřik | D24: 3 | F24: Cementová malta pro úpravu podkladu | G24: např. Cemix 052
C25: Obvodové zdivo keramické s vloženou minerální vatou | D25: 380 | F25: keramické tvárnice broušené P+D vyplněné minerální vatou | G25: např. Porotherm 38TBS Profi
C26: Povrchová úprava | D26: - | F26: viz Tabulka Místností a Tabulka Povrchů
A27: nadzemní obvodová stěna - zdivo
A28: WF | B28: 10 | C28: Cihelné pásky | D28: 25 | E28: =SUM(D28:D32) -> 485 | F28: viz Tabulka povrchů
C29: Lepidlo | D29: 5 | F29: viz Tabulka povrchů
C30: Jádrová omítka | D30: 12 | F30: Vápenocementová jádrová omítka | G30: např. Cemix 012
C31: Cementový postřik | D31: 3 | F31: Cementová malta pro úpravu podkladu | G31: např. Cemix 052
C32: Obvodové zdivo keramické s vloženou minerální vatou | D32: 440 | F32: keramické tvárnice broušené P+D vyplněné minerální vatou | G32: např. Porotherm 44TB Profi
C33: Povrchová úprava | D33: - | F33: viz Tabulka Místností a Tabulka Povrchů
A34: nadzemní obvodová stěna - železobeton štít schodiště k šikmé střeše
A35: WF | B35: 11 | C35: Cihelné pásky | D35: 25 | E35: =SUM(D35:D43) -> 564 | F35: viz Tabulka povrchů
C36: Lepidlo | D36: 5 | F36: viz Tabulka povrchů
C37: Výztužná vrstva | D37: 4 | F37: Lepící a stěrková hmota vč. výztužné tkaniny | G37: např. Cemix Comfort 135
C38: Tepelná izolace | D38: 200 | F38: Desky EPS 70 F z expandovaného fasádního pěnového polystyrenu; min. součinitel tel. vodivosti λ = 0,039 W/mK; vč. kotvících hmoždinek | G38: např. ISOVER EPS 70F
C39: Lepidlo | D39: 5 | F39: Cementová lepící hmota. | G39: např. Cemix Comfort 135
C40: Penetrace | D40: 0 | F40: Adhézní spojovací můstek. | G40: např. Cemix Kontakt
C41: Železobeton | D41: 250 | F41: viz Stavebně-konstrukční část projektu
...

Sheet skladby strech
A1: stavebný objekt / building objects: | C1: ='systém kódování'!B1 -> BYTOVÝ SOUBOR LIBUŠE | F1: revize dokumentu / document revision: | G1: ='systém kódování'!$G$1 -> 01
A2: dokument / document: | C2: ='systém kódování'!B2 -> TABULKA SKLADEB A POVRCHŮ / SURFACES AND STRUCTURES TABLE | F2: aktuální stav ke dni / current situation at: | G2: ='systém kódování'!$G$2 -> 30/11/2021
A4: Kód / Code | C4: Pořadí vrstev / Order of layers | D4: Tloušťka / Thickness (mm) | E4: Celková tl.. / Total thickness (mm) | F4: Technická specifikace / Technical specifications | G4: Referenční výrobek / Reference product
A5: střecha sedlová
A6: RF | B6: 10 | C6: Keramická pálená krytina skládaná | D6: 30 | E6: =SUM(D6:D14) -> 485 | F6: viz Tabulka povrchů
C7: Laťování - vzduchová mezera | D7: 40 | F7: Dřevěné nosné střešní latě 30x40 mm ze smrkového dřeva řádné vysušeného s hloubkovou impregnací
C8: Laťování - provětrávaná mezera | D8: 40 | F8: Dřevěné kontralatě 30x40 mm ze smrkového dřeva řádné vysušeného s hloubkovou impregnací
C9: Pojistná hydroizolace | D9: 0 | F9: Difuzně otevřená fólie lehkého typu, ekvivalentní difuzní tloušťka sd=0,02 m | G9: např. Dekten Multi Pro II
C10: Nadkrokevní dřevěné kontralatě vyplněné minerální izolací | D10: 80 | F10: Dřevěné hranoly - viz Stavebně-konstrukční část projektu, připevněné rovnoběžně s krokvemi na nosnou ocelovou konstukci krovu, vyplněno tepelnou izolací z hydrofobizované minerální skelné vlny; λ = 0,035 W/mK | G10: např. Isover Multiplat 35
C11: Ocelové krokve vyplněné minerální izolací | D11: 220 | F11: HEB 220 vč. zavětrování - viz Stavebně-konstrukční část projektu, vyplněno tepelnou izolací z hydrofobizované minerální skelné vlny; λ = 0,035 W/mK | G11: např. Isover Multiplat 35
C12: Parozábrana | D12: 0 | F12: Fólie s hliníkovou vložkou, ekvivalentní difuzní tloušťka Sd>300 m; přesah ve styku min. 100m a spojen oboustrannou butylkaučukovou páskou | G12: např. Dekfon N AL 170 Special
C13: Ocelová konstrukce instalační předstěny vyplněná tepelnou izolací | D13: 50 | F13: Profily CD 60x27 + minerální tepelné izolace tl. 40mm, vč. přímých závěsů | G13: např. Knauf D112 + Isover Multiplat 35
C14: Vnitřní SDK záklop dvojitý | D14: 25 | F14: SDK desky 2 x 12.5mm, | G14: např. Knauf GKB
A15: vegetační střecha nad suterénem
A16: RF | B16: 11 | C16: vegetační vrstva | D16: 300 | E16: =SUM(D16:D26) -> 683.5 | F16: substrát - viz Sadové úpravy, tl. 300-400mm
C17: Separační textilie | D17: 2 | F17: Netkaná textilie ze 100% polypropylenu, 200 g/m2 | G17: např. Filtek 200
C18: Drenážní vrstva | D18: 20 | F18: Perforovaná nopová HDPE folie, tl. stěny 1mm | G18: např. Dekdren T20 garden
C19: Separační textilie | D19: 3 | F19: Netkaná textilie ze 100% polypropylenu, 300 g/m2 | G19: např. Filtek 300
C20: Hydroizolační fólie | D20: 1.5 | F20: mPVC fólie 1,5mm s výztužnou tkaninou, určená pro zatěžovací vrstvy a odolná prorůstání kořenů | G20: např. DEKPLAN 77
C21: Separační textilie | D21: 3 | F21: Netkaná textilie ze 100% polypropylenu, 300 g/m2 | G21: např. Filtek 300
C22: Tepelná izolace | D22: 200 | F22: Stabilizovaný pěnový polystyren EPS 200, λ = 0,034 W/mK,t rvalá zatížitelnost v tlaku max. 3600 kg/m2 při def. < 2% | G22: např. Isover EPS 200
C23: Spádové klíny | D23: 150 | F23: Stabilizovaný pěnový polystyren EPS 150, spád min.2%, λ = 0,035 W/mK,t rvalá zatížitelnost v tlaku max. 3000 kg/m2 při def. < 2%, tl. 50-150mm | G23: např. Isover EPS 150
C24: Parozábrana | D24: 4 | F24: SBS modifikovaný asfaltový pás celoplošně natavený | G24: např. Glastek AL 40 mineral
C25: Asfaltová penetrace | D25: 0 | F25: Asfaltová vodou ředitelná emulze | G25: např. Dekprimer
C26: Nosná železobetonová deska | F26: viz Stavebně-konstrukční část projektu
A27: terasa nad suterénem
A28: RF | B28: 12 | C28: Pochozí vrstva na rektifikačních terčích | D28: 218.5 | E28: =SUM(D28:D35) -> 380 | F28: viz Tabulka povrchů
C29: Separační textilie | D29: 3 | F29: Netkaná textilie ze 100% polypropylenu, 300 g/m2 | G29: např. Filtek 300
C30: Hydroizolační fólie | D30: 1.5 | F30: mPVC fólie 1,5mm s výztužnou tkaninou, určená pro zatěžovací vrstvy a odolná prorůstání kořenů | G30: např. DEKPLAN 77
C31: Separační textilie | D31: 3 | F31: Netkaná textilie ze 100% polypropylenu, 300 g/m2 | G31: např. Filtek 300
C32: Spádové klíny | D32: 150 | F32: Stabilizovaný pěnový polystyren EPS 150, spád min.2%, λ = 0,035 W/mK,t rvalá zatížitelnost v tlaku max. 3000 kg/m2 při def. < 2%, tl. 50-150mm | G32: např. Isover EPS 150
C33: Parozábrana | D33: 4 | F33: SBS modifikovaný asfaltový pás celoplošně natavený | G33: např. Glastek AL 40 mineral
C34: Asfaltová penetrace | D34: 0 | F34: Asfaltová vodou ředitelná emulze | G34: např. Dekprimer
C35: Nosná železobetonová deska | F35: viz Stavebně-konstrukční část projektu
A36: chodník nad suterénem - vstupy do objektů
A37: RF | B37: 13 | C37: Pochozí dlažba | D37: 60 | E37: =SUM(D37:D46) -> 430 | F37: viz část projektu Komunikace
C38: Štěrkové lóže tl.117-207 pro vyrovnání spádu | D38: 118.5 | F38: viz část projektu Komunikace
C39: Separační textilie | D39: 3 | F39: Netkaná textilie ze 100% polypropylenu, 300 g/m2 | G39: např. Filtek 300
C40: Hydroizolační fólie | D40: 1.5 | F40: mPVC fólie 1,5mm s výztužnou tkaninou, určená pro zatěžovací vrstvy a odolná prorůstání kořenů | G40: např. DEKPLAN 77
C41: Separační textilie | D41: 3 | F41: Netkaná textilie ze 100% polypropylenu, 300 g/m2 | G41: např. Filtek 300
...

Sheet podhledy
A1: stavebný objekt / building objects: | C1: ='systém kódování'!B1 -> BYTOVÝ SOUBOR LIBUŠE | F1: revize dokumentu / document revision: | G1: ='systém kódování'!$G$1 -> 01
A2: dokument / document: | C2: ='systém kódování'!B2 -> TABULKA SKLADEB A POVRCHŮ / SURFACES AND STRUCTURES TABLE | F2: aktuální stav ke dni / current situation at: | G2: ='systém kódování'!$G$2 -> 30/11/2021
A4: Kód / Code | C4: Pořadí vrstev / Order of layers | D4: Tloušťka / Thickness (mm) | E4: Celková tl.. / Total thickness (mm) | F4: Technická specifikace / Technical specifications | G4: Referenční výrobek / Reference product
A5: podhled balkónu a objektových vstupů
A6: CF | B6: 10 | C6: Systémové zavěšení | D6: 54 | E6: =SUM(D6:D8) -> 67.5 | F6: Systémové zavěšení pro venkovní použití se zvýšenou odolností proti korozi | G6: např. Knauf
C7: Pevný podhled do vlhka | D7: 12.5 | F7: Cementová deska | G7: např. Knauf Aquapanel
C8: Povrchová úprava | D8: 1 | F8: viz Tabulka povrchů
A9: podhled chodeb
A10: CF | B10: 20 | C10: Systémové zavěšení | D10: 54 | E10: =SUM(D10:D12) -> 67.5 | F10: Systémové zavěšení ve 2 vrstvách, 2 x CD 60x27 | G10: např. Knauf D112
C11: Pevný SDK podhled | D11: 12.5 | F11: SDK deska 12.5mm, neimpregnovaná | G11: např. Knauf GKB
C12: Povrchová úprava | D12: 1 | F12: viz Tabulka povrchů
A13: podhled koupelen a wc
A14: CF | B14: 21 | C14: Systémové zavěšení | D14: 54 | E14: =SUM(D14:D16) -> 67.5 | F14: Systémové zavěšení ve 2 vrstvách, 2 x CD 60x27 | G14: např. Knauf D112
C15: Pevný SDK podhled do vlhka | D15: 12.5 | F15: SDK deska 12.5mm, impregnovaná | G15: např. Knauf GKBi
C16: Povrchová úprava | D16: 1 | F16: viz Tabulka povrchů
