Workbook

Sheet Rekapitulace stavby
A1: Export Komplet | BA1: 2.0 | BT1: False | BU1: False | BV1: {c5aee045-5a0a-4692-81b8-0acee831865f}
AR2: >> skryté sloupce << | BS2: 0,01 | BT2: 21
BS3: 0,01 | BT3: 15
D4: REKAPITULACE STAVBY | AS4: v --- níže se nacházejí doplnkové a pomocné údaje k sestavám --- v | BS4: 0,001
D5: Kód: | K5: 011-26 | BS5: 0,01
D6: Stavba: | K6: I/26 Kyšice - Plzeň, Hřbitovní | BS6: 0,1
D7: KSO: | AK7: CC-CZ: | BS7: 1
D8: Místo: | AK8: Datum: | AN8: 20. 1. 2026 | BS8: 10
BS9: 100
D10: Zadavatel: | AK10: IČ: | AN10: 65993390 | BS10: 0,1
E11: Ředitelství silnic a dálnic s.p. | AK11: DIČ: | AN11: CZ65993390 | BS11: 0,1
BS12: 0,1
D13: Zhotovitel: | AK13: IČ: | BS13: 0,1
AK14: DIČ: | BS14: 0,1
BS15: False
D16: Projektant: | AK16: IČ: | AN16: 29159342 | BS16: False
E17: Woring s.r.o. | AK17: DIČ: | AN17: CZ29159342 | BS17: False
BS18: 0,01
D19: Zpracovatel: | AK19: IČ: | BS19: 0,01
E20: Pavel Vachtl | AK20: DIČ: | BS20: True
D22: Poznámka:
D26: Cena bez DPH | AK26: =ROUND(AG94,2) -> #REF!
L28: Sazba daně | W28: Základ daně | AK28: Výše daně
D29: DPH | F29: základní | L29: 0.21 | W29: =ROUND(AZ94, 2) -> #REF! | AK29: =ROUND(AV94, 2) -> #REF!
F30: snížená | L30: 0.15 | W30: =ROUND(BA94, 2) -> #REF! | AK30: =ROUND(AW94, 2) -> #REF!
F31: zákl. přenesená | L31: 0.21 | W31: =ROUND(BB94, 2) -> #REF! | AK31: 0
F32: sníž. přenesená | L32: 0.15 | W32: =ROUND(BC94, 2) -> #REF! | AK32: 0
F33: nulová | L33: 0 | W33: =ROUND(BD94, 2) -> #REF! | AK33: 0
D35: Cena s DPH | T35: v | X35: CZK | AK35: =SUM(AK26:AK33) -> #REF!
D49: Projektant | AH49: Zpracovatel
D60: Datum a podpis: | V60: Razítko | AH60: Datum a podpis: | AM60: Razítko
D64: Objednavatel | AH64: Zhotovitel
D75: Datum a podpis: | V75: Razítko | AH75: Datum a podpis: | AM75: Razítko
C82: REKAPITULACE OBJEKTŮ STAVBY A SOUPISŮ PRACÍ
C84: Kód: | L84: =K5 -> 011-26
C85: Stavba: | L85: =K6 -> I/26 Kyšice - Plzeň, Hřbitovní
C87: Místo: | L87: =IF(K8="","",K8) | AI87: Datum: | AM87: =IF(AN8= "","",AN8) -> 20. 1. 2026
C89: Zadavatel: | L89: =IF(E11= "","",E11) -> Ředitelství silnic a dálnic s.p. | AI89: Projektant: | AM89: =IF(E17="","",E17) -> Woring s.r.o. | AS89: Informatívní údaje z listů zakázek
C90: Zhotovitel: | L90: =IF(E14="","",E14) | AI90: Zpracovatel: | AM90: =IF(E20="","",E20) -> Pavel Vachtl
C92: Kód | I92: Popis | AG92: Cena bez DPH [CZK] | AN92: Cena s DPH [CZK] | AQ92: Typ | AS92: z toho Ostat._x000D_ náklady [CZK] | AT92: DPH [CZK] | AU92: Normohodiny [h] | AV92: DPH základní [CZK] | AW92: DPH snížená [CZK] | AX92: DPH základní přenesená_x000D_ [CZK] | AY92: DPH snížená přenesená_x000D_ [CZK] | AZ92: Základna_x000D_ DPH základní | BA92: Základna_x000D_ DPH snížená | BB92: Základna_x000D_ DPH zákl. přenesená | BC92: Základna_x000D_ DPH sníž. přenesená | BD92: Základna_x000D_ DPH nulová
...

Sheet 001 - Vedlejsi a ostatni ...
L2: >> skryté sloupce << | AT2: {f576d6a3-f2c1-4b6e-abea-65d22b6c471f}
AT3: -1
D4: KRYCÍ LIST SOUPISU PRACÍ | M4: v --- níže se nacházejí doplnkové a pomocné údaje k sestavám --- v | AT4: False
D6: Stavba:
E7: ='Rekapitulace stavby'!K6 -> I/26 Kyšice - Plzeň, Hřbitovní
D8: Objekt:
E9: 001 - Vedlejsi a ostatni naklady
D11: KSO: | I11: CC-CZ:
D12: Místo: | I12: Datum: | J12: ='Rekapitulace stavby'!AN8 -> 20. 1. 2026
D14: Zadavatel: | I14: IČ: | J14: 65993390
E15: Ředitelství silnic a dálnic s.p. | I15: DIČ: | J15: CZ65993390
D17: Zhotovitel: | I17: IČ: | J17: ='Rekapitulace stavby'!AN13
E18: ='Rekapitulace stavby'!E14 | I18: DIČ: | J18: ='Rekapitulace stavby'!AN14
D20: Projektant: | I20: IČ: | J20: 29159342
E21: Woring s.r.o. | I21: DIČ: | J21: CZ29159342
D23: Zpracovatel: | I23: IČ: | J23: =IF('Rekapitulace stavby'!AN19="","",'Rekapitulace stavby'!AN19)
E24: =IF('Rekapitulace stavby'!E20="","",'Rekapitulace stavby'!E20) -> Pavel Vachtl | I24: DIČ: | J24: =IF('Rekapitulace stavby'!AN20="","",'Rekapitulace stavby'!AN20)
D26: Poznámka:
D30: Cena bez DPH | J30: =ROUND(J118, 2) -> 0
F32: Základ daně | I32: Sazba daně | J32: Výše daně
D33: DPH | E33: základní | F33: =ROUND((SUM(BE118:BE155)), 2) -> 0 | I33: 0.21 | J33: =ROUND(((SUM(BE118:BE155))*I33), 2) -> 0
E34: snížená | F34: =ROUND((SUM(BF118:BF155)), 2) -> 0 | I34: 0.15 | J34: =ROUND(((SUM(BF118:BF155))*I34), 2) -> 0
E35: zákl. přenesená | F35: =ROUND((SUM(BG118:BG155)), 2) -> 0 | I35: 0.21 | J35: =0 -> 0
E36: sníž. přenesená | F36: =ROUND((SUM(BH118:BH155)), 2) -> 0 | I36: 0.15 | J36: =0 -> 0
E37: nulová | F37: =ROUND((SUM(BI118:BI155)), 2) -> 0 | I37: 0 | J37: =0 -> 0
D39: Cena s DPH | G39: v | H39: CZK | J39: =SUM(J30:J37) -> 0
D50: Projektant | G50: Zpracovatel
D61: Datum a podpis: | F61: Razítko | G61: Datum a podpis: | J61: Razítko
D65: Objednavatel | G65: Zhotovitel
D76: Datum a podpis: | F76: Razítko | G76: Datum a podpis: | J76: Razítko
C82: REKAPITULACE ČLENĚNÍ SOUPISU PRACÍ
C84: Stavba:
E85: =E7 -> I/26 Kyšice - Plzeň, Hřbitovní
C86: Objekt:
E87: =E9 -> 001 - Vedlejsi a ostatni naklady
C89: Místo: | F89: =F12 | I89: Datum: | J89: =IF(J12="","",J12) -> 20. 1. 2026
C91: Zadavatel: | F91: =E15 -> Ředitelství silnic a dálnic s.p. | I91: Projektant: | J91: =E21 -> Woring s.r.o.
C92: Zhotovitel: | F92: =IF(E18="","",E18) | I92: Zpracovatel: | J92: =E24 -> Pavel Vachtl
C94: Kód dílu - Popis | J94: Cena celkem [CZK]
C96: Náklady ze soupisu prací | J96: =J118 -> 0 | AU96: -1
...

Sheet 101 - Oprava vozovky (km ...
L2: >> skryté sloupce << | AT2: {9084f3c3-92e0-4a23-83ee-f324d78c3d21} | AZ2: M1 | BA2: M1 | BC2: 2,25 | BD2: 2
AT3: -1
D4: KRYCÍ LIST SOUPISU PRACÍ | M4: v --- níže se nacházejí doplnkové a pomocné údaje k sestavám --- v | AT4: False
D6: Stavba:
E7: ='Rekapitulace stavby'!K6 -> I/26 Kyšice - Plzeň, Hřbitovní
D8: Objekt:
E9: 101 - Oprava vozovky (km 2,74-4,84)
D11: KSO: | I11: CC-CZ:
D12: Místo: | I12: Datum: | J12: ='Rekapitulace stavby'!AN8 -> 20. 1. 2026
D14: Zadavatel: | I14: IČ: | J14: 65993390
E15: Ředitelství silnic a dálnic s.p. | I15: DIČ: | J15: CZ65993390
D17: Zhotovitel: | I17: IČ: | J17: ='Rekapitulace stavby'!AN13
E18: ='Rekapitulace stavby'!E14 | I18: DIČ: | J18: ='Rekapitulace stavby'!AN14
D20: Projektant: | I20: IČ: | J20: 29159342
E21: Woring s.r.o. | I21: DIČ: | J21: CZ29159342
D23: Zpracovatel: | I23: IČ: | J23: =IF('Rekapitulace stavby'!AN19="","",'Rekapitulace stavby'!AN19)
E24: =IF('Rekapitulace stavby'!E20="","",'Rekapitulace stavby'!E20) -> Pavel Vachtl | I24: DIČ: | J24: =IF('Rekapitulace stavby'!AN20="","",'Rekapitulace stavby'!AN20)
D26: Poznámka:
D30: Cena bez DPH | J30: =ROUND(J125, 2) -> 0
F32: Základ daně | I32: Sazba daně | J32: Výše daně
D33: DPH | E33: základní | F33: =ROUND((SUM(BE125:BE514)), 2) -> 0 | I33: 0.21 | J33: =ROUND(((SUM(BE125:BE514))*I33), 2) -> 0
E34: snížená | F34: =ROUND((SUM(BF125:BF514)), 2) -> 0 | I34: 0.15 | J34: =ROUND(((SUM(BF125:BF514))*I34), 2) -> 0
E35: zákl. přenesená | F35: =ROUND((SUM(BG125:BG514)), 2) -> 0 | I35: 0.21 | J35: =0 -> 0
E36: sníž. přenesená | F36: =ROUND((SUM(BH125:BH514)), 2) -> 0 | I36: 0.15 | J36: =0 -> 0
E37: nulová | F37: =ROUND((SUM(BI125:BI514)), 2) -> 0 | I37: 0 | J37: =0 -> 0
D39: Cena s DPH | G39: v | H39: CZK | J39: =SUM(J30:J37) -> 0
D50: Projektant | G50: Zpracovatel
D61: Datum a podpis: | F61: Razítko | G61: Datum a podpis: | J61: Razítko
D65: Objednavatel | G65: Zhotovitel
D76: Datum a podpis: | F76: Razítko | G76: Datum a podpis: | J76: Razítko
C82: REKAPITULACE ČLENĚNÍ SOUPISU PRACÍ
C84: Stavba:
E85: =E7 -> I/26 Kyšice - Plzeň, Hřbitovní
C86: Objekt:
E87: =E9 -> 101 - Oprava vozovky (km 2,74-4,84)
C89: Místo: | F89: =F12 | I89: Datum: | J89: =IF(J12="","",J12) -> 20. 1. 2026
C91: Zadavatel: | F91: =E15 -> Ředitelství silnic a dálnic s.p. | I91: Projektant: | J91: =E21 -> Woring s.r.o.
C92: Zhotovitel: | F92: =IF(E18="","",E18) | I92: Zpracovatel: | J92: =E24 -> Pavel Vachtl
C94: Kód dílu - Popis | J94: Cena celkem [CZK]
C96: Náklady ze soupisu prací | J96: =J125 -> 0 | AU96: -1
...

Sheet 102 - Oprava vozovky (km ...
L2: >> skryté sloupce << | AT2: {3820f1c8-1ee3-4534-9d18-efb7bbe42a5e} | AZ2: A169 | BA2: A169 | BC2: 2 | BD2: 2
AT3: -1
D4: KRYCÍ LIST SOUPISU PRACÍ | M4: v --- níže se nacházejí doplnkové a pomocné údaje k sestavám --- v | AT4: False
D6: Stavba:
E7: ='Rekapitulace stavby'!K6 -> I/26 Kyšice - Plzeň, Hřbitovní
D8: Objekt:
E9: 102 - Oprava vozovky (km 4,84-5,94)
D11: KSO: | I11: CC-CZ:
D12: Místo: | I12: Datum: | J12: ='Rekapitulace stavby'!AN8 -> 20. 1. 2026
D14: Zadavatel: | I14: IČ: | J14: 65993390
E15: Ředitelství silnic a dálnic s.p. | I15: DIČ: | J15: CZ65993390
D17: Zhotovitel: | I17: IČ: | J17: ='Rekapitulace stavby'!AN13
E18: ='Rekapitulace stavby'!E14 | I18: DIČ: | J18: ='Rekapitulace stavby'!AN14
D20: Projektant: | I20: IČ: | J20: 29159342
E21: Woring s.r.o. | I21: DIČ: | J21: CZ29159342
D23: Zpracovatel: | I23: IČ: | J23: =IF('Rekapitulace stavby'!AN19="","",'Rekapitulace stavby'!AN19)
E24: =IF('Rekapitulace stavby'!E20="","",'Rekapitulace stavby'!E20) -> Pavel Vachtl | I24: DIČ: | J24: =IF('Rekapitulace stavby'!AN20="","",'Rekapitulace stavby'!AN20)
D26: Poznámka:
D30: Cena bez DPH | J30: =ROUND(J124, 2) -> 0
F32: Základ daně | I32: Sazba daně | J32: Výše daně
D33: DPH | E33: základní | F33: =ROUND((SUM(BE124:BE624)), 2) -> 0 | I33: 0.21 | J33: =ROUND(((SUM(BE124:BE624))*I33), 2) -> 0
E34: snížená | F34: =ROUND((SUM(BF124:BF624)), 2) -> 0 | I34: 0.15 | J34: =ROUND(((SUM(BF124:BF624))*I34), 2) -> 0
E35: zákl. přenesená | F35: =ROUND((SUM(BG124:BG624)), 2) -> 0 | I35: 0.21 | J35: =0 -> 0
E36: sníž. přenesená | F36: =ROUND((SUM(BH124:BH624)), 2) -> 0 | I36: 0.15 | J36: =0 -> 0
E37: nulová | F37: =ROUND((SUM(BI124:BI624)), 2) -> 0 | I37: 0 | J37: =0 -> 0
D39: Cena s DPH | G39: v | H39: CZK | J39: =SUM(J30:J37) -> 0
D50: Projektant | G50: Zpracovatel
D61: Datum a podpis: | F61: Razítko | G61: Datum a podpis: | J61: Razítko
D65: Objednavatel | G65: Zhotovitel
D76: Datum a podpis: | F76: Razítko | G76: Datum a podpis: | J76: Razítko
C82: REKAPITULACE ČLENĚNÍ SOUPISU PRACÍ
C84: Stavba:
E85: =E7 -> I/26 Kyšice - Plzeň, Hřbitovní
C86: Objekt:
E87: =E9 -> 102 - Oprava vozovky (km 4,84-5,94)
C89: Místo: | F89: =F12 | I89: Datum: | J89: =IF(J12="","",J12) -> 20. 1. 2026
C91: Zadavatel: | F91: =E15 -> Ředitelství silnic a dálnic s.p. | I91: Projektant: | J91: =E21 -> Woring s.r.o.
C92: Zhotovitel: | F92: =IF(E18="","",E18) | I92: Zpracovatel: | J92: =E24 -> Pavel Vachtl
C94: Kód dílu - Popis | J94: Cena celkem [CZK]
C96: Náklady ze soupisu prací | J96: =J124 -> 0 | AU96: -1
...

Sheet 181 - Přechodné dopravní ...
L2: >> skryté sloupce << | AT2: {2726717c-df5d-4807-80e7-684f156e0da1} | AZ2: A175 | BA2: A175 | BC2: 0 | BD2: 2
AT3: -1 | AZ3: A177 | BA3: A177 | BC3: 12 | BD3: 2
D4: KRYCÍ LIST SOUPISU PRACÍ | M4: v --- níže se nacházejí doplnkové a pomocné údaje k sestavám --- v | AT4: False | AZ4: B19 | BA4: B19 | BC4: 15 | BD4: 2
D6: Stavba:
E7: ='Rekapitulace stavby'!K6 -> I/26 Kyšice - Plzeň, Hřbitovní
D8: Objekt:
E9: 181 - Přechodné dopravní značení
D11: KSO: | I11: CC-CZ:
D12: Místo: | I12: Datum: | J12: ='Rekapitulace stavby'!AN8 -> 20. 1. 2026
D14: Zadavatel: | I14: IČ: | J14: 65993390
E15: Ředitelství silnic a dálnic s.p. | I15: DIČ: | J15: CZ65993390
D17: Zhotovitel: | I17: IČ: | J17: ='Rekapitulace stavby'!AN13
E18: ='Rekapitulace stavby'!E14 | I18: DIČ: | J18: ='Rekapitulace stavby'!AN14
D20: Projektant: | I20: IČ: | J20: 29159342
E21: Woring s.r.o. | I21: DIČ: | J21: CZ29159342
D23: Zpracovatel: | I23: IČ: | J23: =IF('Rekapitulace stavby'!AN19="","",'Rekapitulace stavby'!AN19)
E24: =IF('Rekapitulace stavby'!E20="","",'Rekapitulace stavby'!E20) -> Pavel Vachtl | I24: DIČ: | J24: =IF('Rekapitulace stavby'!AN20="","",'Rekapitulace stavby'!AN20)
D26: Poznámka:
D30: Cena bez DPH | J30: =ROUND(J119, 2) -> 0
F32: Základ daně | I32: Sazba daně | J32: Výše daně
D33: DPH | E33: základní | F33: =ROUND((SUM(BE119:BE204)), 2) -> 0 | I33: 0.21 | J33: =ROUND(((SUM(BE119:BE204))*I33), 2) -> 0
E34: snížená | F34: =ROUND((SUM(BF119:BF204)), 2) -> 0 | I34: 0.15 | J34: =ROUND(((SUM(BF119:BF204))*I34), 2) -> 0
E35: zákl. přenesená | F35: =ROUND((SUM(BG119:BG204)), 2) -> 0 | I35: 0.21 | J35: =0 -> 0
E36: sníž. přenesená | F36: =ROUND((SUM(BH119:BH204)), 2) -> 0 | I36: 0.15 | J36: =0 -> 0
E37: nulová | F37: =ROUND((SUM(BI119:BI204)), 2) -> 0 | I37: 0 | J37: =0 -> 0
D39: Cena s DPH | G39: v | H39: CZK | J39: =SUM(J30:J37) -> 0
D50: Projektant | G50: Zpracovatel
D61: Datum a podpis: | F61: Razítko | G61: Datum a podpis: | J61: Razítko
D65: Objednavatel | G65: Zhotovitel
D76: Datum a podpis: | F76: Razítko | G76: Datum a podpis: | J76: Razítko
C82: REKAPITULACE ČLENĚNÍ SOUPISU PRACÍ
C84: Stavba:
E85: =E7 -> I/26 Kyšice - Plzeň, Hřbitovní
C86: Objekt:
E87: =E9 -> 181 - Přechodné dopravní značení
C89: Místo: | F89: =F12 | I89: Datum: | J89: =IF(J12="","",J12) -> 20. 1. 2026
C91: Zadavatel: | F91: =E15 -> Ředitelství silnic a dálnic s.p. | I91: Projektant: | J91: =E21 -> Woring s.r.o.
C92: Zhotovitel: | F92: =IF(E18="","",E18) | I92: Zpracovatel: | J92: =E24 -> Pavel Vachtl
C94: Kód dílu - Popis | J94: Cena celkem [CZK]
C96: Náklady ze soupisu prací | J96: =J119 -> 0 | AU96: -1
...

Sheet 191 - Dopravní značení
L2: >> skryté sloupce << | AT2: {1396f380-28f3-4aa4-918d-c18ca3b9bba9}
AT3: -1
D4: KRYCÍ LIST SOUPISU PRACÍ | M4: v --- níže se nacházejí doplnkové a pomocné údaje k sestavám --- v | AT4: False
D6: Stavba:
E7: ='Rekapitulace stavby'!K6 -> I/26 Kyšice - Plzeň, Hřbitovní
D8: Objekt:
E9: 191 - Dopravní značení
D11: KSO: | I11: CC-CZ:
D12: Místo: | I12: Datum: | J12: ='Rekapitulace stavby'!AN8 -> 20. 1. 2026
D14: Zadavatel: | I14: IČ: | J14: 65993390
E15: Ředitelství silnic a dálnic s.p. | I15: DIČ: | J15: CZ65993390
D17: Zhotovitel: | I17: IČ: | J17: ='Rekapitulace stavby'!AN13
E18: ='Rekapitulace stavby'!E14 | I18: DIČ: | J18: ='Rekapitulace stavby'!AN14
D20: Projektant: | I20: IČ: | J20: 29159342
E21: Woring s.r.o. | I21: DIČ: | J21: CZ29159342
D23: Zpracovatel: | I23: IČ: | J23: =IF('Rekapitulace stavby'!AN19="","",'Rekapitulace stavby'!AN19)
E24: =IF('Rekapitulace stavby'!E20="","",'Rekapitulace stavby'!E20) -> Pavel Vachtl | I24: DIČ: | J24: =IF('Rekapitulace stavby'!AN20="","",'Rekapitulace stavby'!AN20)
D26: Poznámka:
D30: Cena bez DPH | J30: =ROUND(J119, 2) -> 0
F32: Základ daně | I32: Sazba daně | J32: Výše daně
D33: DPH | E33: základní | F33: =ROUND((SUM(BE119:BE185)), 2) -> 0 | I33: 0.21 | J33: =ROUND(((SUM(BE119:BE185))*I33), 2) -> 0
E34: snížená | F34: =ROUND((SUM(BF119:BF185)), 2) -> 0 | I34: 0.15 | J34: =ROUND(((SUM(BF119:BF185))*I34), 2) -> 0
E35: zákl. přenesená | F35: =ROUND((SUM(BG119:BG185)), 2) -> 0 | I35: 0.21 | J35: =0 -> 0
E36: sníž. přenesená | F36: =ROUND((SUM(BH119:BH185)), 2) -> 0 | I36: 0.15 | J36: =0 -> 0
E37: nulová | F37: =ROUND((SUM(BI119:BI185)), 2) -> 0 | I37: 0 | J37: =0 -> 0
D39: Cena s DPH | G39: v | H39: CZK | J39: =SUM(J30:J37) -> 0
D50: Projektant | G50: Zpracovatel
D61: Datum a podpis: | F61: Razítko | G61: Datum a podpis: | J61: Razítko
D65: Objednavatel | G65: Zhotovitel
D76: Datum a podpis: | F76: Razítko | G76: Datum a podpis: | J76: Razítko
C82: REKAPITULACE ČLENĚNÍ SOUPISU PRACÍ
C84: Stavba:
E85: =E7 -> I/26 Kyšice - Plzeň, Hřbitovní
C86: Objekt:
E87: =E9 -> 191 - Dopravní značení
C89: Místo: | F89: =F12 | I89: Datum: | J89: =IF(J12="","",J12) -> 20. 1. 2026
C91: Zadavatel: | F91: =E15 -> Ředitelství silnic a dálnic s.p. | I91: Projektant: | J91: =E21 -> Woring s.r.o.
C92: Zhotovitel: | F92: =IF(E18="","",E18) | I92: Zpracovatel: | J92: =E24 -> Pavel Vachtl
C94: Kód dílu - Popis | J94: Cena celkem [CZK]
C96: Náklady ze soupisu prací | J96: =J119 -> 0 | AU96: -1
...

Sheet 201-003 - Most ev.č. 206-003
C4: SOUPIS PRACÍ
C6: Stavba:
E7: =#REF! -> #REF!
C8: Objekt:
E9: =#REF! -> #REF!
C11: Místo: | F11: =#REF! -> #REF! | I11: Datum: | J11: =IF(#REF!="","",#REF!) -> #REF!
C13: Zadavatel: | F13: =#REF! -> #REF! | I13: Projektant: | J13: =#REF! -> #REF!
C14: Zhotovitel: | F14: =IF(#REF!="","",#REF!) -> #REF! | I14: Zpracovatel: | J14: =#REF! -> #REF!
C16: PČ | D16: Typ | E16: Kód | F16: Popis | G16: MJ | H16: Množství | I16: J.cena [CZK] | J16: Cena celkem [CZK] | K16: Cenová soustava | N16: DPH | O16: J. Nh [h] | P16: Nh celkem [h] | Q16: J. hmotnost [t] | R16: Hmotnost celkem [t] | S16: J. suť [t] | T16: Suť Celkem [t]
C17: Náklady soupisu celkem | J17: =BK17 -> #REF! | P17: =P18+P53+P54+P69+P93+P125+P126+P145+P176+P183 -> #REF! | R17: =R18+R53+R54+R69+R93+R125+R126+R145+R176+R183 -> #REF! | T17: =T18+T53+T54+T69+T93+T125+T126+T145+T176+T183 -> #REF! | AT17: D | AU17: -1 | BK17: =BK18+BK53+BK54+BK69+BK93+BK125+BK126+BK145+BK176+BK183 -> #REF!
D18: D | E18: 0 | F18: Všeobecné konstrukce a práce | J18: =BK18 -> 0 | P18: =SUM(P19:P52) -> 0 | R18: =SUM(R19:R52) -> 0 | T18: =SUM(T19:T52) -> 0 | AR18: 4 | AT18: D | AU18: 0 | AY18: ROZPOCET | BK18: =SUM(BK19:BK52) -> 0
C19: 1 | D19: K | E19: 014121 | F19: POPLATKY ZA SKLÁDKU TYP S-OO (OSTATNÍ ODPAD) | G19: M3 | H19: 1243.036 | I19: 0 | J19: =ROUND(I19*H19,2) -> 0 | K19: OTSKP 2025 | N19: základní | O19: 0 | P19: =O19*H19 -> 0 | Q19: 0 | R19: =Q19*H19 -> 0 | S19: 0 | T19: =S19*H19 -> 0 | AR19: 4 | AT19: K | AU19: 1 | AY19: ROZPOCET | BE19: =IF(N19="základní",J19,0) -> 0 | BF19: =IF(N19="snížená",J19,0) -> 0 | BG19: =IF(N19="zákl. přenesená",J19,0) -> 0 | BH19: =IF(N19="sníž. přenesená",J19,0) -> 0 | BI19: =IF(N19="nulová",J19,0) -> 0 | BJ19: 1 | BK19: =ROUND(I19*H19,2) -> 0 | BL19: 4 | BM19: 1150791547
D20: PP | F20: POPLATKY ZA SKLÁDKU TYP S-OO (OSTATNÍ ODPAD) | AT20: PP | AU20: 1
D21: PSC | F21: Poznámka k souboru cen:_x000D_ zahrnuje veškeré poplatky provozovateli skládky související s uložením odpadu na skládce. | AT21: PSC | AU21: 1
D22: VV | E22: A195 | F22: 46,000000 "(966168) | H22: 46 | AT22: VV | AU22: 1 | AV22: 2 | AW22: True | AX22: 0 | AY22: ROZPOCET
D23: VV | E23: B5 | F23: 26,000000 "(966118) | H23: 26 | AT23: VV | AU23: 1 | AV23: 2 | AW23: True | AX23: 0 | AY23: ROZPOCET
D24: VV | E24: C5 | F24: 1161,400000 "(131738) | H24: 1161.4 | AT24: VV | AU24: 1 | AV24: 2 | AW24: True | AX24: 0 | AY24: ROZPOCET
D25: VV | E25: D4 | F25: 114,400000 "(626113)"*0,03 | H25: 3.432 | AT25: VV | AU25: 1 | AV25: 2 | AW25: True | AX25: 0 | AY25: ROZPOCET
D26: VV | E26: E3 | F26: 28,600000 "(626123)"*0,06 | H26: 1.716 | AT26: VV | AU26: 1 | AV26: 2 | AW26: True | AX26: 0 | AY26: ROZPOCET
D27: VV | E27: F3 | F27: 149,600000 "(626213)"*0,03 | H27: 4.488 | AT27: VV | AU27: 1 | AV27: 2 | AW27: True | AX27: 0 | AY27: ROZPOCET
D28: VV | F28: "Celkové množství "1243.036000 | H28: 1243.036 | AT28: VV | AU28: 1 | AV28: 2 | AW28: True | AX28: 1 | AY28: ROZPOCET
C29: 2 | D29: K | E29: 014132 | F29: POPLATKY ZA SKLÁDKU TYP S-NO (NEBEZPEČNÝ ODPAD) | G29: T | H29: 90.831 | I29: 0 | J29: =ROUND(I29*H29,2) -> 0 | K29: OTSKP 2025 | N29: základní | O29: 0 | P29: =O29*H29 -> 0 | Q29: 0 | R29: =Q29*H29 -> 0 | S29: 0 | T29: =S29*H29 -> 0 | AR29: 4 | AT29: K | AU29: 1 | AY29: ROZPOCET | BE29: =IF(N29="základní",J29,0) -> 0 | BF29: =IF(N29="snížená",J29,0) -> 0 | BG29: =IF(N29="zákl. přenesená",J29,0) -> 0 | BH29: =IF(N29="sníž. přenesená",J29,0) -> 0 | BI29: =IF(N29="nulová",J29,0) -> 0 | BJ29: 1 | BK29: =ROUND(I29*H29,2) -> 0 | BL29: 4 | BM29: -702011773
D30: PP | F30: POPLATKY ZA SKLÁDKU TYP S-NO (NEBEZPEČNÝ ODPAD) | AT30: PP | AU30: 1
D31: PSC | F31: Poznámka k souboru cen:_x000D_ zahrnuje veškeré poplatky provozovateli skládky související s uložením odpadu na skládce. | AT31: PSC | AU31: 1
D32: VV | E32: A196 | F32: "izolace "99,000000 "(97817)"*0,007 | H32: 0.693 | AT32: VV | AU32: 1 | AV32: 2 | AW32: True | AX32: 0 | AY32: ROZPOCET
D33: VV | E33: B38 | F33: "frézovaná ZAS-T3 "45,069000 "(113728)"*2,0 | H33: 90.138 | AT33: VV | AU33: 1 | AV33: 2 | AW33: True | AX33: 0 | AY33: ROZPOCET
D34: VV | F34: "Celkové množství "90.831000 | H34: 90.831 | AT34: VV | AU34: 1 | AV34: 2 | AW34: True | AX34: 1 | AY34: ROZPOCET
C35: 3 | D35: K | E35: 02851 | F35: PRŮZKUMNÉ PRÁCE DIAGNOSTIKY KONSTRUKCÍ NA POVRCHU | G35: KPL | H35: 1 | I35: 0 | J35: =ROUND(I35*H35,2) -> 0 | K35: OTSKP 2025 | N35: základní | O35: 0 | P35: =O35*H35 -> 0 | Q35: 0 | R35: =Q35*H35 -> 0 | S35: 0 | T35: =S35*H35 -> 0 | AR35: 4 | AT35: K | AU35: 1 | AY35: ROZPOCET | BE35: =IF(N35="základní",J35,0) -> 0 | BF35: =IF(N35="snížená",J35,0) -> 0 | BG35: =IF(N35="zákl. přenesená",J35,0) -> 0 | BH35: =IF(N35="sníž. přenesená",J35,0) -> 0 | BI35: =IF(N35="nulová",J35,0) -> 0 | BJ35: 1 | BK35: =ROUND(I35*H35,2) -> 0 | BL35: 4 | BM35: 1097067810
D36: PP | F36: Odtrhové zkoušky, karbonatace, chloridy | AT36: PP | AU36: 1
D37: PSC | F37: Poznámka k souboru cen:_x000D_ zahrnuje veškeré náklady spojené s objednatelem požadovanými pracemi | AT37: PSC | AU37: 1
C38: 4 | D38: K | E38: 029113 | F38: OSTATNÍ POŽADAVKY - GEODETICKÉ ZAMĚŘENÍ - CELKY | G38: KUS | H38: 3 | I38: 0 | J38: =ROUND(I38*H38,2) -> 0 | K38: OTSKP 2025 | N38: základní | O38: 0 | P38: =O38*H38 -> 0 | Q38: 0 | R38: =Q38*H38 -> 0 | S38: 0 | T38: =S38*H38 -> 0 | AR38: 4 | AT38: K | AU38: 1 | AY38: ROZPOCET | BE38: =IF(N38="základní",J38,0) -> 0 | BF38: =IF(N38="snížená",J38,0) -> 0 | BG38: =IF(N38="zákl. přenesená",J38,0) -> 0 | BH38: =IF(N38="sníž. přenesená",J38,0) -> 0 | BI38: =IF(N38="nulová",J38,0) -> 0 | BJ38: 1 | BK38: =ROUND(I38*H38,2) -> 0 | BL38: 4 | BM38: -1333448232
D39: PP | F39: zamereni stavu pred stavbou; prubezne zamerovani a vytycovani behem vystavby; zamereni stavu po dokonceni | AT39: PP | AU39: 1
D40: PSC | F40: Poznámka k souboru cen:_x000D_ zahrnuje veškeré náklady spojené s objednatelem požadovanými pracemi | AT40: PSC | AU40: 1
C41: 5 | D41: K | E41: 02912 | F41: OSTATNÍ POŽADAVKY - VYTYČOVACÍ BOD MIKROSÍTĚ | G41: KUS | H41: 4 | I41: 0 | J41: =ROUND(I41*H41,2) -> 0 | K41: OTSKP 2025 | N41: základní | O41: 0 | P41: =O41*H41 -> 0 | Q41: 0 | R41: =Q41*H41 -> 0 | S41: 0 | T41: =S41*H41 -> 0 | AR41: 4 | AT41: K | AU41: 1 | AY41: ROZPOCET | BE41: =IF(N41="základní",J41,0) -> 0 | BF41: =IF(N41="snížená",J41,0) -> 0 | BG41: =IF(N41="zákl. přenesená",J41,0) -> 0 | BH41: =IF(N41="sníž. přenesená",J41,0) -> 0 | BI41: =IF(N41="nulová",J41,0) -> 0 | BJ41: 1 | BK41: =ROUND(I41*H41,2) -> 0 | BL41: 4 | BM41: 414409725
D42: PP | F42: OSTATNÍ POŽADAVKY - VYTYČOVACÍ BOD MIKROSÍTĚ | AT42: PP | AU42: 1
D43: PSC | F43: Poznámka k souboru cen:_x000D_ zahrnuje vrt D 300-500mm, ocelovou zárubnici DN 180-300 mm, ochrannou plastovou trubku DN 220-350 mm, plastový uzávěr, čepovou nivelační značku z nerez oceli, kotvu se šroubem z nerez oceli, ochranný tyčový znak s tabulkou, betonovou skruž DN 1500mm výšky 0,5m, beton C30/37-XF4, izolační pěnu, zaměření bodu včetně vyrovnání (velmi přesná nivelace) - dle projektu základní vytyčovací sítě, kde je hloubka určena geologem na základě dostupných průzkumů či dat | AT43: PSC | AU43: 1
C44: 6 | D44: K | E44: 029412 | F44: OSTATNÍ POŽADAVKY - VYPRACOVÁNÍ MOSTNÍHO LISTU | G44: KUS | H44: 1 | I44: 0 | J44: =ROUND(I44*H44,2) -> 0 | K44: OTSKP 2025 | N44: základní | O44: 0 | P44: =O44*H44 -> 0 | Q44: 0 | R44: =Q44*H44 -> 0 | S44: 0 | T44: =S44*H44 -> 0 | AR44: 4 | AT44: K | AU44: 1 | AY44: ROZPOCET | BE44: =IF(N44="základní",J44,0) -> 0 | BF44: =IF(N44="snížená",J44,0) -> 0 | BG44: =IF(N44="zákl. přenesená",J44,0) -> 0 | BH44: =IF(N44="sníž. přenesená",J44,0) -> 0 | BI44: =IF(N44="nulová",J44,0) -> 0 | BJ44: 1 | BK44: =ROUND(I44*H44,2) -> 0 | BL44: 4 | BM44: 1029464919
D45: PP | F45: Mostní list; Včetně stanovení zatížitelnosti výpočtem | AT45: PP | AU45: 1
D46: PSC | F46: Poznámka k souboru cen:_x000D_ zahrnuje veškeré náklady spojené s objednatelem požadovanými pracemi | AT46: PSC | AU46: 1
C47: 7 | D47: K | E47: 02944 | F47: OSTAT POŽADAVKY - DOKUMENTACE SKUTEČ PROVEDENÍ V DIGIT FORMĚ | G47: KPL | H47: 1 | I47: 0 | J47: =ROUND(I47*H47,2) -> 0 | K47: OTSKP 2025 | N47: základní | O47: 0 | P47: =O47*H47 -> 0 | Q47: 0 | R47: =Q47*H47 -> 0 | S47: 0 | T47: =S47*H47 -> 0 | AR47: 4 | AT47: K | AU47: 1 | AY47: ROZPOCET | BE47: =IF(N47="základní",J47,0) -> 0 | BF47: =IF(N47="snížená",J47,0) -> 0 | BG47: =IF(N47="zákl. přenesená",J47,0) -> 0 | BH47: =IF(N47="sníž. přenesená",J47,0) -> 0 | BI47: =IF(N47="nulová",J47,0) -> 0 | BJ47: 1 | BK47: =ROUND(I47*H47,2) -> 0 | BL47: 4 | BM47: -785140313
...

Sheet 201-004 - Mosty ev. č. 26...
C4: SOUPIS PRACÍ
C6: Stavba:
E7: =#REF! -> #REF!
C8: Objekt:
E9: =#REF! -> #REF!
C11: Místo: | F11: =#REF! -> #REF! | I11: Datum: | J11: =IF(#REF!="","",#REF!) -> #REF!
C13: Zadavatel: | F13: =#REF! -> #REF! | I13: Projektant: | J13: =#REF! -> #REF!
C14: Zhotovitel: | F14: =IF(#REF!="","",#REF!) -> #REF! | I14: Zpracovatel: | J14: =#REF! -> #REF!
C16: PČ | D16: Typ | E16: Kód | F16: Popis | G16: MJ | H16: Množství | I16: J.cena [CZK] | J16: Cena celkem [CZK] | K16: Cenová soustava | N16: DPH | O16: J. Nh [h] | P16: Nh celkem [h] | Q16: J. hmotnost [t] | R16: Hmotnost celkem [t] | S16: J. suť [t] | T16: Suť Celkem [t]
C17: Náklady soupisu celkem | J17: =BK17 -> #REF! | P17: =P18+P60+P61+P106+P149+P193+P194+P218+P286+P287 -> #REF! | R17: =R18+R60+R61+R106+R149+R193+R194+R218+R286+R287 -> #REF! | T17: =T18+T60+T61+T106+T149+T193+T194+T218+T286+T287 -> #REF! | AT17: D | AU17: -1 | BK17: =BK18+BK60+BK61+BK106+BK149+BK193+BK194+BK218+BK286+BK287 -> #REF!
D18: D | E18: 0 | F18: Všeobecné konstrukce a práce | J18: =BK18 -> 0 | P18: =SUM(P19:P59) -> 0 | R18: =SUM(R19:R59) -> 0 | T18: =SUM(T19:T59) -> 0 | AR18: 4 | AT18: D | AU18: 0 | AY18: ROZPOCET | BK18: =SUM(BK19:BK59) -> 0
C19: 1 | D19: K | E19: 014101 | F19: POPLATKY ZA SKLÁDKU | G19: M3 | H19: 529.2 | I19: 0 | J19: =ROUND(I19*H19,2) -> 0 | K19: OTSKP 2025 | N19: základní | O19: 0 | P19: =O19*H19 -> 0 | Q19: 0 | R19: =Q19*H19 -> 0 | S19: 0 | T19: =S19*H19 -> 0 | AR19: 4 | AT19: K | AU19: 1 | AY19: ROZPOCET | BE19: =IF(N19="základní",J19,0) -> 0 | BF19: =IF(N19="snížená",J19,0) -> 0 | BG19: =IF(N19="zákl. přenesená",J19,0) -> 0 | BH19: =IF(N19="sníž. přenesená",J19,0) -> 0 | BI19: =IF(N19="nulová",J19,0) -> 0 | BJ19: 1 | BK19: =ROUND(I19*H19,2) -> 0 | BL19: 4 | BM19: 1511577371
D20: PP | F20: materiál z výkopu | AT20: PP | AU20: 1
D21: PSC | F21: Poznámka k souboru cen:_x000D_ Položka zahrnuje: - veškeré poplatky provozovateli skládky související s uložením odpadu na skládce. Položka nezahrnuje: - x | AT21: PSC | AU21: 1
D22: VV | E22: A264 | F22: "objem z pol. 13173 "529,2 | H22: 529.2 | AT22: VV | AU22: 1 | AV22: 2 | AW22: True | AX22: 0 | AY22: ROZPOCET
D23: VV | F23: "Celkové množství "529.200000 | H23: 529.2 | AT23: VV | AU23: 1 | AV23: 2 | AW23: True | AX23: 1 | AY23: ROZPOCET
C24: 2 | D24: K | E24: 014101.1 | F24: POPLATKY ZA SKLÁDKU | G24: M3 | H24: 163.141 | I24: 0 | J24: =ROUND(I24*H24,2) -> 0 | K24: OTSKP 2025 | N24: základní | O24: 0 | P24: =O24*H24 -> 0 | Q24: 0 | R24: =Q24*H24 -> 0 | S24: 0 | T24: =S24*H24 -> 0 | AR24: 4 | AT24: K | AU24: 1 | AY24: ROZPOCET | BE24: =IF(N24="základní",J24,0) -> 0 | BF24: =IF(N24="snížená",J24,0) -> 0 | BG24: =IF(N24="zákl. přenesená",J24,0) -> 0 | BH24: =IF(N24="sníž. přenesená",J24,0) -> 0 | BI24: =IF(N24="nulová",J24,0) -> 0 | BJ24: 1 | BK24: =ROUND(I24*H24,2) -> 0 | BL24: 4 | BM24: -423129561
D25: PP | F25: prostý beton, železobeton, železobetonové dílce | AT25: PP | AU25: 1
D26: PSC | F26: Poznámka k souboru cen:_x000D_ Položka zahrnuje: - veškeré poplatky provozovateli skládky související s uložením odpadu na skládce. Položka nezahrnuje: - x | AT26: PSC | AU26: 1
D27: VV | E27: A265 | F27: "objem z pol. 96611 "6,064 | H27: 6.064 | AT27: VV | AU27: 1 | AV27: 2 | AW27: True | AX27: 0 | AY27: ROZPOCET
D28: VV | E28: B90 | F28: "objem z pol. 96615 "21,56 | H28: 21.56 | AT28: VV | AU28: 1 | AV28: 2 | AW28: True | AX28: 0 | AY28: ROZPOCET
D29: VV | E29: C49 | F29: "objem z pol. 96616 "126,349 | H29: 126.349 | AT29: VV | AU29: 1 | AV29: 2 | AW29: True | AX29: 0 | AY29: ROZPOCET
D30: VV | E30: D5 | F30: "délka z pol. 11352 * plocha 0,1 m2 "66,0*0,1 | H30: 6.6 | AT30: VV | AU30: 1 | AV30: 2 | AW30: True | AX30: 0 | AY30: ROZPOCET
D31: VV | E31: E4 | F31: "plocha z pol. 11328 * tl. 0,2 m "3,6*0,2 | H31: 0.72 | AT31: VV | AU31: 1 | AV31: 2 | AW31: True | AX31: 0 | AY31: ROZPOCET
D32: VV | E32: F4 | F32: "objem z jádrových odvrtů pro trny fixace A265 drenaž "(3,14*0,085*0,085*0,5)*40+(3,14*0,1*0,1*1,0)*40+(3,14*0,1*0,1*1,1)*4 | H32: 1.84789 | AT32: VV | AU32: 1 | AV32: 2 | AW32: True | AX32: 0 | AY32: ROZPOCET
D33: VV | F33: "Celkové množství "163.141000 | H33: 163.141 | AT33: VV | AU33: 1 | AV33: 2 | AW33: True | AX33: 1 | AY33: ROZPOCET
C34: 3 | D34: K | E34: 014102 | F34: POPLATKY ZA SKLÁDKU | G34: T | H34: 4.182 | I34: 0 | J34: =ROUND(I34*H34,2) -> 0 | K34: OTSKP 2025 | N34: základní | O34: 0 | P34: =O34*H34 -> 0 | Q34: 0 | R34: =Q34*H34 -> 0 | S34: 0 | T34: =S34*H34 -> 0 | AR34: 4 | AT34: K | AU34: 1 | AY34: ROZPOCET | BE34: =IF(N34="základní",J34,0) -> 0 | BF34: =IF(N34="snížená",J34,0) -> 0 | BG34: =IF(N34="zákl. přenesená",J34,0) -> 0 | BH34: =IF(N34="sníž. přenesená",J34,0) -> 0 | BI34: =IF(N34="nulová",J34,0) -> 0 | BJ34: 1 | BK34: =ROUND(I34*H34,2) -> 0 | BL34: 4 | BM34: 1751187917
D35: PP | F35: asfaltové izolační pásy, izolační materiály | AT35: PP | AU35: 1
D36: PSC | F36: Poznámka k souboru cen:_x000D_ Položka zahrnuje: - veškeré poplatky provozovateli skládky související s uložením odpadu na skládce. Položka nezahrnuje: - x | AT36: PSC | AU36: 1
D37: VV | E37: A266 | F37: "plocha z pol. 97817 * 5 kg/m2 "836,34*0,005 | H37: 4.1817 | AT37: VV | AU37: 1 | AV37: 2 | AW37: True | AX37: 1 | AY37: ROZPOCET
C38: 4 | D38: K | E38: 029113 | F38: OSTATNÍ POŽADAVKY - ZEMĚMĚŘICKÉ ZAMĚŘENÍ - CELKY | G38: KUS | H38: 6 | I38: 0 | J38: =ROUND(I38*H38,2) -> 0 | K38: OTSKP 2025 | N38: základní | O38: 0 | P38: =O38*H38 -> 0 | Q38: 0 | R38: =Q38*H38 -> 0 | S38: 0 | T38: =S38*H38 -> 0 | AR38: 4 | AT38: K | AU38: 1 | AY38: ROZPOCET | BE38: =IF(N38="základní",J38,0) -> 0 | BF38: =IF(N38="snížená",J38,0) -> 0 | BG38: =IF(N38="zákl. přenesená",J38,0) -> 0 | BH38: =IF(N38="sníž. přenesená",J38,0) -> 0 | BI38: =IF(N38="nulová",J38,0) -> 0 | BJ38: 1 | BK38: =ROUND(I38*H38,2) -> 0 | BL38: 4 | BM38: 948596069
D39: PP | F39: zamereni stavu pred stavbou; prubezne zamerovani a vytycovani behem vystavby; zamereni stavu po dokonceni; | AT39: PP | AU39: 1
D40: PSC | F40: Poznámka k souboru cen:_x000D_ Položka zahrnuje: - veškeré náklady spojené s objednatelem požadovanými pracemi - položka se využije pro celky 3D charakteru (objekty s vysokou mírou nepravidelnosti vzájemně navazujících částí, technologické a průmyslové celky) Položka nezahrnuje: - x | AT40: PSC | AU40: 1
C41: 5 | D41: K | E41: 029412 | F41: OSTATNÍ POŽADAVKY - VYPRACOVÁNÍ MOSTNÍHO LISTU | G41: KUS | H41: 2 | I41: 0 | J41: =ROUND(I41*H41,2) -> 0 | K41: OTSKP 2025 | N41: základní | O41: 0 | P41: =O41*H41 -> 0 | Q41: 0 | R41: =Q41*H41 -> 0 | S41: 0 | T41: =S41*H41 -> 0 | AR41: 4 | AT41: K | AU41: 1 | AY41: ROZPOCET | BE41: =IF(N41="základní",J41,0) -> 0 | BF41: =IF(N41="snížená",J41,0) -> 0 | BG41: =IF(N41="zákl. přenesená",J41,0) -> 0 | BH41: =IF(N41="sníž. přenesená",J41,0) -> 0 | BI41: =IF(N41="nulová",J41,0) -> 0 | BJ41: 1 | BK41: =ROUND(I41*H41,2) -> 0 | BL41: 4 | BM41: 998521399
D42: PP | F42: v počtu tisků dle SOD | AT42: PP | AU42: 1
D43: PSC | F43: Poznámka k souboru cen:_x000D_ Položka zahrnuje: - veškeré náklady spojené s objednatelem požadovanými pracemi Položka nezahrnuje: - x | AT43: PSC | AU43: 1
D44: VV | E44: A267 | F44: "LM + PM "1+1 | H44: 2 | AT44: VV | AU44: 1 | AV44: 2 | AW44: True | AX44: 0 | AY44: ROZPOCET
D45: VV | F45: "Celkové množství "2.000000 | H45: 2 | AT45: VV | AU45: 1 | AV45: 2 | AW45: True | AX45: 1 | AY45: ROZPOCET
C46: 6 | D46: K | E46: 02944 | F46: OSTAT POŽADAVKY - DOKUMENTACE SKUTEČ PROVEDENÍ V DIGIT FORMĚ | G46: KPL | H46: 1 | I46: 0 | J46: =ROUND(I46*H46,2) -> 0 | K46: OTSKP 2025 | N46: základní | O46: 0 | P46: =O46*H46 -> 0 | Q46: 0 | R46: =Q46*H46 -> 0 | S46: 0 | T46: =S46*H46 -> 0 | AR46: 4 | AT46: K | AU46: 1 | AY46: ROZPOCET | BE46: =IF(N46="základní",J46,0) -> 0 | BF46: =IF(N46="snížená",J46,0) -> 0 | BG46: =IF(N46="zákl. přenesená",J46,0) -> 0 | BH46: =IF(N46="sníž. přenesená",J46,0) -> 0 | BI46: =IF(N46="nulová",J46,0) -> 0 | BJ46: 1 | BK46: =ROUND(I46*H46,2) -> 0 | BL46: 4 | BM46: 861781995
D47: PP | F47: v počtu tisků dle SOD | AT47: PP | AU47: 1
...

Sheet 441 - Přeložka a ochrana ...
L2: >> skryté sloupce << | AT2: {714a2bd5-f1ca-44ad-8658-2384fadf25ce}
AT3: -1
D4: KRYCÍ LIST SOUPISU PRACÍ | M4: v --- níže se nacházejí doplnkové a pomocné údaje k sestavám --- v | AT4: False
D6: Stavba:
E7: ='Rekapitulace stavby'!K6 -> I/26 Kyšice - Plzeň, Hřbitovní
D8: Objekt:
E9: 441 - Přeložka a ochrana vedení VO
D11: KSO: | I11: CC-CZ:
D12: Místo: | I12: Datum: | J12: ='Rekapitulace stavby'!AN8 -> 20. 1. 2026
D14: Zadavatel: | I14: IČ: | J14: 65993390
E15: Ředitelství silnic a dálnic s.p. | I15: DIČ: | J15: CZ65993390
D17: Zhotovitel: | I17: IČ: | J17: ='Rekapitulace stavby'!AN13
E18: ='Rekapitulace stavby'!E14 | I18: DIČ: | J18: ='Rekapitulace stavby'!AN14
D20: Projektant: | I20: IČ: | J20: 29159342
E21: Woring s.r.o. | I21: DIČ: | J21: CZ29159342
D23: Zpracovatel: | I23: IČ: | J23: =IF('Rekapitulace stavby'!AN19="","",'Rekapitulace stavby'!AN19)
E24: =IF('Rekapitulace stavby'!E20="","",'Rekapitulace stavby'!E20) -> Pavel Vachtl | I24: DIČ: | J24: =IF('Rekapitulace stavby'!AN20="","",'Rekapitulace stavby'!AN20)
D26: Poznámka:
D30: Cena bez DPH | J30: =ROUND(J117, 2) -> 0
F32: Základ daně | I32: Sazba daně | J32: Výše daně
D33: DPH | E33: základní | F33: =ROUND((SUM(BE117:BE121)), 2) -> 0 | I33: 0.21 | J33: =ROUND(((SUM(BE117:BE121))*I33), 2) -> 0
E34: snížená | F34: =ROUND((SUM(BF117:BF121)), 2) -> 0 | I34: 0.15 | J34: =ROUND(((SUM(BF117:BF121))*I34), 2) -> 0
E35: zákl. přenesená | F35: =ROUND((SUM(BG117:BG121)), 2) -> 0 | I35: 0.21 | J35: =0 -> 0
E36: sníž. přenesená | F36: =ROUND((SUM(BH117:BH121)), 2) -> 0 | I36: 0.15 | J36: =0 -> 0
E37: nulová | F37: =ROUND((SUM(BI117:BI121)), 2) -> 0 | I37: 0 | J37: =0 -> 0
D39: Cena s DPH | G39: v | H39: CZK | J39: =SUM(J30:J37) -> 0
D50: Projektant | G50: Zpracovatel
D61: Datum a podpis: | F61: Razítko | G61: Datum a podpis: | J61: Razítko
D65: Objednavatel | G65: Zhotovitel
D76: Datum a podpis: | F76: Razítko | G76: Datum a podpis: | J76: Razítko
C82: REKAPITULACE ČLENĚNÍ SOUPISU PRACÍ
C84: Stavba:
E85: =E7 -> I/26 Kyšice - Plzeň, Hřbitovní
C86: Objekt:
E87: =E9 -> 441 - Přeložka a ochrana vedení VO
C89: Místo: | F89: =F12 | I89: Datum: | J89: =IF(J12="","",J12) -> 20. 1. 2026
C91: Zadavatel: | F91: =E15 -> Ředitelství silnic a dálnic s.p. | I91: Projektant: | J91: =E21 -> Woring s.r.o.
C92: Zhotovitel: | F92: =IF(E18="","",E18) | I92: Zpracovatel: | J92: =E24 -> Pavel Vachtl
C94: Kód dílu - Popis | J94: Cena celkem [CZK]
C96: Náklady ze soupisu prací | J96: =J117 -> 0 | AU96: -1
...
