Workbook
Name vorn_sum: VORN!$I$37

Sheet Stavební rozpočet
A1: Stavební rozpočet | AS1: =SUM(AJ1:AJ2) -> 0 | AT1: =SUM(AK1:AK2) -> 0 | AU1: =SUM(AL1:AL2) -> 0
A2: Název stavby: | D2: Areál společnosti FORESTINA s.r.o. – Horažďovice, Blatenská 587 | F2: Doba výstavby: | I2: Objednatel:
A4: Druh stavby: | D4: Zdravotně technické instalace | F4: Začátek výstavby: | I4: Projektant: | K4: Ing. Michal Albrecht
A6: Lokalita: | D6: !!!! Pracovní verze !!!! | F6: Konec výstavby: | I6: Zhotovitel:
A8: JKSO: | F8: Zpracováno dne: | H8: 11.06.2025 | I8: Zpracoval: | K8: Ing. Michal Albrecht
A10: Č | B10: Objekt | C10: Kód | D10: Zkrácený popis / Varianta | F10: MJ | G10: Množství | H10: Cena/MJ | I10: Sazba DPH | J10: Náklady (Kč) | M10: Náklady (Kč) | N10: Hmotnost (t) | P10: Cenová | BK10: ISWORK | BL10: GROUPCODE | BW10: VATTAX
D11: Rozměry | H11: (Kč) | J11: Dodávka | K11: Montáž | L11: Celkem | M11: Celkem vč. DPH | N11: Jednot. | O11: Celkem | P11: soustava | Z11: Přesuny | AA11: Typ skupiny | AB11: HSV mat | AC11: HSV prac | AD11: PSV mat | AE11: PSV prac | AF11: Mont mat | AG11: Mont prac | AH11: Ostatní mat. | BH11: MAT | BI11: WORK | BJ11: CELK
C12: 713 | D12: Izolace tepelné | J12: =SUM(J13:J19) -> 0 | K12: =SUM(K13:K19) -> 0 | L12: =SUM(L13:L19) -> 0 | M12: =SUM(M13:M19) -> 0 | O12: =SUM(O13:O19) -> 0.1191 | AS12: =SUM(AJ13:AJ19) -> 0 | AT12: =SUM(AK13:AK19) -> 0 | AU12: =SUM(AL13:AL19) -> 0
A13: 1 | C13: 230330091R00 | D13: Izolace potrubí D do 76 mm | F13: m | G13: 605 | J13: =ROUND(G13*AO13,2) -> 0 | K13: =ROUND(G13*AP13,2) -> 0 | L13: =ROUND(G13*H13,2) -> 0 | M13: =L13*(1+BW13/100) -> 0 | N13: 0 | O13: =G13*N13 -> 0 | P13: RTS I / 2022 | Z13: =ROUND(IF(AQ13="5",BJ13,0),2) -> 0 | AB13: =ROUND(IF(AQ13="1",BH13,0),2) -> 0 | AC13: =ROUND(IF(AQ13="1",BI13,0),2) -> 0 | AD13: =ROUND(IF(AQ13="7",BH13,0),2) -> 0 | AE13: =ROUND(IF(AQ13="7",BI13,0),2) -> 0 | AF13: =ROUND(IF(AQ13="2",BH13,0),2) -> 0 | AG13: =ROUND(IF(AQ13="2",BI13,0),2) -> 0 | AH13: =ROUND(IF(AQ13="0",BJ13,0),2) -> 0 | AJ13: =IF(AN13=0,L13,0) -> 0 | AK13: =IF(AN13=12,L13,0) -> 0 | AL13: =IF(AN13=21,L13,0) -> 0 | AN13: 12 | AO13: =H13*0 -> 0 | AP13: =H13*(1-0) -> 0 | AQ13: 2 | AV13: =ROUND(AW13+AX13,2) -> 0 | AW13: =ROUND(G13*AO13,2) -> 0 | AX13: =ROUND(G13*AP13,2) -> 0 | AY13: 713_ | AZ13: 71_ | BA13: _ | BC13: =AW13+AX13 -> 0 | BD13: =H13/(100-BE13)*100 -> 0 | BE13: 0 | BF13: =O13 -> 0 | BH13: =G13*AO13 -> 0 | BI13: =G13*AP13 -> 0 | BJ13: =G13*H13 -> 0 | BK13: P | BL13: 713 | BW13: =I13 -> 0 | BX13: Izolace potrubí D do 76 mm
A14: 2 | C14: 631547013 | D14: Pouzdro potrubní izolační ROCKWOOL 800 22/20 mm | F14: m | G14: 0 | J14: =ROUND(G14*AO14,2) -> 0 | K14: =ROUND(G14*AP14,2) -> 0 | L14: =ROUND(G14*H14,2) -> 0 | M14: =L14*(1+BW14/100) -> 0 | N14: 7e-05 | O14: =G14*N14 -> 0 | P14: RTS I / 2025 | Z14: =ROUND(IF(AQ14="5",BJ14,0),2) -> 0 | AB14: =ROUND(IF(AQ14="1",BH14,0),2) -> 0 | AC14: =ROUND(IF(AQ14="1",BI14,0),2) -> 0 | AD14: =ROUND(IF(AQ14="7",BH14,0),2) -> 0 | AE14: =ROUND(IF(AQ14="7",BI14,0),2) -> 0 | AF14: =ROUND(IF(AQ14="2",BH14,0),2) -> 0 | AG14: =ROUND(IF(AQ14="2",BI14,0),2) -> 0 | AH14: =ROUND(IF(AQ14="0",BJ14,0),2) -> 0 | AJ14: =IF(AN14=0,L14,0) -> 0 | AK14: =IF(AN14=12,L14,0) -> 0 | AL14: =IF(AN14=21,L14,0) -> 0 | AN14: 12 | AO14: =H14*1 -> 0 | AP14: =H14*(1-1) -> 0 | AQ14: 7 | AV14: =ROUND(AW14+AX14,2) -> 0 | AW14: =ROUND(G14*AO14,2) -> 0 | AX14: =ROUND(G14*AP14,2) -> 0 | AY14: 713_ | AZ14: 71_ | BA14: _ | BC14: =AW14+AX14 -> 0 | BD14: =H14/(100-BE14)*100 -> 0 | BE14: 0 | BF14: =O14 -> 0 | BH14: =G14*AO14 -> 0 | BI14: =G14*AP14 -> 0 | BJ14: =G14*H14 -> 0 | BK14: M | BL14: 713 | BW14: =I14 -> 0 | BX14: Pouzdro potrubní izolační ROCKWOOL 800 22/20 mm
A15: 3 | C15: 631547114 | D15: Pouzdro potrubní izolační ROCKWOOL 800 28/30 mm | F15: m | G15: 0 | J15: =ROUND(G15*AO15,2) -> 0 | K15: =ROUND(G15*AP15,2) -> 0 | L15: =ROUND(G15*H15,2) -> 0 | M15: =L15*(1+BW15/100) -> 0 | N15: 0.00031 | O15: =G15*N15 -> 0 | P15: RTS I / 2025 | Z15: =ROUND(IF(AQ15="5",BJ15,0),2) -> 0 | AB15: =ROUND(IF(AQ15="1",BH15,0),2) -> 0 | AC15: =ROUND(IF(AQ15="1",BI15,0),2) -> 0 | AD15: =ROUND(IF(AQ15="7",BH15,0),2) -> 0 | AE15: =ROUND(IF(AQ15="7",BI15,0),2) -> 0 | AF15: =ROUND(IF(AQ15="2",BH15,0),2) -> 0 | AG15: =ROUND(IF(AQ15="2",BI15,0),2) -> 0 | AH15: =ROUND(IF(AQ15="0",BJ15,0),2) -> 0 | AJ15: =IF(AN15=0,L15,0) -> 0 | AK15: =IF(AN15=12,L15,0) -> 0 | AL15: =IF(AN15=21,L15,0) -> 0 | AN15: 12 | AO15: =H15*1 -> 0 | AP15: =H15*(1-1) -> 0 | AQ15: 7 | AV15: =ROUND(AW15+AX15,2) -> 0 | AW15: =ROUND(G15*AO15,2) -> 0 | AX15: =ROUND(G15*AP15,2) -> 0 | AY15: 713_ | AZ15: 71_ | BA15: _ | BC15: =AW15+AX15 -> 0 | BD15: =H15/(100-BE15)*100 -> 0 | BE15: 0 | BF15: =O15 -> 0 | BH15: =G15*AO15 -> 0 | BI15: =G15*AP15 -> 0 | BJ15: =G15*H15 -> 0 | BK15: M | BL15: 713 | BW15: =I15 -> 0 | BX15: Pouzdro potrubní izolační ROCKWOOL 800 28/30 mm
A16: 4 | C16: 631547115 | D16: Pouzdro potrubní izolační ROCKWOOL 800 35/30 mm | F16: m | G16: 0 | J16: =ROUND(G16*AO16,2) -> 0 | K16: =ROUND(G16*AP16,2) -> 0 | L16: =ROUND(G16*H16,2) -> 0 | M16: =L16*(1+BW16/100) -> 0 | N16: 0.00034 | O16: =G16*N16 -> 0 | P16: RTS I / 2025 | Z16: =ROUND(IF(AQ16="5",BJ16,0),2) -> 0 | AB16: =ROUND(IF(AQ16="1",BH16,0),2) -> 0 | AC16: =ROUND(IF(AQ16="1",BI16,0),2) -> 0 | AD16: =ROUND(IF(AQ16="7",BH16,0),2) -> 0 | AE16: =ROUND(IF(AQ16="7",BI16,0),2) -> 0 | AF16: =ROUND(IF(AQ16="2",BH16,0),2) -> 0 | AG16: =ROUND(IF(AQ16="2",BI16,0),2) -> 0 | AH16: =ROUND(IF(AQ16="0",BJ16,0),2) -> 0 | AJ16: =IF(AN16=0,L16,0) -> 0 | AK16: =IF(AN16=12,L16,0) -> 0 | AL16: =IF(AN16=21,L16,0) -> 0 | AN16: 12 | AO16: =H16*1 -> 0 | AP16: =H16*(1-1) -> 0 | AQ16: 7 | AV16: =ROUND(AW16+AX16,2) -> 0 | AW16: =ROUND(G16*AO16,2) -> 0 | AX16: =ROUND(G16*AP16,2) -> 0 | AY16: 713_ | AZ16: 71_ | BA16: _ | BC16: =AW16+AX16 -> 0 | BD16: =H16/(100-BE16)*100 -> 0 | BE16: 0 | BF16: =O16 -> 0 | BH16: =G16*AO16 -> 0 | BI16: =G16*AP16 -> 0 | BJ16: =G16*H16 -> 0 | BK16: M | BL16: 713 | BW16: =I16 -> 0 | BX16: Pouzdro potrubní izolační ROCKWOOL 800 35/30 mm
A17: 5 | C17: 631547116 | D17: Pouzdro potrubní izolační ROCKWOOL 800 42/30 mm | F17: m | G17: 85 | J17: =ROUND(G17*AO17,2) -> 0 | K17: =ROUND(G17*AP17,2) -> 0 | L17: =ROUND(G17*H17,2) -> 0 | M17: =L17*(1+BW17/100) -> 0 | N17: 0.00039 | O17: =G17*N17 -> 0.03315 | P17: RTS I / 2025 | Z17: =ROUND(IF(AQ17="5",BJ17,0),2) -> 0 | AB17: =ROUND(IF(AQ17="1",BH17,0),2) -> 0 | AC17: =ROUND(IF(AQ17="1",BI17,0),2) -> 0 | AD17: =ROUND(IF(AQ17="7",BH17,0),2) -> 0 | AE17: =ROUND(IF(AQ17="7",BI17,0),2) -> 0 | AF17: =ROUND(IF(AQ17="2",BH17,0),2) -> 0 | AG17: =ROUND(IF(AQ17="2",BI17,0),2) -> 0 | AH17: =ROUND(IF(AQ17="0",BJ17,0),2) -> 0 | AJ17: =IF(AN17=0,L17,0) -> 0 | AK17: =IF(AN17=12,L17,0) -> 0 | AL17: =IF(AN17=21,L17,0) -> 0 | AN17: 12 | AO17: =H17*1 -> 0 | AP17: =H17*(1-1) -> 0 | AQ17: 7 | AV17: =ROUND(AW17+AX17,2) -> 0 | AW17: =ROUND(G17*AO17,2) -> 0 | AX17: =ROUND(G17*AP17,2) -> 0 | AY17: 713_ | AZ17: 71_ | BA17: _ | BC17: =AW17+AX17 -> 0 | BD17: =H17/(100-BE17)*100 -> 0 | BE17: 0 | BF17: =O17 -> 0.03315 | BH17: =G17*AO17 -> 0 | BI17: =G17*AP17 -> 0 | BJ17: =G17*H17 -> 0 | BK17: M | BL17: 713 | BW17: =I17 -> 0 | BX17: Pouzdro potrubní izolační ROCKWOOL 800 42/30 mm
A18: 6 | C18: 631547118 | D18: Pouzdro potrubní izolační ROCKWOOL 800 54/30 mm | F18: m | G18: 90 | J18: =ROUND(G18*AO18,2) -> 0 | K18: =ROUND(G18*AP18,2) -> 0 | L18: =ROUND(G18*H18,2) -> 0 | M18: =L18*(1+BW18/100) -> 0 | N18: 0.00047 | O18: =G18*N18 -> 0.0423 | P18: RTS I / 2025 | Z18: =ROUND(IF(AQ18="5",BJ18,0),2) -> 0 | AB18: =ROUND(IF(AQ18="1",BH18,0),2) -> 0 | AC18: =ROUND(IF(AQ18="1",BI18,0),2) -> 0 | AD18: =ROUND(IF(AQ18="7",BH18,0),2) -> 0 | AE18: =ROUND(IF(AQ18="7",BI18,0),2) -> 0 | AF18: =ROUND(IF(AQ18="2",BH18,0),2) -> 0 | AG18: =ROUND(IF(AQ18="2",BI18,0),2) -> 0 | AH18: =ROUND(IF(AQ18="0",BJ18,0),2) -> 0 | AJ18: =IF(AN18=0,L18,0) -> 0 | AK18: =IF(AN18=12,L18,0) -> 0 | AL18: =IF(AN18=21,L18,0) -> 0 | AN18: 12 | AO18: =H18*1 -> 0 | AP18: =H18*(1-1) -> 0 | AQ18: 7 | AV18: =ROUND(AW18+AX18,2) -> 0 | AW18: =ROUND(G18*AO18,2) -> 0 | AX18: =ROUND(G18*AP18,2) -> 0 | AY18: 713_ | AZ18: 71_ | BA18: _ | BC18: =AW18+AX18 -> 0 | BD18: =H18/(100-BE18)*100 -> 0 | BE18: 0 | BF18: =O18 -> 0.0423 | BH18: =G18*AO18 -> 0 | BI18: =G18*AP18 -> 0 | BJ18: =G18*H18 -> 0 | BK18: M | BL18: 713 | BW18: =I18 -> 0 | BX18: Pouzdro potrubní izolační ROCKWOOL 800 54/30 mm
A19: 7 | C19: 631547220 | D19: Pouzdro potrubní izolační ROCKWOOL 800 64/40 mm | F19: m | G19: 45 | J19: =ROUND(G19*AO19,2) -> 0 | K19: =ROUND(G19*AP19,2) -> 0 | L19: =ROUND(G19*H19,2) -> 0 | M19: =L19*(1+BW19/100) -> 0 | N19: 0.00097 | O19: =G19*N19 -> 0.04365 | P19: RTS I / 2025 | Z19: =ROUND(IF(AQ19="5",BJ19,0),2) -> 0 | AB19: =ROUND(IF(AQ19="1",BH19,0),2) -> 0 | AC19: =ROUND(IF(AQ19="1",BI19,0),2) -> 0 | AD19: =ROUND(IF(AQ19="7",BH19,0),2) -> 0 | AE19: =ROUND(IF(AQ19="7",BI19,0),2) -> 0 | AF19: =ROUND(IF(AQ19="2",BH19,0),2) -> 0 | AG19: =ROUND(IF(AQ19="2",BI19,0),2) -> 0 | AH19: =ROUND(IF(AQ19="0",BJ19,0),2) -> 0 | AJ19: =IF(AN19=0,L19,0) -> 0 | AK19: =IF(AN19=12,L19,0) -> 0 | AL19: =IF(AN19=21,L19,0) -> 0 | AN19: 12 | AO19: =H19*1 -> 0 | AP19: =H19*(1-1) -> 0 | AQ19: 7 | AV19: =ROUND(AW19+AX19,2) -> 0 | AW19: =ROUND(G19*AO19,2) -> 0 | AX19: =ROUND(G19*AP19,2) -> 0 | AY19: 713_ | AZ19: 71_ | BA19: _ | BC19: =AW19+AX19 -> 0 | BD19: =H19/(100-BE19)*100 -> 0 | BE19: 0 | BF19: =O19 -> 0.04365 | BH19: =G19*AO19 -> 0 | BI19: =G19*AP19 -> 0 | BJ19: =G19*H19 -> 0 | BK19: M | BL19: 713 | BW19: =I19 -> 0 | BX19: Pouzdro potrubní izolační ROCKWOOL 800 64/40 mm
C20: 721 | D20: Vnitřní kanalizace | J20: =SUM(J21:J51) -> 0 | K20: =SUM(K21:K51) -> 0 | L20: =SUM(L21:L51) -> 0 | M20: =SUM(M21:M51) -> 0 | O20: =SUM(O21:O51) -> 4.58462 | AS20: =SUM(AJ21:AJ51) -> 0 | AT20: =SUM(AK21:AK51) -> 0 | AU20: =SUM(AL21:AL51) -> 0
A21: 8 | C21: 721176101R00 | D21: Potrubí HT připojovací, D 32 x 1,8 mm | F21: m | G21: 75 | J21: =ROUND(G21*AO21,2) -> 0 | K21: =ROUND(G21*AP21,2) -> 0 | L21: =ROUND(G21*H21,2) -> 0 | M21: =L21*(1+BW21/100) -> 0 | N21: 0.00034 | O21: =G21*N21 -> 0.0255 | P21: RTS I / 2025 | Z21: =ROUND(IF(AQ21="5",BJ21,0),2) -> 0 | AB21: =ROUND(IF(AQ21="1",BH21,0),2) -> 0 | AC21: =ROUND(IF(AQ21="1",BI21,0),2) -> 0 | AD21: =ROUND(IF(AQ21="7",BH21,0),2) -> 0 | AE21: =ROUND(IF(AQ21="7",BI21,0),2) -> 0 | AF21: =ROUND(IF(AQ21="2",BH21,0),2) -> 0 | AG21: =ROUND(IF(AQ21="2",BI21,0),2) -> 0 | AH21: =ROUND(IF(AQ21="0",BJ21,0),2) -> 0 | AJ21: =IF(AN21=0,L21,0) -> 0 | AK21: =IF(AN21=12,L21,0) -> 0 | AL21: =IF(AN21=21,L21,0) -> 0 | AN21: 12 | AO21: =H21*0.306450617 -> 0 | AP21: =H21*(1-0.306450617) -> 0 | AQ21: 7 | AV21: =ROUND(AW21+AX21,2) -> 0 | AW21: =ROUND(G21*AO21,2) -> 0 | AX21: =ROUND(G21*AP21,2) -> 0 | AY21: 721_ | AZ21: 72_ | BA21: _ | BC21: =AW21+AX21 -> 0 | BD21: =H21/(100-BE21)*100 -> 0 | BE21: 0 | BF21: =O21 -> 0.0255 | BH21: =G21*AO21 -> 0 | BI21: =G21*AP21 -> 0 | BJ21: =G21*H21 -> 0 | BK21: P | BL21: 721 | BW21: =I21 -> 0 | BX21: Potrubí HT připojovací, D 32 x 1,8 mm
A22: 9 | C22: 721176102R00 | D22: Potrubí HT připojovací D 40 x 1,8 mm | F22: m | G22: 40 | J22: =ROUND(G22*AO22,2) -> 0 | K22: =ROUND(G22*AP22,2) -> 0 | L22: =ROUND(G22*H22,2) -> 0 | M22: =L22*(1+BW22/100) -> 0 | N22: 0.00038 | O22: =G22*N22 -> 0.0152 | P22: RTS I / 2025 | Z22: =ROUND(IF(AQ22="5",BJ22,0),2) -> 0 | AB22: =ROUND(IF(AQ22="1",BH22,0),2) -> 0 | AC22: =ROUND(IF(AQ22="1",BI22,0),2) -> 0 | AD22: =ROUND(IF(AQ22="7",BH22,0),2) -> 0 | AE22: =ROUND(IF(AQ22="7",BI22,0),2) -> 0 | AF22: =ROUND(IF(AQ22="2",BH22,0),2) -> 0 | AG22: =ROUND(IF(AQ22="2",BI22,0),2) -> 0 | AH22: =ROUND(IF(AQ22="0",BJ22,0),2) -> 0 | AJ22: =IF(AN22=0,L22,0) -> 0 | AK22: =IF(AN22=12,L22,0) -> 0 | AL22: =IF(AN22=21,L22,0) -> 0 | AN22: 12 | AO22: =H22*0.259176594 -> 0 | AP22: =H22*(1-0.259176594) -> 0 | AQ22: 7 | AV22: =ROUND(AW22+AX22,2) -> 0 | AW22: =ROUND(G22*AO22,2) -> 0 | AX22: =ROUND(G22*AP22,2) -> 0 | AY22: 721_ | AZ22: 72_ | BA22: _ | BC22: =AW22+AX22 -> 0 | BD22: =H22/(100-BE22)*100 -> 0 | BE22: 0 | BF22: =O22 -> 0.0152 | BH22: =G22*AO22 -> 0 | BI22: =G22*AP22 -> 0 | BJ22: =G22*H22 -> 0 | BK22: P | BL22: 721 | BW22: =I22 -> 0 | BX22: Potrubí HT připojovací D 40 x 1,8 mm
A23: 10 | C23: 721176103R00 | D23: Potrubí HT připojovací D 50 x 1,8 mm | F23: m | G23: 40 | J23: =ROUND(G23*AO23,2) -> 0 | K23: =ROUND(G23*AP23,2) -> 0 | L23: =ROUND(G23*H23,2) -> 0 | M23: =L23*(1+BW23/100) -> 0 | N23: 0.00047 | O23: =G23*N23 -> 0.0188 | P23: RTS I / 2025 | Z23: =ROUND(IF(AQ23="5",BJ23,0),2) -> 0 | AB23: =ROUND(IF(AQ23="1",BH23,0),2) -> 0 | AC23: =ROUND(IF(AQ23="1",BI23,0),2) -> 0 | AD23: =ROUND(IF(AQ23="7",BH23,0),2) -> 0 | AE23: =ROUND(IF(AQ23="7",BI23,0),2) -> 0 | AF23: =ROUND(IF(AQ23="2",BH23,0),2) -> 0 | AG23: =ROUND(IF(AQ23="2",BI23,0),2) -> 0 | AH23: =ROUND(IF(AQ23="0",BJ23,0),2) -> 0 | AJ23: =IF(AN23=0,L23,0) -> 0 | AK23: =IF(AN23=12,L23,0) -> 0 | AL23: =IF(AN23=21,L23,0) -> 0 | AN23: 12 | AO23: =H23*0.268268346 -> 0 | AP23: =H23*(1-0.268268346) -> 0 | AQ23: 7 | AV23: =ROUND(AW23+AX23,2) -> 0 | AW23: =ROUND(G23*AO23,2) -> 0 | AX23: =ROUND(G23*AP23,2) -> 0 | AY23: 721_ | AZ23: 72_ | BA23: _ | BC23: =AW23+AX23 -> 0 | BD23: =H23/(100-BE23)*100 -> 0 | BE23: 0 | BF23: =O23 -> 0.0188 | BH23: =G23*AO23 -> 0 | BI23: =G23*AP23 -> 0 | BJ23: =G23*H23 -> 0 | BK23: P | BL23: 721 | BW23: =I23 -> 0 | BX23: Potrubí HT připojovací D 50 x 1,8 mm
A24: 11 | C24: 721176105R00 | D24: Potrubí HT připojovací D 110 x 2,7 mm | F24: m | G24: 45 | J24: =ROUND(G24*AO24,2) -> 0 | K24: =ROUND(G24*AP24,2) -> 0 | L24: =ROUND(G24*H24,2) -> 0 | M24: =L24*(1+BW24/100) -> 0 | N24: 0.00152 | O24: =G24*N24 -> 0.0684 | P24: RTS I / 2025 | Z24: =ROUND(IF(AQ24="5",BJ24,0),2) -> 0 | AB24: =ROUND(IF(AQ24="1",BH24,0),2) -> 0 | AC24: =ROUND(IF(AQ24="1",BI24,0),2) -> 0 | AD24: =ROUND(IF(AQ24="7",BH24,0),2) -> 0 | AE24: =ROUND(IF(AQ24="7",BI24,0),2) -> 0 | AF24: =ROUND(IF(AQ24="2",BH24,0),2) -> 0 | AG24: =ROUND(IF(AQ24="2",BI24,0),2) -> 0 | AH24: =ROUND(IF(AQ24="0",BJ24,0),2) -> 0 | AJ24: =IF(AN24=0,L24,0) -> 0 | AK24: =IF(AN24=12,L24,0) -> 0 | AL24: =IF(AN24=21,L24,0) -> 0 | AN24: 12 | AO24: =H24*0.244082569 -> 0 | AP24: =H24*(1-0.244082569) -> 0 | AQ24: 7 | AV24: =ROUND(AW24+AX24,2) -> 0 | AW24: =ROUND(G24*AO24,2) -> 0 | AX24: =ROUND(G24*AP24,2) -> 0 | AY24: 721_ | AZ24: 72_ | BA24: _ | BC24: =AW24+AX24 -> 0 | BD24: =H24/(100-BE24)*100 -> 0 | BE24: 0 | BF24: =O24 -> 0.0684 | BH24: =G24*AO24 -> 0 | BI24: =G24*AP24 -> 0 | BJ24: =G24*H24 -> 0 | BK24: P | BL24: 721 | BW24: =I24 -> 0 | BX24: Potrubí HT připojovací D 110 x 2,7 mm
A25: 12 | C25: 721177715R00 | D25: Potrubí Wavin SiTech+ odpadní svislé D 110 x 3,6mm | F25: m | G25: 60 | J25: =ROUND(G25*AO25,2) -> 0 | K25: =ROUND(G25*AP25,2) -> 0 | L25: =ROUND(G25*H25,2) -> 0 | M25: =L25*(1+BW25/100) -> 0 | N25: 0.00206 | O25: =G25*N25 -> 0.1236 | P25: RTS I / 2025 | Z25: =ROUND(IF(AQ25="5",BJ25,0),2) -> 0 | AB25: =ROUND(IF(AQ25="1",BH25,0),2) -> 0 | AC25: =ROUND(IF(AQ25="1",BI25,0),2) -> 0 | AD25: =ROUND(IF(AQ25="7",BH25,0),2) -> 0 | AE25: =ROUND(IF(AQ25="7",BI25,0),2) -> 0 | AF25: =ROUND(IF(AQ25="2",BH25,0),2) -> 0 | AG25: =ROUND(IF(AQ25="2",BI25,0),2) -> 0 | AH25: =ROUND(IF(AQ25="0",BJ25,0),2) -> 0 | AJ25: =IF(AN25=0,L25,0) -> 0 | AK25: =IF(AN25=12,L25,0) -> 0 | AL25: =IF(AN25=21,L25,0) -> 0 | AN25: 12 | AO25: =H25*0.540411237 -> 0 | AP25: =H25*(1-0.540411237) -> 0 | AQ25: 7 | AV25: =ROUND(AW25+AX25,2) -> 0 | AW25: =ROUND(G25*AO25,2) -> 0 | AX25: =ROUND(G25*AP25,2) -> 0 | AY25: 721_ | AZ25: 72_ | BA25: _ | BC25: =AW25+AX25 -> 0 | BD25: =H25/(100-BE25)*100 -> 0 | BE25: 0 | BF25: =O25 -> 0.1236 | BH25: =G25*AO25 -> 0 | BI25: =G25*AP25 -> 0 | BJ25: =G25*H25 -> 0 | BK25: P | BL25: 721 | BW25: =I25 -> 0 | BX25: Potrubí Wavin SiTech+ odpadní svislé D 110 x 3,6mm
A26: 13 | C26: 721177716R00 | D26: Potrubí Wavin SiTech+ odpadní svislé D 125 x 4,0mm | F26: m | G26: 80 | J26: =ROUND(G26*AO26,2) -> 0 | K26: =ROUND(G26*AP26,2) -> 0 | L26: =ROUND(G26*H26,2) -> 0 | M26: =L26*(1+BW26/100) -> 0 | N26: 0.0025 | O26: =G26*N26 -> 0.2 | P26: RTS I / 2025 | Z26: =ROUND(IF(AQ26="5",BJ26,0),2) -> 0 | AB26: =ROUND(IF(AQ26="1",BH26,0),2) -> 0 | AC26: =ROUND(IF(AQ26="1",BI26,0),2) -> 0 | AD26: =ROUND(IF(AQ26="7",BH26,0),2) -> 0 | AE26: =ROUND(IF(AQ26="7",BI26,0),2) -> 0 | AF26: =ROUND(IF(AQ26="2",BH26,0),2) -> 0 | AG26: =ROUND(IF(AQ26="2",BI26,0),2) -> 0 | AH26: =ROUND(IF(AQ26="0",BJ26,0),2) -> 0 | AJ26: =IF(AN26=0,L26,0) -> 0 | AK26: =IF(AN26=12,L26,0) -> 0 | AL26: =IF(AN26=21,L26,0) -> 0 | AN26: 12 | AO26: =H26*0.622900994 -> 0 | AP26: =H26*(1-0.622900994) -> 0 | AQ26: 7 | AV26: =ROUND(AW26+AX26,2) -> 0 | AW26: =ROUND(G26*AO26,2) -> 0 | AX26: =ROUND(G26*AP26,2) -> 0 | AY26: 721_ | AZ26: 72_ | BA26: _ | BC26: =AW26+AX26 -> 0 | BD26: =H26/(100-BE26)*100 -> 0 | BE26: 0 | BF26: =O26 -> 0.2 | BH26: =G26*AO26 -> 0 | BI26: =G26*AP26 -> 0 | BJ26: =G26*H26 -> 0 | BK26: P | BL26: 721 | BW26: =I26 -> 0 | BX26: Potrubí Wavin SiTech+ odpadní svislé D 125 x 4,0mm
A27: 14 | C27: 721177717R00 | D27: Potrubí Wavin SiTech+ odpadní svislé D 160 x 5,0mm | F27: m | G27: 300 | J27: =ROUND(G27*AO27,2) -> 0 | K27: =ROUND(G27*AP27,2) -> 0 | L27: =ROUND(G27*H27,2) -> 0 | M27: =L27*(1+BW27/100) -> 0 | N27: 0.00373 | O27: =G27*N27 -> 1.119 | P27: RTS I / 2025 | Z27: =ROUND(IF(AQ27="5",BJ27,0),2) -> 0 | AB27: =ROUND(IF(AQ27="1",BH27,0),2) -> 0 | AC27: =ROUND(IF(AQ27="1",BI27,0),2) -> 0 | AD27: =ROUND(IF(AQ27="7",BH27,0),2) -> 0 | AE27: =ROUND(IF(AQ27="7",BI27,0),2) -> 0 | AF27: =ROUND(IF(AQ27="2",BH27,0),2) -> 0 | AG27: =ROUND(IF(AQ27="2",BI27,0),2) -> 0 | AH27: =ROUND(IF(AQ27="0",BJ27,0),2) -> 0 | AJ27: =IF(AN27=0,L27,0) -> 0 | AK27: =IF(AN27=12,L27,0) -> 0 | AL27: =IF(AN27=21,L27,0) -> 0 | AN27: 12 | AO27: =H27*0.760747153 -> 0 | AP27: =H27*(1-0.760747153) -> 0 | AQ27: 7 | AV27: =ROUND(AW27+AX27,2) -> 0 | AW27: =ROUND(G27*AO27,2) -> 0 | AX27: =ROUND(G27*AP27,2) -> 0 | AY27: 721_ | AZ27: 72_ | BA27: _ | BC27: =AW27+AX27 -> 0 | BD27: =H27/(100-BE27)*100 -> 0 | BE27: 0 | BF27: =O27 -> 1.119 | BH27: =G27*AO27 -> 0 | BI27: =G27*AP27 -> 0 | BJ27: =G27*H27 -> 0 | BK27: P | BL27: 721 | BW27: =I27 -> 0 | BX27: Potrubí Wavin SiTech+ odpadní svislé D 160 x 5,0mm
A28: 15 | C28: 721177725R00 | D28: Čisticí kus Wavin SiTech+, odpadní svislé D 110 | F28: kus | G28: 30 | J28: =ROUND(G28*AO28,2) -> 0 | K28: =ROUND(G28*AP28,2) -> 0 | L28: =ROUND(G28*H28,2) -> 0 | M28: =L28*(1+BW28/100) -> 0 | N28: 0.00024 | O28: =G28*N28 -> 0.0072 | P28: RTS I / 2025 | Z28: =ROUND(IF(AQ28="5",BJ28,0),2) -> 0 | AB28: =ROUND(IF(AQ28="1",BH28,0),2) -> 0 | AC28: =ROUND(IF(AQ28="1",BI28,0),2) -> 0 | AD28: =ROUND(IF(AQ28="7",BH28,0),2) -> 0 | AE28: =ROUND(IF(AQ28="7",BI28,0),2) -> 0 | AF28: =ROUND(IF(AQ28="2",BH28,0),2) -> 0 | AG28: =ROUND(IF(AQ28="2",BI28,0),2) -> 0 | AH28: =ROUND(IF(AQ28="0",BJ28,0),2) -> 0 | AJ28: =IF(AN28=0,L28,0) -> 0 | AK28: =IF(AN28=12,L28,0) -> 0 | AL28: =IF(AN28=21,L28,0) -> 0 | AN28: 12 | AO28: =H28*0.560580205 -> 0 | AP28: =H28*(1-0.560580205) -> 0 | AQ28: 7 | AV28: =ROUND(AW28+AX28,2) -> 0 | AW28: =ROUND(G28*AO28,2) -> 0 | AX28: =ROUND(G28*AP28,2) -> 0 | AY28: 721_ | AZ28: 72_ | BA28: _ | BC28: =AW28+AX28 -> 0 | BD28: =H28/(100-BE28)*100 -> 0 | BE28: 0 | BF28: =O28 -> 0.0072 | BH28: =G28*AO28 -> 0 | BI28: =G28*AP28 -> 0 | BJ28: =G28*H28 -> 0 | BK28: P | BL28: 721 | BW28: =I28 -> 0 | BX28: Čisticí kus Wavin SiTech+, odpadní svislé D 110
A29: 16 | C29: 721176222R00 | D29: Potrubí KG svodné (ležaté) v zemi D 110 x 3,2 mm | F29: m | G29: 35 | J29: =ROUND(G29*AO29,2) -> 0 | K29: =ROUND(G29*AP29,2) -> 0 | L29: =ROUND(G29*H29,2) -> 0 | M29: =L29*(1+BW29/100) -> 0 | N29: 0.0021 | O29: =G29*N29 -> 0.0735 | P29: RTS I / 2025 | Z29: =ROUND(IF(AQ29="5",BJ29,0),2) -> 0 | AB29: =ROUND(IF(AQ29="1",BH29,0),2) -> 0 | AC29: =ROUND(IF(AQ29="1",BI29,0),2) -> 0 | AD29: =ROUND(IF(AQ29="7",BH29,0),2) -> 0 | AE29: =ROUND(IF(AQ29="7",BI29,0),2) -> 0 | AF29: =ROUND(IF(AQ29="2",BH29,0),2) -> 0 | AG29: =ROUND(IF(AQ29="2",BI29,0),2) -> 0 | AH29: =ROUND(IF(AQ29="0",BJ29,0),2) -> 0 | AJ29: =IF(AN29=0,L29,0) -> 0 | AK29: =IF(AN29=12,L29,0) -> 0 | AL29: =IF(AN29=21,L29,0) -> 0 | AN29: 12 | AO29: =H29*0.342947433 -> 0 | AP29: =H29*(1-0.342947433) -> 0 | AQ29: 7 | AV29: =ROUND(AW29+AX29,2) -> 0 | AW29: =ROUND(G29*AO29,2) -> 0 | AX29: =ROUND(G29*AP29,2) -> 0 | AY29: 721_ | AZ29: 72_ | BA29: _ | BC29: =AW29+AX29 -> 0 | BD29: =H29/(100-BE29)*100 -> 0 | BE29: 0 | BF29: =O29 -> 0.0735 | BH29: =G29*AO29 -> 0 | BI29: =G29*AP29 -> 0 | BJ29: =G29*H29 -> 0 | BK29: P | BL29: 721 | BW29: =I29 -> 0 | BX29: Potrubí KG svodné (ležaté) v zemi D 110 x 3,2 mm
A30: 17 | C30: 721176223R00 | D30: Potrubí KG svodné (ležaté) v zemi, D 125 x 3,2 mm | F30: m | G30: 70 | J30: =ROUND(G30*AO30,2) -> 0 | K30: =ROUND(G30*AP30,2) -> 0 | L30: =ROUND(G30*H30,2) -> 0 | M30: =L30*(1+BW30/100) -> 0 | N30: 0.00252 | O30: =G30*N30 -> 0.1764 | P30: RTS I / 2025 | Z30: =ROUND(IF(AQ30="5",BJ30,0),2) -> 0 | AB30: =ROUND(IF(AQ30="1",BH30,0),2) -> 0 | AC30: =ROUND(IF(AQ30="1",BI30,0),2) -> 0 | AD30: =ROUND(IF(AQ30="7",BH30,0),2) -> 0 | AE30: =ROUND(IF(AQ30="7",BI30,0),2) -> 0 | AF30: =ROUND(IF(AQ30="2",BH30,0),2) -> 0 | AG30: =ROUND(IF(AQ30="2",BI30,0),2) -> 0 | AH30: =ROUND(IF(AQ30="0",BJ30,0),2) -> 0 | AJ30: =IF(AN30=0,L30,0) -> 0 | AK30: =IF(AN30=12,L30,0) -> 0 | AL30: =IF(AN30=21,L30,0) -> 0 | AN30: 12 | AO30: =H30*0.418447205 -> 0 | AP30: =H30*(1-0.418447205) -> 0 | AQ30: 7 | AV30: =ROUND(AW30+AX30,2) -> 0 | AW30: =ROUND(G30*AO30,2) -> 0 | AX30: =ROUND(G30*AP30,2) -> 0 | AY30: 721_ | AZ30: 72_ | BA30: _ | BC30: =AW30+AX30 -> 0 | BD30: =H30/(100-BE30)*100 -> 0 | BE30: 0 | BF30: =O30 -> 0.1764 | BH30: =G30*AO30 -> 0 | BI30: =G30*AP30 -> 0 | BJ30: =G30*H30 -> 0 | BK30: P | BL30: 721 | BW30: =I30 -> 0 | BX30: Potrubí KG svodné (ležaté) v zemi, D 125 x 3,2 mm
A31: 18 | C31: 721176224R00 | D31: Potrubí KG svodné (ležaté) v zemi, D 160 x 4,0 mm | F31: m | G31: 240 | J31: =ROUND(G31*AO31,2) -> 0 | K31: =ROUND(G31*AP31,2) -> 0 | L31: =ROUND(G31*H31,2) -> 0 | M31: =L31*(1+BW31/100) -> 0 | N31: 0.00357 | O31: =G31*N31 -> 0.8568 | P31: RTS I / 2025 | Z31: =ROUND(IF(AQ31="5",BJ31,0),2) -> 0 | AB31: =ROUND(IF(AQ31="1",BH31,0),2) -> 0 | AC31: =ROUND(IF(AQ31="1",BI31,0),2) -> 0 | AD31: =ROUND(IF(AQ31="7",BH31,0),2) -> 0 | AE31: =ROUND(IF(AQ31="7",BI31,0),2) -> 0 | AF31: =ROUND(IF(AQ31="2",BH31,0),2) -> 0 | AG31: =ROUND(IF(AQ31="2",BI31,0),2) -> 0 | AH31: =ROUND(IF(AQ31="0",BJ31,0),2) -> 0 | AJ31: =IF(AN31=0,L31,0) -> 0 | AK31: =IF(AN31=12,L31,0) -> 0 | AL31: =IF(AN31=21,L31,0) -> 0 | AN31: 12 | AO31: =H31*0.573708609 -> 0 | AP31: =H31*(1-0.573708609) -> 0 | AQ31: 7 | AV31: =ROUND(AW31+AX31,2) -> 0 | AW31: =ROUND(G31*AO31,2) -> 0 | AX31: =ROUND(G31*AP31,2) -> 0 | AY31: 721_ | AZ31: 72_ | BA31: _ | BC31: =AW31+AX31 -> 0 | BD31: =H31/(100-BE31)*100 -> 0 | BE31: 0 | BF31: =O31 -> 0.8568 | BH31: =G31*AO31 -> 0 | BI31: =G31*AP31 -> 0 | BJ31: =G31*H31 -> 0 | BK31: P | BL31: 721 | BW31: =I31 -> 0 | BX31: Potrubí KG svodné (ležaté) v zemi, D 160 x 4,0 mm
A32: 19 | C32: 721176225R00 | D32: Potrubí KG svodné (ležaté) v zemi, D 200 x 4,9 mm | F32: m | G32: 140 | J32: =ROUND(G32*AO32,2) -> 0 | K32: =ROUND(G32*AP32,2) -> 0 | L32: =ROUND(G32*H32,2) -> 0 | M32: =L32*(1+BW32/100) -> 0 | N32: 0.00403 | O32: =G32*N32 -> 0.5642 | P32: RTS I / 2025 | Z32: =ROUND(IF(AQ32="5",BJ32,0),2) -> 0 | AB32: =ROUND(IF(AQ32="1",BH32,0),2) -> 0 | AC32: =ROUND(IF(AQ32="1",BI32,0),2) -> 0 | AD32: =ROUND(IF(AQ32="7",BH32,0),2) -> 0 | AE32: =ROUND(IF(AQ32="7",BI32,0),2) -> 0 | AF32: =ROUND(IF(AQ32="2",BH32,0),2) -> 0 | AG32: =ROUND(IF(AQ32="2",BI32,0),2) -> 0 | AH32: =ROUND(IF(AQ32="0",BJ32,0),2) -> 0 | AJ32: =IF(AN32=0,L32,0) -> 0 | AK32: =IF(AN32=12,L32,0) -> 0 | AL32: =IF(AN32=21,L32,0) -> 0 | AN32: 12 | AO32: =H32*0.556022719 -> 0 | AP32: =H32*(1-0.556022719) -> 0 | AQ32: 7 | AV32: =ROUND(AW32+AX32,2) -> 0 | AW32: =ROUND(G32*AO32,2) -> 0 | AX32: =ROUND(G32*AP32,2) -> 0 | AY32: 721_ | AZ32: 72_ | BA32: _ | BC32: =AW32+AX32 -> 0 | BD32: =H32/(100-BE32)*100 -> 0 | BE32: 0 | BF32: =O32 -> 0.5642 | BH32: =G32*AO32 -> 0 | BI32: =G32*AP32 -> 0 | BJ32: =G32*H32 -> 0 | BK32: P | BL32: 721 | BW32: =I32 -> 0 | BX32: Potrubí KG svodné (ležaté) v zemi, D 200 x 4,9 mm
A33: 20 | C33: 721176226R00 | D33: Potrubí KG svodné (ležaté) v zemi, DN 250 x 6,2 mm | F33: m | G33: 160 | J33: =ROUND(G33*AO33,2) -> 0 | K33: =ROUND(G33*AP33,2) -> 0 | L33: =ROUND(G33*H33,2) -> 0 | M33: =L33*(1+BW33/100) -> 0 | N33: 0.00698 | O33: =G33*N33 -> 1.1168 | P33: RTS I / 2025 | Z33: =ROUND(IF(AQ33="5",BJ33,0),2) -> 0 | AB33: =ROUND(IF(AQ33="1",BH33,0),2) -> 0 | AC33: =ROUND(IF(AQ33="1",BI33,0),2) -> 0 | AD33: =ROUND(IF(AQ33="7",BH33,0),2) -> 0 | AE33: =ROUND(IF(AQ33="7",BI33,0),2) -> 0 | AF33: =ROUND(IF(AQ33="2",BH33,0),2) -> 0 | AG33: =ROUND(IF(AQ33="2",BI33,0),2) -> 0 | AH33: =ROUND(IF(AQ33="0",BJ33,0),2) -> 0 | AJ33: =IF(AN33=0,L33,0) -> 0 | AK33: =IF(AN33=12,L33,0) -> 0 | AL33: =IF(AN33=21,L33,0) -> 0 | AN33: 12 | AO33: =H33*0.599097606 -> 0 | AP33: =H33*(1-0.599097606) -> 0 | AQ33: 7 | AV33: =ROUND(AW33+AX33,2) -> 0 | AW33: =ROUND(G33*AO33,2) -> 0 | AX33: =ROUND(G33*AP33,2) -> 0 | AY33: 721_ | AZ33: 72_ | BA33: _ | BC33: =AW33+AX33 -> 0 | BD33: =H33/(100-BE33)*100 -> 0 | BE33: 0 | BF33: =O33 -> 1.1168 | BH33: =G33*AO33 -> 0 | BI33: =G33*AP33 -> 0 | BJ33: =G33*H33 -> 0 | BK33: P | BL33: 721 | BW33: =I33 -> 0 | BX33: Potrubí KG svodné (ležaté) v zemi, DN 250 x 6,2 mm
A34: 21 | C34: 721194104R00 | D34: Vyvedení odpadních výpustek D 40 x 1,8 | F34: kus | G34: 33 | J34: =ROUND(G34*AO34,2) -> 0 | K34: =ROUND(G34*AP34,2) -> 0 | L34: =ROUND(G34*H34,2) -> 0 | M34: =L34*(1+BW34/100) -> 0 | N34: 0 | O34: =G34*N34 -> 0 | P34: RTS I / 2025 | Z34: =ROUND(IF(AQ34="5",BJ34,0),2) -> 0 | AB34: =ROUND(IF(AQ34="1",BH34,0),2) -> 0 | AC34: =ROUND(IF(AQ34="1",BI34,0),2) -> 0 | AD34: =ROUND(IF(AQ34="7",BH34,0),2) -> 0 | AE34: =ROUND(IF(AQ34="7",BI34,0),2) -> 0 | AF34: =ROUND(IF(AQ34="2",BH34,0),2) -> 0 | AG34: =ROUND(IF(AQ34="2",BI34,0),2) -> 0 | AH34: =ROUND(IF(AQ34="0",BJ34,0),2) -> 0 | AJ34: =IF(AN34=0,L34,0) -> 0 | AK34: =IF(AN34=12,L34,0) -> 0 | AL34: =IF(AN34=21,L34,0) -> 0 | AN34: 12 | AO34: =H34*0 -> 0 | AP34: =H34*(1-0) -> 0 | AQ34: 7 | AV34: =ROUND(AW34+AX34,2) -> 0 | AW34: =ROUND(G34*AO34,2) -> 0 | AX34: =ROUND(G34*AP34,2) -> 0 | AY34: 721_ | AZ34: 72_ | BA34: _ | BC34: =AW34+AX34 -> 0 | BD34: =H34/(100-BE34)*100 -> 0 | BE34: 0 | BF34: =O34 -> 0 | BH34: =G34*AO34 -> 0 | BI34: =G34*AP34 -> 0 | BJ34: =G34*H34 -> 0 | BK34: P | BL34: 721 | BW34: =I34 -> 0 | BX34: Vyvedení odpadních výpustek D 40 x 1,8
A35: 22 | C35: 721194105R00 | D35: Vyvedení odpadních výpustek D 50 x 1,8 | F35: kus | G35: 30 | J35: =ROUND(G35*AO35,2) -> 0 | K35: =ROUND(G35*AP35,2) -> 0 | L35: =ROUND(G35*H35,2) -> 0 | M35: =L35*(1+BW35/100) -> 0 | N35: 0 | O35: =G35*N35 -> 0 | P35: RTS I / 2025 | Z35: =ROUND(IF(AQ35="5",BJ35,0),2) -> 0 | AB35: =ROUND(IF(AQ35="1",BH35,0),2) -> 0 | AC35: =ROUND(IF(AQ35="1",BI35,0),2) -> 0 | AD35: =ROUND(IF(AQ35="7",BH35,0),2) -> 0 | AE35: =ROUND(IF(AQ35="7",BI35,0),2) -> 0 | AF35: =ROUND(IF(AQ35="2",BH35,0),2) -> 0 | AG35: =ROUND(IF(AQ35="2",BI35,0),2) -> 0 | AH35: =ROUND(IF(AQ35="0",BJ35,0),2) -> 0 | AJ35: =IF(AN35=0,L35,0) -> 0 | AK35: =IF(AN35=12,L35,0) -> 0 | AL35: =IF(AN35=21,L35,0) -> 0 | AN35: 12 | AO35: =H35*0 -> 0 | AP35: =H35*(1-0) -> 0 | AQ35: 7 | AV35: =ROUND(AW35+AX35,2) -> 0 | AW35: =ROUND(G35*AO35,2) -> 0 | AX35: =ROUND(G35*AP35,2) -> 0 | AY35: 721_ | AZ35: 72_ | BA35: _ | BC35: =AW35+AX35 -> 0 | BD35: =H35/(100-BE35)*100 -> 0 | BE35: 0 | BF35: =O35 -> 0 | BH35: =G35*AO35 -> 0 | BI35: =G35*AP35 -> 0 | BJ35: =G35*H35 -> 0 | BK35: P | BL35: 721 | BW35: =I35 -> 0 | BX35: Vyvedení odpadních výpustek D 50 x 1,8
A36: 23 | C36: 721194109R00 | D36: Vyvedení odpadních výpustek D 110 x 2,3 | F36: kus | G36: 21 | J36: =ROUND(G36*AO36,2) -> 0 | K36: =ROUND(G36*AP36,2) -> 0 | L36: =ROUND(G36*H36,2) -> 0 | M36: =L36*(1+BW36/100) -> 0 | N36: 0 | O36: =G36*N36 -> 0 | P36: RTS I / 2025 | Z36: =ROUND(IF(AQ36="5",BJ36,0),2) -> 0 | AB36: =ROUND(IF(AQ36="1",BH36,0),2) -> 0 | AC36: =ROUND(IF(AQ36="1",BI36,0),2) -> 0 | AD36: =ROUND(IF(AQ36="7",BH36,0),2) -> 0 | AE36: =ROUND(IF(AQ36="7",BI36,0),2) -> 0 | AF36: =ROUND(IF(AQ36="2",BH36,0),2) -> 0 | AG36: =ROUND(IF(AQ36="2",BI36,0),2) -> 0 | AH36: =ROUND(IF(AQ36="0",BJ36,0),2) -> 0 | AJ36: =IF(AN36=0,L36,0) -> 0 | AK36: =IF(AN36=12,L36,0) -> 0 | AL36: =IF(AN36=21,L36,0) -> 0 | AN36: 12 | AO36: =H36*0 -> 0 | AP36: =H36*(1-0) -> 0 | AQ36: 7 | AV36: =ROUND(AW36+AX36,2) -> 0 | AW36: =ROUND(G36*AO36,2) -> 0 | AX36: =ROUND(G36*AP36,2) -> 0 | AY36: 721_ | AZ36: 72_ | BA36: _ | BC36: =AW36+AX36 -> 0 | BD36: =H36/(100-BE36)*100 -> 0 | BE36: 0 | BF36: =O36 -> 0 | BH36: =G36*AO36 -> 0 | BI36: =G36*AP36 -> 0 | BJ36: =G36*H36 -> 0 | BK36: P | BL36: 721 | BW36: =I36 -> 0 | BX36: Vyvedení odpadních výpustek D 110 x 2,3
A37: 24 | C37: 721273200RT2 | D37: Souprava ventilační střešní HL | F37: kus | G37: 6 | J37: =ROUND(G37*AO37,2) -> 0 | K37: =ROUND(G37*AP37,2) -> 0 | L37: =ROUND(G37*H37,2) -> 0 | M37: =L37*(1+BW37/100) -> 0 | N37: 0.00013 | O37: =G37*N37 -> 0.00078 | P37: RTS I / 2025 | Z37: =ROUND(IF(AQ37="5",BJ37,0),2) -> 0 | AB37: =ROUND(IF(AQ37="1",BH37,0),2) -> 0 | AC37: =ROUND(IF(AQ37="1",BI37,0),2) -> 0 | AD37: =ROUND(IF(AQ37="7",BH37,0),2) -> 0 | AE37: =ROUND(IF(AQ37="7",BI37,0),2) -> 0 | AF37: =ROUND(IF(AQ37="2",BH37,0),2) -> 0 | AG37: =ROUND(IF(AQ37="2",BI37,0),2) -> 0 | AH37: =ROUND(IF(AQ37="0",BJ37,0),2) -> 0 | AJ37: =IF(AN37=0,L37,0) -> 0 | AK37: =IF(AN37=12,L37,0) -> 0 | AL37: =IF(AN37=21,L37,0) -> 0 | AN37: 12 | AO37: =H37*0.835483251 -> 0 | AP37: =H37*(1-0.835483251) -> 0 | AQ37: 7 | AV37: =ROUND(AW37+AX37,2) -> 0 | AW37: =ROUND(G37*AO37,2) -> 0 | AX37: =ROUND(G37*AP37,2) -> 0 | AY37: 721_ | AZ37: 72_ | BA37: _ | BC37: =AW37+AX37 -> 0 | BD37: =H37/(100-BE37)*100 -> 0 | BE37: 0 | BF37: =O37 -> 0.00078 | BH37: =G37*AO37 -> 0 | BI37: =G37*AP37 -> 0 | BJ37: =G37*H37 -> 0 | BK37: P | BL37: 721 | BW37: =I37 -> 0 | BX37: Souprava ventilační střešní HL
C38: Varianta: | D38: souprava větrací hlavice PP HL807 D 75 mm
A39: 25 | C39: 721223423RT2 | D39: Vpusť podlahová se zápachovou uzávěrkou HL 310N | F39: kus | G39: 5 | J39: =ROUND(G39*AO39,2) -> 0 | K39: =ROUND(G39*AP39,2) -> 0 | L39: =ROUND(G39*H39,2) -> 0 | M39: =L39*(1+BW39/100) -> 0 | N39: 0.00075 | O39: =G39*N39 -> 0.00375 | P39: RTS I / 2025 | Z39: =ROUND(IF(AQ39="5",BJ39,0),2) -> 0 | AB39: =ROUND(IF(AQ39="1",BH39,0),2) -> 0 | AC39: =ROUND(IF(AQ39="1",BI39,0),2) -> 0 | AD39: =ROUND(IF(AQ39="7",BH39,0),2) -> 0 | AE39: =ROUND(IF(AQ39="7",BI39,0),2) -> 0 | AF39: =ROUND(IF(AQ39="2",BH39,0),2) -> 0 | AG39: =ROUND(IF(AQ39="2",BI39,0),2) -> 0 | AH39: =ROUND(IF(AQ39="0",BJ39,0),2) -> 0 | AJ39: =IF(AN39=0,L39,0) -> 0 | AK39: =IF(AN39=12,L39,0) -> 0 | AL39: =IF(AN39=21,L39,0) -> 0 | AN39: 12 | AO39: =H39*0.931151961 -> 0 | AP39: =H39*(1-0.931151961) -> 0 | AQ39: 7 | AV39: =ROUND(AW39+AX39,2) -> 0 | AW39: =ROUND(G39*AO39,2) -> 0 | AX39: =ROUND(G39*AP39,2) -> 0 | AY39: 721_ | AZ39: 72_ | BA39: _ | BC39: =AW39+AX39 -> 0 | BD39: =H39/(100-BE39)*100 -> 0 | BE39: 0 | BF39: =O39 -> 0.00375 | BH39: =G39*AO39 -> 0 | BI39: =G39*AP39 -> 0 | BJ39: =G39*H39 -> 0 | BK39: P | BL39: 721 | BW39: =I39 -> 0 | BX39: Vpusť podlahová se zápachovou uzávěrkou HL 310N
C40: Varianta: | D40: mřížka nerez 115 x 115 D 50/75/110 mm, Primus
A41: 26 | C41: 721242110R00 | D41: Lapač střešních splavenin PP HL600, kloub | F41: kus | G41: 1 | J41: =ROUND(G41*AO41,2) -> 0 | K41: =ROUND(G41*AP41,2) -> 0 | L41: =ROUND(G41*H41,2) -> 0 | M41: =L41*(1+BW41/100) -> 0 | N41: 0.07663 | O41: =G41*N41 -> 0.07663 | P41: RTS I / 2025 | Z41: =ROUND(IF(AQ41="5",BJ41,0),2) -> 0 | AB41: =ROUND(IF(AQ41="1",BH41,0),2) -> 0 | AC41: =ROUND(IF(AQ41="1",BI41,0),2) -> 0 | AD41: =ROUND(IF(AQ41="7",BH41,0),2) -> 0 | AE41: =ROUND(IF(AQ41="7",BI41,0),2) -> 0 | AF41: =ROUND(IF(AQ41="2",BH41,0),2) -> 0 | AG41: =ROUND(IF(AQ41="2",BI41,0),2) -> 0 | AH41: =ROUND(IF(AQ41="0",BJ41,0),2) -> 0 | AJ41: =IF(AN41=0,L41,0) -> 0 | AK41: =IF(AN41=12,L41,0) -> 0 | AL41: =IF(AN41=21,L41,0) -> 0 | AN41: 12 | AO41: =H41*0.909155366 -> 0 | AP41: =H41*(1-0.909155366) -> 0 | AQ41: 7 | AV41: =ROUND(AW41+AX41,2) -> 0 | AW41: =ROUND(G41*AO41,2) -> 0 | AX41: =ROUND(G41*AP41,2) -> 0 | AY41: 721_ | AZ41: 72_ | BA41: _ | BC41: =AW41+AX41 -> 0 | BD41: =H41/(100-BE41)*100 -> 0 | BE41: 0 | BF41: =O41 -> 0.07663 | BH41: =G41*AO41 -> 0 | BI41: =G41*AP41 -> 0 | BJ41: =G41*H41 -> 0 | BK41: P | BL41: 721 | BW41: =I41 -> 0 | BX41: Lapač střešních splavenin PP HL600, kloub
A42: 27 | C42: 721290111R00 | D42: Zkouška těsnosti kanalizace vodou DN 125 | F42: m | G42: 900 | J42: =ROUND(G42*AO42,2) -> 0 | K42: =ROUND(G42*AP42,2) -> 0 | L42: =ROUND(G42*H42,2) -> 0 | M42: =L42*(1+BW42/100) -> 0 | N42: 0 | O42: =G42*N42 -> 0 | P42: RTS I / 2025 | Z42: =ROUND(IF(AQ42="5",BJ42,0),2) -> 0 | AB42: =ROUND(IF(AQ42="1",BH42,0),2) -> 0 | AC42: =ROUND(IF(AQ42="1",BI42,0),2) -> 0 | AD42: =ROUND(IF(AQ42="7",BH42,0),2) -> 0 | AE42: =ROUND(IF(AQ42="7",BI42,0),2) -> 0 | AF42: =ROUND(IF(AQ42="2",BH42,0),2) -> 0 | AG42: =ROUND(IF(AQ42="2",BI42,0),2) -> 0 | AH42: =ROUND(IF(AQ42="0",BJ42,0),2) -> 0 | AJ42: =IF(AN42=0,L42,0) -> 0 | AK42: =IF(AN42=12,L42,0) -> 0 | AL42: =IF(AN42=21,L42,0) -> 0 | AN42: 12 | AO42: =H42*0.026021685 -> 0 | AP42: =H42*(1-0.026021685) -> 0 | AQ42: 7 | AV42: =ROUND(AW42+AX42,2) -> 0 | AW42: =ROUND(G42*AO42,2) -> 0 | AX42: =ROUND(G42*AP42,2) -> 0 | AY42: 721_ | AZ42: 72_ | BA42: _ | BC42: =AW42+AX42 -> 0 | BD42: =H42/(100-BE42)*100 -> 0 | BE42: 0 | BF42: =O42 -> 0 | BH42: =G42*AO42 -> 0 | BI42: =G42*AP42 -> 0 | BJ42: =G42*H42 -> 0 | BK42: P | BL42: 721 | BW42: =I42 -> 0 | BX42: Zkouška těsnosti kanalizace vodou DN 125
A43: 28 | C43: 721231144VL1 | D43: Vtok terasový TW pod dlažbou, zateplení 300 mm + zápachová uzávěrka TW | F43: kpl | G43: 14 | J43: =ROUND(G43*AO43,2) -> 0 | K43: =ROUND(G43*AP43,2) -> 0 | L43: =ROUND(G43*H43,2) -> 0 | M43: =L43*(1+BW43/100) -> 0 | N43: 0.00242 | O43: =G43*N43 -> 0.03388 | P43: RTS I / 2022 | Z43: =ROUND(IF(AQ43="5",BJ43,0),2) -> 0 | AB43: =ROUND(IF(AQ43="1",BH43,0),2) -> 0 | AC43: =ROUND(IF(AQ43="1",BI43,0),2) -> 0 | AD43: =ROUND(IF(AQ43="7",BH43,0),2) -> 0 | AE43: =ROUND(IF(AQ43="7",BI43,0),2) -> 0 | AF43: =ROUND(IF(AQ43="2",BH43,0),2) -> 0 | AG43: =ROUND(IF(AQ43="2",BI43,0),2) -> 0 | AH43: =ROUND(IF(AQ43="0",BJ43,0),2) -> 0 | AJ43: =IF(AN43=0,L43,0) -> 0 | AK43: =IF(AN43=12,L43,0) -> 0 | AL43: =IF(AN43=21,L43,0) -> 0 | AN43: 12 | AO43: =H43*0.93172311 -> 0 | AP43: =H43*(1-0.93172311) -> 0 | AQ43: 7 | AV43: =ROUND(AW43+AX43,2) -> 0 | AW43: =ROUND(G43*AO43,2) -> 0 | AX43: =ROUND(G43*AP43,2) -> 0 | AY43: 721_ | AZ43: 72_ | BA43: _ | BC43: =AW43+AX43 -> 0 | BD43: =H43/(100-BE43)*100 -> 0 | BE43: 0 | BF43: =O43 -> 0.03388 | BH43: =G43*AO43 -> 0 | BI43: =G43*AP43 -> 0 | BJ43: =G43*H43 -> 0 | BK43: P | BL43: 721 | BW43: =I43 -> 0 | BX43: Vtok terasový TW pod dlažbou, zateplení 300 mm + zápachová uzávěrka TW
C44: Varianta: | D44: průměr 75-125 mm
...

Sheet Stavební rozpočet - součet
A1: Stavební rozpočet - rekapitulace
A2: Název stavby: | C2: ='Stavební rozpočet'!D2 -> Areál společnosti FORESTINA s.r.o. – Horažďovice, Blatenská 587 | D2: Doba výstavby: | F2: Objednatel: | G2: ='Stavební rozpočet'!K2
A4: Druh stavby: | C4: ='Stavební rozpočet'!D4 -> Zdravotně technické instalace | D4: Začátek výstavby: | F4: Projektant: | G4: ='Stavební rozpočet'!K4 -> Ing. Michal Albrecht
A6: Lokalita: | C6: ='Stavební rozpočet'!D6 -> !!!! Pracovní verze !!!! | D6: Konec výstavby: | F6: Zhotovitel: | G6: ='Stavební rozpočet'!K6
A8: Zpracoval: | C8: ='Stavební rozpočet'!K8 -> Ing. Michal Albrecht | D8: Zpracováno dne: | E8: 11.06.2025 | F8: Zpracováno dne: | G8: ='Stavební rozpočet'!H8 -> 11.06.2025
A10: Objekt | B10: Kód | C10: Zkrácený popis | D10: Náklady (Kč) - dodávka | E10: Náklady (Kč) - Montáž | F10: Náklady (Kč) - celkem | G10: Celková hmotnost (t)
B11: 713 | C11: Izolace tepelné | D11: =ROUND('Stavební rozpočet'!J12,2) -> 0 | E11: =ROUND('Stavební rozpočet'!K12,2) -> 0 | F11: =ROUND('Stavební rozpočet'!L12,2) -> 0 | G11: ='Stavební rozpočet'!O12 -> 0.1191 | H11: T | I11: =IF(H11="F",0,F11) -> 0
B12: 721 | C12: Vnitřní kanalizace | D12: =ROUND('Stavební rozpočet'!J20,2) -> 0 | E12: =ROUND('Stavební rozpočet'!K20,2) -> 0 | F12: =ROUND('Stavební rozpočet'!L20,2) -> 0 | G12: ='Stavební rozpočet'!O20 -> 4.58462 | H12: T | I12: =IF(H12="F",0,F12) -> 0
B13: 722 | C13: Vnitřní vodovod | D13: =ROUND('Stavební rozpočet'!J52,2) -> 0 | E13: =ROUND('Stavební rozpočet'!K52,2) -> 0 | F13: =ROUND('Stavební rozpočet'!L52,2) -> 0 | G13: ='Stavební rozpočet'!O52 -> 1.66158 | H13: T | I13: =IF(H13="F",0,F13) -> 0
B14: 725 | C14: Zařizovací předměty | D14: =ROUND('Stavební rozpočet'!J114,2) -> 0 | E14: =ROUND('Stavební rozpočet'!K114,2) -> 0 | F14: =ROUND('Stavební rozpočet'!L114,2) -> 0 | G14: ='Stavební rozpočet'!O114 -> 2.19973 | H14: T | I14: =IF(H14="F",0,F14) -> 0
B15: 900 | C15: Ostatní | D15: =ROUND('Stavební rozpočet'!J150,2) -> 0 | E15: =ROUND('Stavební rozpočet'!K150,2) -> 0 | F15: =ROUND('Stavební rozpočet'!L150,2) -> 0 | G15: ='Stavební rozpočet'!O150 -> 0 | H15: T | I15: =IF(H15="F",0,F15) -> 0
E16: Celkem: | F16: =ROUND(SUM(I11:I15),2) -> 0

Sheet Krycí list rozpočtu
A1: Krycí list rozpočtu
A2: Název stavby: | C2: ='Stavební rozpočet'!D2 -> Areál společnosti FORESTINA s.r.o. – Horažďovice, Blatenská 587 | E2: Objednatel: | F2: ='Stavební rozpočet'!K2 | H2: IČO/DIČ:
A4: Druh stavby: | C4: ='Stavební rozpočet'!D4 -> Zdravotně technické instalace | E4: Projektant: | F4: ='Stavební rozpočet'!K4 -> Ing. Michal Albrecht | H4: IČO/DIČ:
A6: Lokalita: | C6: ='Stavební rozpočet'!D6 -> !!!! Pracovní verze !!!! | E6: Zhotovitel: | F6: ='Stavební rozpočet'!K6 | H6: IČO/DIČ:
A8: Začátek výstavby: | C8: ='Stavební rozpočet'!H4 | E8: Konec výstavby: | F8: ='Stavební rozpočet'!H6 | H8: Položek: | I8: 120
A10: JKSO: | C10: ='Stavební rozpočet'!D8 | E10: Zpracoval: | F10: ='Stavební rozpočet'!K8 -> Ing. Michal Albrecht | H10: Datum: | I10: ='Stavební rozpočet'!H8 -> 11.06.2025
A12: Rozpočtové náklady v Kč
A13: A | B13: Základní rozpočtové náklady | D13: B | E13: Doplňkové náklady | G13: C | H13: Náklady na umístění stavby (NUS)
A14: HSV | B14: Dodávky | C14: =SUM('Stavební rozpočet'!AB12:AB304) -> 0 | D14: Práce přesčas | F14: =VORN!I15 -> 0 | G14: Zařízení staveniště | I14: 0
B15: Montáž | C15: =SUM('Stavební rozpočet'!AC12:AC304) -> 0 | D15: Bez pevné podl. | F15: =VORN!I16 -> 0 | G15: Mimostav. doprava | I15: =VORN!I23 -> 0
A16: PSV | B16: Dodávky | C16: =SUM('Stavební rozpočet'!AD12:AD304) -> 0 | D16: Kulturní památka | F16: =VORN!I17 -> 0 | G16: Územní vlivy | I16: =VORN!I24 -> 0
B17: Montáž | C17: =SUM('Stavební rozpočet'!AE12:AE304) -> 0 | D17: Vytyčení podzemních | F17: =VORN!I18 -> 0 | G17: Provozní vlivy | I17: =VORN!I25 -> 0
A18: "M" | B18: Dodávky | C18: =SUM('Stavební rozpočet'!AF12:AF304) -> 0 | G18: Ostatní | I18: =VORN!I26 -> 0
B19: Montáž | C19: =SUM('Stavební rozpočet'!AG12:AG304) -> 0 | G19: NUS z rozpočtu | I19: =VORN!I27 -> 0
A20: Ostatní materiál | C20: =SUM('Stavební rozpočet'!AH12:AH304) -> 0
A21: Přesun hmot a sutí | C21: =SUM('Stavební rozpočet'!Z12:Z304) -> 0
A22: ZRN celkem | C22: =ROUND(SUM(C14:C21),2) -> 0 | D22: DN celkem | F22: =SUM(F14:F21) -> 0 | G22: NUS celkem | I22: =SUM(I14:I21) -> 0
D23: DN celkem z obj. | F23: 0 | G23: NUS celkem z obj. | I23: 0
G24: VORN celkem | I24: =vorn_sum -> 0
G25: VORN celkem z obj. | I25: 0
A27: Základ 0% | C27: =ROUND(SUM('Stavební rozpočet'!AJ12:AJ304),2) -> 0
A28: Základ 12% | C28: =ROUND(SUM('Stavební rozpočet'!AK12:AK304)+(F22+I22+F23+I23+I24+I25),2) -> 0 | D28: DPH 12% | F28: =ROUND(C28*(12/100),2) -> 0 | G28: Celkem bez DPH | I28: =ROUND(SUM(C27:C29),2) -> 0
A29: Základ 21% | C29: =ROUND(SUM('Stavební rozpočet'!AL12:AL304),2) -> 0 | D29: DPH 21% | F29: =ROUND(C29*(21/100),2) -> 0 | G29: Celkem včetně DPH | I29: =ROUND(SUM(F28:F29)+I28,2) -> 0
A31: Projektant | D31: Objednatel | G31: Zhotovitel
A35: Datum, razítko a podpis | D35: Datum, razítko a podpis | G35: Datum, razítko a podpis
A36: Poznámka:

Sheet VORN
A1: Vedlejší a ostatní rozpočtové náklady
A2: Název stavby: | C2: ='Stavební rozpočet'!D2 -> Areál společnosti FORESTINA s.r.o. – Horažďovice, Blatenská 587 | E2: Objednatel: | F2: ='Stavební rozpočet'!K2 | H2: IČO/DIČ:
A4: Druh stavby: | C4: ='Stavební rozpočet'!D4 -> Zdravotně technické instalace | E4: Projektant: | F4: ='Stavební rozpočet'!K4 -> Ing. Michal Albrecht | H4: IČO/DIČ:
A6: Lokalita: | C6: ='Stavební rozpočet'!D6 -> !!!! Pracovní verze !!!! | E6: Zhotovitel: | F6: ='Stavební rozpočet'!K6 | H6: IČO/DIČ:
A8: Začátek výstavby: | C8: ='Stavební rozpočet'!H4 | E8: Konec výstavby: | F8: ='Stavební rozpočet'!H6 | H8: Položek: | I8: 120
A10: JKSO: | C10: ='Stavební rozpočet'!D8 | E10: Zpracoval: | F10: ='Stavební rozpočet'!K8 -> Ing. Michal Albrecht | H10: Datum: | I10: ='Stavební rozpočet'!H8 -> 11.06.2025
A13: Vedlejší rozpočtové náklady VRN
A14: Doplňkové náklady DN | F14: Kč | G14: % | H14: Základna | I14: Kč
A15: Práce přesčas | F15: 0 | I15: =F15 -> 0
A16: Bez pevné podl. | F16: 0 | I16: =F16 -> 0
A17: Kulturní památka | F17: 0 | I17: =F17 -> 0
A18: Vytyčení podzemních | F18: 0 | I18: =F18 -> 0
A19: Celkem DN | I19: =SUM(I15:I18) -> 0
A21: Náklady na umístění stavby (NUS) | F21: Kč | G21: % | H21: Základna | I21: Kč
A22: Zařízení staveniště | F22: 20000 | I22: =F22 -> 20000
A23: Mimostav. doprava | F23: 0 | I23: =F23 -> 0
A24: Územní vlivy | F24: 0 | I24: =F24 -> 0
A25: Provozní vlivy | F25: 0 | I25: =F25 -> 0
A26: Ostatní | F26: 0 | I26: =F26 -> 0
A27: NUS z rozpočtu | F27: 0 | I27: =F27 -> 0
A28: Celkem NUS | I28: =SUM(I22:I27) -> 20000
A30: Celkem VRN | F30: =I19+I28 -> 20000
A34: Ostatní rozpočtové náklady ORN
A35: Ostatní rozpočtové náklady (ORN) | F35: Kč | G35: % | H35: Základna | I35: Kč
F36: 0 | I36: =F36 -> 0
A37: Celkem ORN | I37: =SUM(I36:I36) -> 0
