Workbook

Sheet Krycí list CZK
A1: CENOVÁ NABÍDKA
A3: Zadavatel: | C3: ANTRACIT KOP s.r.o. | D3: Zhotovitel:
C4: Lihovarská 689/40A
C5: 718 00 Ostrava - Kunčičky
A6: Vyřizuje: Tel.: e-mail: | C6: Ing. Aleš Kytnar | D6: Vyřizuje: Tel.: e-mail:
C7: 775615054
C8: ales.kytnar@antracitproperty.eu
D9: Zpracoval: Tel.: e-mail:
D10: Tel.:
D11: e-mail:
A12: Číslo nabídky: | D12: Datum: | E12: =TODAY() -> 45219
A15: NÁZEV AKCE :
A17: Novostavba logistické haly ANTRACIT, Město Touškov
A21: REKAPITULACE NÁKLADŮ :
A22: ='Položkový rozpočet CZK'!A6 -> V. | B22: ='Položkový rozpočet CZK'!B6 -> VRN a projekční práce | E22: =D23 -> 0
A23: ='Položkový rozpočet CZK'!A7 -> V.01 | B23: ='Položkový rozpočet CZK'!B7 -> VRN a projekční práce | D23: ='Položkový rozpočet CZK'!G7 -> 0
A24: ='Položkový rozpočet CZK'!A13 -> P. | B24: ='Položkový rozpočet CZK'!B13 -> Příprava území | E24: =SUM(D25:D26) -> 0
A25: ='Položkový rozpočet CZK'!A14 -> P.01 | B25: ='Položkový rozpočet CZK'!B14 -> HTÚ | D25: ='Položkový rozpočet CZK'!G14 -> 0
A26: ='Položkový rozpočet CZK'!A18 -> P.02 | B26: ='Položkový rozpočet CZK'!B18 -> Demolice | D26: ='Položkový rozpočet CZK'!G18 -> 0
A27: ='Položkový rozpočet CZK'!A24 -> A. | B27: ='Položkový rozpočet CZK'!B24 -> Hala | E27: =SUM(D28:D43) -> 0
A28: ='Položkový rozpočet CZK'!A25 -> A.01 | B28: ='Položkový rozpočet CZK'!B25 -> Zemní práce | C28: ='Položkový rozpočet CZK'!C25 -> 0 | D28: ='Položkový rozpočet CZK'!G25 -> 0
A29: ='Položkový rozpočet CZK'!A29 -> A.02 | B29: ='Položkový rozpočet CZK'!B29 -> Základy | C29: ='Položkový rozpočet CZK'!C29 -> 0 | D29: ='Položkový rozpočet CZK'!G29 -> 0
A30: ='Položkový rozpočet CZK'!A33 -> A.03 | B30: ='Položkový rozpočet CZK'!B33 -> Nosné konstrukce | C30: ='Položkový rozpočet CZK'!C33 -> 0 | D30: ='Položkový rozpočet CZK'!G33 -> 0
A31: ='Položkový rozpočet CZK'!A40 -> A.04 | B31: ='Položkový rozpočet CZK'!B40 -> Podlahové desky | C31: ='Položkový rozpočet CZK'!C40 -> 0 | D31: ='Položkový rozpočet CZK'!G40 -> 0
A32: ='Položkový rozpočet CZK'!A43 -> A.05 | B32: ='Položkový rozpočet CZK'!B43 -> Fasády objektu vč.OK a lemování | C32: ='Položkový rozpočet CZK'!C43 -> 0 | D32: ='Položkový rozpočet CZK'!G43 -> 0
A33: ='Položkový rozpočet CZK'!A47 -> A.06 | B33: ='Položkový rozpočet CZK'!B47 -> Výplně otvorů - okna,dveře,vrata | C33: ='Položkový rozpočet CZK'!C47 -> 0 | D33: ='Položkový rozpočet CZK'!G47 -> 0
A34: ='Položkový rozpočet CZK'!A54 -> A.07 | B34: ='Položkový rozpočet CZK'!B54 -> Střešní plášť vč.OK | C34: ='Položkový rozpočet CZK'!C54 -> 0 | D34: ='Položkový rozpočet CZK'!G54 -> 0
A35: ='Položkový rozpočet CZK'!A60 -> A.08 | B35: ='Položkový rozpočet CZK'!B60 -> Záchytný systém | C35: ='Položkový rozpočet CZK'!C60 -> 0 | D35: ='Položkový rozpočet CZK'!G60 -> 0
A36: ='Položkový rozpočet CZK'!A62 -> A.09 | B36: ='Položkový rozpočet CZK'!B62 -> Podtlakové odvodnění | C36: ='Položkový rozpočet CZK'!C62 -> 0 | D36: ='Položkový rozpočet CZK'!G62 -> 0
A37: ='Položkový rozpočet CZK'!A64 -> A.10 | B37: ='Položkový rozpočet CZK'!B64 -> Světlíky + RWA + kouřové zástěny | C37: ='Položkový rozpočet CZK'!C64 -> 0 | D37: ='Položkový rozpočet CZK'!G64 -> 0
A38: ='Položkový rozpočet CZK'!A68 -> A.11 | B38: ='Položkový rozpočet CZK'!B68 -> Vnitřní vestavby - ASR | C38: ='Položkový rozpočet CZK'!C68 -> 0 | D38: ='Položkový rozpočet CZK'!G68 -> 0
A39: ='Položkový rozpočet CZK'!A74 -> A.12 | B39: ='Položkový rozpočet CZK'!B74 -> Zámečnické konstrukce | C39: ='Položkový rozpočet CZK'!C74 -> 0 | D39: ='Položkový rozpočet CZK'!G74 -> 0
A40: ='Položkový rozpočet CZK'!A81 -> A.13 | B40: ='Položkový rozpočet CZK'!B81 -> TZB | C40: ='Položkový rozpočet CZK'!C81 -> 0 | D40: ='Položkový rozpočet CZK'!G81 -> 0
A41: ='Položkový rozpočet CZK'!A85 -> A.14 | B41: ='Položkový rozpočet CZK'!B85 -> Elektroinstalace | C41: ='Položkový rozpočet CZK'!C85 -> 0 | D41: ='Položkový rozpočet CZK'!G85 -> 0
A42: ='Položkový rozpočet CZK'!A87 -> A.15 | B42: ='Položkový rozpočet CZK'!B87 -> EPS | C42: ='Položkový rozpočet CZK'!C87 -> 0 | D42: ='Položkový rozpočet CZK'!G87 -> 0
A43: ='Položkový rozpočet CZK'!A89 -> A.16 | B43: ='Položkový rozpočet CZK'!B89 -> MaR | C43: ='Položkový rozpočet CZK'!C89 -> 0 | D43: ='Položkový rozpočet CZK'!G89 -> 0
A44: ='Položkový rozpočet CZK'!A91 -> B | B44: ='Položkový rozpočet CZK'!B91 -> Venkovní objekty a inženýrské sítě | E44: =SUM(D45:D49) -> 0
A45: ='Položkový rozpočet CZK'!A92 -> B.01 | B45: ='Položkový rozpočet CZK'!B92 -> Zpevněné plochy, sadové úpravy | D45: ='Položkový rozpočet CZK'!G92 -> 0
A46: ='Položkový rozpočet CZK'!A97 -> B.02 | B46: ='Položkový rozpočet CZK'!B97 -> Vodovod | D46: ='Položkový rozpočet CZK'!G97 -> 0
A47: ='Položkový rozpočet CZK'!A101 -> B.03 | B47: ='Položkový rozpočet CZK'!B101 -> Kanalizace | D47: ='Položkový rozpočet CZK'!G101 -> 0
...

Sheet Položkový rozpočet CZK
A1: ='Krycí list CZK'!A17 -> Novostavba logistické haly ANTRACIT, Město Touškov
A2: ='Krycí list CZK'!C12 -> 0
A3: ='Krycí list CZK'!E12 -> 45219
A4: C. | B4: Popis | C4: MN | D4: J | E4: JC | F4: CELKEM | G4: TOTAL SUM
B5: SUMA KONTROL | G5: =G6+G13+G24+G91 -> 0
A6: V. | B6: VRN a projekční práce | G6: =SUM(G7:G12) -> 0
A7: V.01 | B7: VRN a projekční práce | G7: =SUM(F8:F12) -> 0
A8: 1. | B8: DPS | D8: sum | F8: =C8*E8 -> 0
A9: 2. | B9: DSPS | D9: sum | F9: =C9*E9 -> 0
A10: 3. | B10: Zařízení staveniště | D10: sum | F10: =C10*E10 -> 0
A11: 4. | B11: Vedlejší rozpočtové náklady | D11: sum | F11: =C11*E11 -> 0
A12: 5. | B12: BREEAM good | D12: sum | F12: =C12*E12 -> 0
A13: P. | B13: Příprava území | G13: =SUM(G14:G23) -> 0
A14: P.01 | B14: HTÚ | G14: =SUM(F15:F17) -> 0
A15: 1. | B15: Výkopy pro můstky, základy apod. | D15: m3 | F15: =C15*E15 -> 0
A16: 2. | B16: Násypy, zásypy | D16: m3 | F16: =C16*E16 -> 0
A17: 3. | B17: Stabilizace | D17: m2 | F17: =C17*E17 -> 0
A18: P.02 | B18: Demolice | G18: =SUM(F19:F23) -> 0
A19: 1. | B19: Odstranění stávajících komunikací | D19: m2 | F19: =C19*E19 -> 0
A20: 2. | B20: Odstranění inženýrských sítí | D20: sum | F20: =C20*E20 -> 0
A21: 3. | B21: Demolice objektů | D21: m3 | F21: =C21*E21 -> 0
A22: 4. | B22: Nadrcení využitelného materiálu na frakci 0-63 a uložení v rámci staveniště | D22: m3 | F22: =C22*E22 -> 0
A23: 5. | B23: Odvoz a likvidace odpadu | D23: m3 | F23: =C23*E23 -> 0
A24: A. | B24: Hala | G24: =SUM(G25:G90) -> 0
A25: A.01 | B25: Zemní práce | G25: =SUM(F26:F28) -> 0
A26: 1. | B26: Výkopy pro můstky, základy apod. | D26: m3 | F26: =C26*E26 -> 0
A27: 2. | B27: Násypy, zásypy | D27: m3 | F27: =C27*E27 -> 0
A28: 3. | B28: Stabilizace | D28: m2 | F28: =C28*E28 -> 0
A29: A.02 | B29: Základy | G29: =SUM(F30:F32) -> 0
A30: 1. | B30: Pilotové založení, vč. kalichů | D30: ks | F30: =C30*E30 -> 0
A31: 2. | B31: Monolizické základy | D31: m3 | F31: =C31*E31 -> 0
A32: 3. | B32: Vrstvy štěrkodrtě pod halou | D32: m2 | F32: =C32*E32 -> 0
A33: A.03 | B33: Nosné konstrukce | G33: =SUM(F34:F39) -> 0
A34: 1. | B34: ŽB prefa překládací můstky | D34: sum | F34: =C34*E34 -> 0
A35: 2. | B35: ŽB prefa sokly | D35: sum | F35: =C35*E35 -> 0
A36: 3. | B36: ŽB prefa zateplené stěny u můstků | D36: sum | F36: =C36*E36 -> 0
A37: 4. | B37: ŽB prefa sloupy | D37: sum | F37: =C37*E37 -> 0
A38: 5. | B38: Střešní ŽB prefa konstrukce | D38: sum | F38: =C38*E38 -> 0
A39: 6. | B39: Monolitické dobetonávky | D39: m3 | F39: =C39*E39 -> 0
A40: A.04 | B40: Podlahové desky | G40: =SUM(F41:F42) -> 0
...
