Workbook

Sheet Rekapitulace stavby
A1: Export Komplet | AZ1: VZ | BA1: 2.0 | BT1: False | BU1: False | BV1: {fbc1a46a-d86b-4298-981e-dbf850c2ca92}
AR2: >> skryté sloupce << | BS2: 0,01 | BT2: 21
BS3: 0,01 | BT3: 15
D4: REKAPITULACE STAVBY | AS4: v --- níže se nacházejí doplnkové a pomocné údaje k sestavám --- v | BE4: Návod na vyplnění | BS4: 0,001
D5: Kód: | K5: 2023/003 | BE5: Měnit lze pouze buňky se žlutým podbarvením!_x000D_ _x000D_ 1) v Rekapitulaci stavby vyplňte údaje o Uchazeči (přenesou se do ostatních sestav i v jiných listech)_x000D_ _x000D_ 2) na vybraných listech vyplňte v sestavě Soupis prací ceny u položek | BS5: 0,01
D6: Stavba: | K6: SKLAD ŠKROBU P-001 | BS6: 0,01
D7: KSO: | AK7: CC-CZ: | BS7: 0,01
D8: Místo: | AK8: Datum: | AN8: 45167 | BS8: 0,01
BS9: 0,01
D10: Zadavatel: | AK10: IČ: | BS10: 0,01
AK11: DIČ: | BS11: 0,01
BS12: 0,01
D13: Uchazeč: | AK13: IČ: | AN13: Vyplň údaj | BS13: 0,01
E14: Vyplň údaj | AK14: DIČ: | AN14: Vyplň údaj | BS14: 0,01
BS15: False
D16: Projektant: | AK16: IČ: | BS16: False
AK17: DIČ: | BS17: True
BS18: 0,01
D19: Zpracovatel: | AK19: IČ: | BS19: 0,01
E20: rostarek s.r.o. | AK20: DIČ: | BS20: False
D22: Poznámka:
E23: Soupis prací je sestaven s využitím Cenové soustavy ÚRS. Položky, které pochází z této cenové soustavy, jsou ve sloupci 'Cenová soustava' označeny popisem 'CS ÚRS' a úrovní příslušného kalendářního pololetí. Veškeré další informace vymezující popis a podmínky použití těchto položek z Cenové soustavy, které nejsou uvedeny přímo v soupisu prací, jsou neomezeně dálkově k dispozici na webu podminky.urs.cz.
D26: Cena bez DPH | AK26: =ROUND(AG54,2) -> 0
L28: Sazba daně | W28: Základ daně | AK28: Výše daně
D29: DPH | F29: základní | L29: 0.21 | W29: =ROUND(AZ54, 2) -> 0 | AK29: =ROUND(AV54, 2) -> 0
F30: snížená | L30: 0.15 | W30: =ROUND(BA54, 2) -> 0 | AK30: =ROUND(AW54, 2) -> 0
F31: zákl. přenesená | L31: 0.21 | W31: =ROUND(BB54, 2) -> 0 | AK31: 0
F32: sníž. přenesená | L32: 0.15 | W32: =ROUND(BC54, 2) -> 0 | AK32: 0
F33: nulová | L33: 0 | W33: =ROUND(BD54, 2) -> 0 | AK33: 0
D35: Cena s DPH | T35: v | X35: CZK | AK35: =SUM(AK26:AK33) -> 0
C42: REKAPITULACE OBJEKTŮ STAVBY A SOUPISŮ PRACÍ
C44: Kód: | L44: =K5 -> 2023/003
C45: Stavba: | L45: =K6 -> SKLAD ŠKROBU P-001
C47: Místo: | L47: =IF(K8="","",K8) | AI47: Datum: | AM47: =IF(AN8= "","",AN8) -> 45167
C49: Zadavatel: | L49: =IF(E11= "","",E11) | AI49: Projektant: | AM49: =IF(E17="","",E17) | AS49: Informatívní údaje z listů zakázek
C50: Uchazeč: | L50: =IF(E14= "Vyplň údaj","",E14) | AI50: Zpracovatel: | AM50: =IF(E20="","",E20) -> rostarek s.r.o.
C52: Kód | I52: Popis | AG52: Cena bez DPH [CZK] | AN52: Cena s DPH [CZK] | AQ52: Typ | AS52: z toho Ostat._x000D_ náklady [CZK] | AT52: DPH [CZK] | AU52: Normohodiny [h] | AV52: DPH základní [CZK] | AW52: DPH snížená [CZK] | AX52: DPH základní přenesená_x000D_ [CZK] | AY52: DPH snížená přenesená_x000D_ [CZK] | AZ52: Základna_x000D_ DPH základní | BA52: Základna_x000D_ DPH snížená | BB52: Základna_x000D_ DPH zákl. přenesená | BC52: Základna_x000D_ DPH sníž. přenesená | BD52: Základna_x000D_ DPH nulová
C54: Náklady stavby celkem | AG54: =ROUND(AG55+SUM(AG56:AG61)+SUM(AG64:AG66),2) -> 0 | AN54: =SUM(AG54,AT54) -> 0 | AS54: =ROUND(AS55+SUM(AS56:AS61)+SUM(AS64:AS66),2) -> 0 | AT54: =ROUND(SUM(AV54:AW54),2) -> 0 | AU54: =ROUND(AU55+SUM(AU56:AU61)+SUM(AU64:AU66),5) -> 0 | AV54: =ROUND(AZ54*L29,2) -> 0 | AW54: =ROUND(BA54*L30,2) -> 0 | AX54: =ROUND(BB54*L29,2) -> 0 | AY54: =ROUND(BC54*L30,2) -> 0 | AZ54: =ROUND(AZ55+SUM(AZ56:AZ61)+SUM(AZ64:AZ66),2) -> 0 | BA54: =ROUND(BA55+SUM(BA56:BA61)+SUM(BA64:BA66),2) -> 0 | BB54: =ROUND(BB55+SUM(BB56:BB61)+SUM(BB64:BB66),2) -> 0 | BC54: =ROUND(BC55+SUM(BC56:BC61)+SUM(BC64:BC66),2) -> 0 | BD54: =ROUND(BD55+SUM(BD56:BD61)+SUM(BD64:BD66),2) -> 0 | BS54: D | BT54: 0 | BU54: ###NOIMPORT### | BV54: IMPORT | BW54: {fbc1a46a-d86b-4298-981e-dbf850c2ca92} | BX54: {00000000-0000-0000-0000-000000000000}
A55: / | D55: 2023/003/a | J55: SO-21 - Stavební a konstrukční část | AG55: ='2023-003-a - SO-21 - Stav...'!J30 -> 0 | AN55: =SUM(AG55,AT55) -> 0 | AQ55: STA | AS55: 0 | AT55: =ROUND(SUM(AV55:AW55),2) -> 0 | AU55: ='2023-003-a - SO-21 - Stav...'!P95 -> 0 | AV55: ='2023-003-a - SO-21 - Stav...'!J33 -> 0 | AW55: ='2023-003-a - SO-21 - Stav...'!J34 -> 0 | AX55: ='2023-003-a - SO-21 - Stav...'!J35 -> 0 | AY55: ='2023-003-a - SO-21 - Stav...'!J36 -> 0 | AZ55: ='2023-003-a - SO-21 - Stav...'!F33 -> 0 | BA55: ='2023-003-a - SO-21 - Stav...'!F34 -> 0 | BB55: ='2023-003-a - SO-21 - Stav...'!F35 -> 0 | BC55: ='2023-003-a - SO-21 - Stav...'!F36 -> 0 | BD55: ='2023-003-a - SO-21 - Stav...'!F37 -> 0 | BT55: 1 | BV55: IMPORT | BW55: {53e5e397-cbc3-4bfc-8477-08edf2619bcd} | BX55: {fbc1a46a-d86b-4298-981e-dbf850c2ca92} | CM55: 2
A56: / | D56: 2023/003/b | J56: SO-21 - Elektroinstalace | AG56: ='2023-003-b - SO-21 - Elek...'!J30 -> 0 | AN56: =SUM(AG56,AT56) -> 0 | AQ56: STA | AS56: 0 | AT56: =ROUND(SUM(AV56:AW56),2) -> 0 | AU56: ='2023-003-b - SO-21 - Elek...'!P87 -> 0 | AV56: ='2023-003-b - SO-21 - Elek...'!J33 -> 0 | AW56: ='2023-003-b - SO-21 - Elek...'!J34 -> 0 | AX56: ='2023-003-b - SO-21 - Elek...'!J35 -> 0 | AY56: ='2023-003-b - SO-21 - Elek...'!J36 -> 0 | AZ56: ='2023-003-b - SO-21 - Elek...'!F33 -> 0 | BA56: ='2023-003-b - SO-21 - Elek...'!F34 -> 0 | BB56: ='2023-003-b - SO-21 - Elek...'!F35 -> 0 | BC56: ='2023-003-b - SO-21 - Elek...'!F36 -> 0 | BD56: ='2023-003-b - SO-21 - Elek...'!F37 -> 0 | BT56: 1 | BV56: IMPORT | BW56: {50b00f3e-97d9-45c0-a5d5-471b4cac3b75} | BX56: {fbc1a46a-d86b-4298-981e-dbf850c2ca92} | CM56: 2
...

Sheet 2023-003-a - SO-21 - Stav...
L2: >> skryté sloupce << | AT2: {53e5e397-cbc3-4bfc-8477-08edf2619bcd}
AT3: 2
D4: KRYCÍ LIST SOUPISU PRACÍ | M4: v --- níže se nacházejí doplnkové a pomocné údaje k sestavám --- v | AT4: False
D6: Stavba:
E7: ='Rekapitulace stavby'!K6 -> SKLAD ŠKROBU P-001
D8: Objekt:
E9: 2023/003/a - SO-21 - Stavební a konstrukční část
D11: KSO: | I11: CC-CZ:
D12: Místo: | I12: Datum: | J12: ='Rekapitulace stavby'!AN8 -> 45167
D14: Zadavatel: | I14: IČ: | J14: =IF('Rekapitulace stavby'!AN10="","",'Rekapitulace stavby'!AN10)
E15: =IF('Rekapitulace stavby'!E11="","",'Rekapitulace stavby'!E11) | I15: DIČ: | J15: =IF('Rekapitulace stavby'!AN11="","",'Rekapitulace stavby'!AN11)
D17: Uchazeč: | I17: IČ: | J17: ='Rekapitulace stavby'!AN13 -> Vyplň údaj
E18: ='Rekapitulace stavby'!E14 -> Vyplň údaj | I18: DIČ: | J18: ='Rekapitulace stavby'!AN14 -> Vyplň údaj
D20: Projektant: | I20: IČ: | J20: =IF('Rekapitulace stavby'!AN16="","",'Rekapitulace stavby'!AN16)
E21: =IF('Rekapitulace stavby'!E17="","",'Rekapitulace stavby'!E17) | I21: DIČ: | J21: =IF('Rekapitulace stavby'!AN17="","",'Rekapitulace stavby'!AN17)
D23: Zpracovatel: | I23: IČ: | J23: =IF('Rekapitulace stavby'!AN19="","",'Rekapitulace stavby'!AN19)
E24: =IF('Rekapitulace stavby'!E20="","",'Rekapitulace stavby'!E20) -> rostarek s.r.o. | I24: DIČ: | J24: =IF('Rekapitulace stavby'!AN20="","",'Rekapitulace stavby'!AN20)
D26: Poznámka:
D30: Cena bez DPH | J30: =ROUND(J95, 2) -> 0
F32: Základ daně | I32: Sazba daně | J32: Výše daně
D33: DPH | E33: základní | F33: =ROUND((SUM(BE95:BE403)), 2) -> 0 | I33: 0.21 | J33: =ROUND(((SUM(BE95:BE403))*I33), 2) -> 0
E34: snížená | F34: =ROUND((SUM(BF95:BF403)), 2) -> 0 | I34: 0.15 | J34: =ROUND(((SUM(BF95:BF403))*I34), 2) -> 0
E35: zákl. přenesená | F35: =ROUND((SUM(BG95:BG403)), 2) -> 0 | I35: 0.21 | J35: =0 -> 0
E36: sníž. přenesená | F36: =ROUND((SUM(BH95:BH403)), 2) -> 0 | I36: 0.15 | J36: =0 -> 0
E37: nulová | F37: =ROUND((SUM(BI95:BI403)), 2) -> 0 | I37: 0 | J37: =0 -> 0
D39: Cena s DPH | G39: v | H39: CZK | J39: =SUM(J30:J37) -> 0
C45: REKAPITULACE ČLENĚNÍ SOUPISU PRACÍ
C47: Stavba:
E48: =E7 -> SKLAD ŠKROBU P-001
C49: Objekt:
E50: =E9 -> 2023/003/a - SO-21 - Stavební a konstrukční část
C52: Místo: | F52: =F12 | I52: Datum: | J52: =IF(J12="","",J12) -> 45167
C54: Zadavatel: | F54: =E15 | I54: Projektant: | J54: =E21
C55: Uchazeč: | F55: =IF(E18="","",E18) -> Vyplň údaj | I55: Zpracovatel: | J55: =E24 -> rostarek s.r.o.
C57: Kód dílu - Popis | J57: Cena celkem [CZK]
C59: Náklady stavby celkem | J59: =J95 -> 0 | AU59: -1
D60: HSV - HSV | J60: =J96 -> 0
D61: 1 - Zemní práce | J61: =J97 -> 0
D62: 2 - Zakládání | J62: =J120 -> 0
D63: 3 - Svislé a kompletní konstrukce | J63: =J201 -> 0
...

Sheet 2023-003-b - SO-21 - Elek...
L2: >> skryté sloupce << | AT2: {50b00f3e-97d9-45c0-a5d5-471b4cac3b75}
AT3: 2
D4: KRYCÍ LIST SOUPISU PRACÍ | M4: v --- níže se nacházejí doplnkové a pomocné údaje k sestavám --- v | AT4: False
D6: Stavba:
E7: ='Rekapitulace stavby'!K6 -> SKLAD ŠKROBU P-001
D8: Objekt:
E9: 2023/003/b - SO-21 - Elektroinstalace
D11: KSO: | I11: CC-CZ:
D12: Místo: | I12: Datum: | J12: ='Rekapitulace stavby'!AN8 -> 45167
D14: Zadavatel: | I14: IČ: | J14: =IF('Rekapitulace stavby'!AN10="","",'Rekapitulace stavby'!AN10)
E15: =IF('Rekapitulace stavby'!E11="","",'Rekapitulace stavby'!E11) | I15: DIČ: | J15: =IF('Rekapitulace stavby'!AN11="","",'Rekapitulace stavby'!AN11)
D17: Uchazeč: | I17: IČ: | J17: ='Rekapitulace stavby'!AN13 -> Vyplň údaj
E18: ='Rekapitulace stavby'!E14 -> Vyplň údaj | I18: DIČ: | J18: ='Rekapitulace stavby'!AN14 -> Vyplň údaj
D20: Projektant: | I20: IČ: | J20: =IF('Rekapitulace stavby'!AN16="","",'Rekapitulace stavby'!AN16)
E21: =IF('Rekapitulace stavby'!E17="","",'Rekapitulace stavby'!E17) | I21: DIČ: | J21: =IF('Rekapitulace stavby'!AN17="","",'Rekapitulace stavby'!AN17)
D23: Zpracovatel: | I23: IČ: | J23: =IF('Rekapitulace stavby'!AN19="","",'Rekapitulace stavby'!AN19)
E24: =IF('Rekapitulace stavby'!E20="","",'Rekapitulace stavby'!E20) -> rostarek s.r.o. | I24: DIČ: | J24: =IF('Rekapitulace stavby'!AN20="","",'Rekapitulace stavby'!AN20)
D26: Poznámka:
D30: Cena bez DPH | J30: =ROUND(J87, 2) -> 0
F32: Základ daně | I32: Sazba daně | J32: Výše daně
D33: DPH | E33: základní | F33: =ROUND((SUM(BE87:BE242)), 2) -> 0 | I33: 0.21 | J33: =ROUND(((SUM(BE87:BE242))*I33), 2) -> 0
E34: snížená | F34: =ROUND((SUM(BF87:BF242)), 2) -> 0 | I34: 0.15 | J34: =ROUND(((SUM(BF87:BF242))*I34), 2) -> 0
E35: zákl. přenesená | F35: =ROUND((SUM(BG87:BG242)), 2) -> 0 | I35: 0.21 | J35: =0 -> 0
E36: sníž. přenesená | F36: =ROUND((SUM(BH87:BH242)), 2) -> 0 | I36: 0.15 | J36: =0 -> 0
E37: nulová | F37: =ROUND((SUM(BI87:BI242)), 2) -> 0 | I37: 0 | J37: =0 -> 0
D39: Cena s DPH | G39: v | H39: CZK | J39: =SUM(J30:J37) -> 0
C45: REKAPITULACE ČLENĚNÍ SOUPISU PRACÍ
C47: Stavba:
E48: =E7 -> SKLAD ŠKROBU P-001
C49: Objekt:
E50: =E9 -> 2023/003/b - SO-21 - Elektroinstalace
C52: Místo: | F52: =F12 | I52: Datum: | J52: =IF(J12="","",J12) -> 45167
C54: Zadavatel: | F54: =E15 | I54: Projektant: | J54: =E21
C55: Uchazeč: | F55: =IF(E18="","",E18) -> Vyplň údaj | I55: Zpracovatel: | J55: =E24 -> rostarek s.r.o.
C57: Kód dílu - Popis | J57: Cena celkem [CZK]
C59: Náklady stavby celkem | J59: =J87 -> 0 | AU59: -1
D60: 741 - Elektroinstalace | J60: =J88 -> 0
D61: D1 - Projektové práce | J61: =J89 -> 0
D62: D2 - Výroba a dodávka rozváděče | J62: =J91 -> 0
D63: D3 - Materiál a montážní práce | J63: =J146 -> 0
...

Sheet 2023-003-c - SO-21 - Zdra...
L2: >> skryté sloupce << | AT2: {641cb51b-4565-4279-be31-dc176f3dc517}
AT3: 2
D4: KRYCÍ LIST SOUPISU PRACÍ | M4: v --- níže se nacházejí doplnkové a pomocné údaje k sestavám --- v | AT4: False
D6: Stavba:
E7: ='Rekapitulace stavby'!K6 -> SKLAD ŠKROBU P-001
D8: Objekt:
E9: 2023/003/c - SO-21 - Zdravotechnika
D11: KSO: | I11: CC-CZ:
D12: Místo: | I12: Datum: | J12: ='Rekapitulace stavby'!AN8 -> 45167
D14: Zadavatel: | I14: IČ: | J14: =IF('Rekapitulace stavby'!AN10="","",'Rekapitulace stavby'!AN10)
E15: =IF('Rekapitulace stavby'!E11="","",'Rekapitulace stavby'!E11) | I15: DIČ: | J15: =IF('Rekapitulace stavby'!AN11="","",'Rekapitulace stavby'!AN11)
D17: Uchazeč: | I17: IČ: | J17: ='Rekapitulace stavby'!AN13 -> Vyplň údaj
E18: ='Rekapitulace stavby'!E14 -> Vyplň údaj | I18: DIČ: | J18: ='Rekapitulace stavby'!AN14 -> Vyplň údaj
D20: Projektant: | I20: IČ: | J20: =IF('Rekapitulace stavby'!AN16="","",'Rekapitulace stavby'!AN16)
E21: =IF('Rekapitulace stavby'!E17="","",'Rekapitulace stavby'!E17) | I21: DIČ: | J21: =IF('Rekapitulace stavby'!AN17="","",'Rekapitulace stavby'!AN17)
D23: Zpracovatel: | I23: IČ: | J23: =IF('Rekapitulace stavby'!AN19="","",'Rekapitulace stavby'!AN19)
E24: =IF('Rekapitulace stavby'!E20="","",'Rekapitulace stavby'!E20) -> rostarek s.r.o. | I24: DIČ: | J24: =IF('Rekapitulace stavby'!AN20="","",'Rekapitulace stavby'!AN20)
D26: Poznámka:
D30: Cena bez DPH | J30: =ROUND(J86, 2) -> 0
F32: Základ daně | I32: Sazba daně | J32: Výše daně
D33: DPH | E33: základní | F33: =ROUND((SUM(BE86:BE113)), 2) -> 0 | I33: 0.21 | J33: =ROUND(((SUM(BE86:BE113))*I33), 2) -> 0
E34: snížená | F34: =ROUND((SUM(BF86:BF113)), 2) -> 0 | I34: 0.15 | J34: =ROUND(((SUM(BF86:BF113))*I34), 2) -> 0
E35: zákl. přenesená | F35: =ROUND((SUM(BG86:BG113)), 2) -> 0 | I35: 0.21 | J35: =0 -> 0
E36: sníž. přenesená | F36: =ROUND((SUM(BH86:BH113)), 2) -> 0 | I36: 0.15 | J36: =0 -> 0
E37: nulová | F37: =ROUND((SUM(BI86:BI113)), 2) -> 0 | I37: 0 | J37: =0 -> 0
D39: Cena s DPH | G39: v | H39: CZK | J39: =SUM(J30:J37) -> 0
C45: REKAPITULACE ČLENĚNÍ SOUPISU PRACÍ
C47: Stavba:
E48: =E7 -> SKLAD ŠKROBU P-001
C49: Objekt:
E50: =E9 -> 2023/003/c - SO-21 - Zdravotechnika
C52: Místo: | F52: =F12 | I52: Datum: | J52: =IF(J12="","",J12) -> 45167
C54: Zadavatel: | F54: =E15 | I54: Projektant: | J54: =E21
C55: Uchazeč: | F55: =IF(E18="","",E18) -> Vyplň údaj | I55: Zpracovatel: | J55: =E24 -> rostarek s.r.o.
C57: Kód dílu - Popis | J57: Cena celkem [CZK]
C59: Náklady stavby celkem | J59: =J86 -> 0 | AU59: -1
D60: D1 - Zdravotně technické instalace | J60: =J87 -> 0
D61: D2 - A.) Vodovod | J61: =J88 -> 0
D62: D3 - 1.) Potrubí (včetně tvarovek montáže a upevnění) | J62: =J89 -> 0
D63: D4 - Potrubí pro uloženi do země | J63: =J95 -> 0
...

Sheet 2023-003-d - SO-21 - Vytá...
L2: >> skryté sloupce << | AT2: {2b14f685-7267-4df4-b1e2-07fb37b9630f}
AT3: 2
D4: KRYCÍ LIST SOUPISU PRACÍ | M4: v --- níže se nacházejí doplnkové a pomocné údaje k sestavám --- v | AT4: False
D6: Stavba:
E7: ='Rekapitulace stavby'!K6 -> SKLAD ŠKROBU P-001
D8: Objekt:
E9: 2023/003/d - SO-21 - Vytápění
D11: KSO: | I11: CC-CZ:
D12: Místo: | I12: Datum: | J12: ='Rekapitulace stavby'!AN8 -> 45167
D14: Zadavatel: | I14: IČ: | J14: =IF('Rekapitulace stavby'!AN10="","",'Rekapitulace stavby'!AN10)
E15: =IF('Rekapitulace stavby'!E11="","",'Rekapitulace stavby'!E11) | I15: DIČ: | J15: =IF('Rekapitulace stavby'!AN11="","",'Rekapitulace stavby'!AN11)
D17: Uchazeč: | I17: IČ: | J17: ='Rekapitulace stavby'!AN13 -> Vyplň údaj
E18: ='Rekapitulace stavby'!E14 -> Vyplň údaj | I18: DIČ: | J18: ='Rekapitulace stavby'!AN14 -> Vyplň údaj
D20: Projektant: | I20: IČ: | J20: =IF('Rekapitulace stavby'!AN16="","",'Rekapitulace stavby'!AN16)
E21: =IF('Rekapitulace stavby'!E17="","",'Rekapitulace stavby'!E17) | I21: DIČ: | J21: =IF('Rekapitulace stavby'!AN17="","",'Rekapitulace stavby'!AN17)
D23: Zpracovatel: | I23: IČ: | J23: =IF('Rekapitulace stavby'!AN19="","",'Rekapitulace stavby'!AN19)
E24: =IF('Rekapitulace stavby'!E20="","",'Rekapitulace stavby'!E20) -> rostarek s.r.o. | I24: DIČ: | J24: =IF('Rekapitulace stavby'!AN20="","",'Rekapitulace stavby'!AN20)
D26: Poznámka:
D30: Cena bez DPH | J30: =ROUND(J83, 2) -> 0
F32: Základ daně | I32: Sazba daně | J32: Výše daně
D33: DPH | E33: základní | F33: =ROUND((SUM(BE83:BE101)), 2) -> 0 | I33: 0.21 | J33: =ROUND(((SUM(BE83:BE101))*I33), 2) -> 0
E34: snížená | F34: =ROUND((SUM(BF83:BF101)), 2) -> 0 | I34: 0.15 | J34: =ROUND(((SUM(BF83:BF101))*I34), 2) -> 0
E35: zákl. přenesená | F35: =ROUND((SUM(BG83:BG101)), 2) -> 0 | I35: 0.21 | J35: =0 -> 0
E36: sníž. přenesená | F36: =ROUND((SUM(BH83:BH101)), 2) -> 0 | I36: 0.15 | J36: =0 -> 0
E37: nulová | F37: =ROUND((SUM(BI83:BI101)), 2) -> 0 | I37: 0 | J37: =0 -> 0
D39: Cena s DPH | G39: v | H39: CZK | J39: =SUM(J30:J37) -> 0
C45: REKAPITULACE ČLENĚNÍ SOUPISU PRACÍ
C47: Stavba:
E48: =E7 -> SKLAD ŠKROBU P-001
C49: Objekt:
E50: =E9 -> 2023/003/d - SO-21 - Vytápění
C52: Místo: | F52: =F12 | I52: Datum: | J52: =IF(J12="","",J12) -> 45167
C54: Zadavatel: | F54: =E15 | I54: Projektant: | J54: =E21
C55: Uchazeč: | F55: =IF(E18="","",E18) -> Vyplň údaj | I55: Zpracovatel: | J55: =E24 -> rostarek s.r.o.
C57: Kód dílu - Popis | J57: Cena celkem [CZK]
C59: Náklady stavby celkem | J59: =J83 -> 0 | AU59: -1
D60: 731 - Ústřední vytápění | J60: =J84 -> 0
D61: D1 - Hala 1.01 | J61: =J85 -> 0
D62: D2 - Hala 1.02 | J62: =J90 -> 0
D63: D3 - Ostatní | J63: =J100 -> 0
...

Sheet 2023-003-i - SO-21 - bles...
L2: >> skryté sloupce << | AT2: {d837e52b-1dfb-4487-ba6f-fec39e2311eb}
AT3: 2
D4: KRYCÍ LIST SOUPISU PRACÍ | M4: v --- níže se nacházejí doplnkové a pomocné údaje k sestavám --- v | AT4: False
D6: Stavba:
E7: ='Rekapitulace stavby'!K6 -> SKLAD ŠKROBU P-001
D8: Objekt:
E9: 2023/003/i - SO-21 - bleskosvod a uzemnění
D11: KSO: | I11: CC-CZ:
D12: Místo: | I12: Datum: | J12: ='Rekapitulace stavby'!AN8 -> 45167
D14: Zadavatel: | I14: IČ: | J14: =IF('Rekapitulace stavby'!AN10="","",'Rekapitulace stavby'!AN10)
E15: =IF('Rekapitulace stavby'!E11="","",'Rekapitulace stavby'!E11) | I15: DIČ: | J15: =IF('Rekapitulace stavby'!AN11="","",'Rekapitulace stavby'!AN11)
D17: Uchazeč: | I17: IČ: | J17: ='Rekapitulace stavby'!AN13 -> Vyplň údaj
E18: ='Rekapitulace stavby'!E14 -> Vyplň údaj | I18: DIČ: | J18: ='Rekapitulace stavby'!AN14 -> Vyplň údaj
D20: Projektant: | I20: IČ: | J20: =IF('Rekapitulace stavby'!AN16="","",'Rekapitulace stavby'!AN16)
E21: =IF('Rekapitulace stavby'!E17="","",'Rekapitulace stavby'!E17) | I21: DIČ: | J21: =IF('Rekapitulace stavby'!AN17="","",'Rekapitulace stavby'!AN17)
D23: Zpracovatel: | I23: IČ: | J23: =IF('Rekapitulace stavby'!AN19="","",'Rekapitulace stavby'!AN19)
E24: =IF('Rekapitulace stavby'!E20="","",'Rekapitulace stavby'!E20) -> rostarek s.r.o. | I24: DIČ: | J24: =IF('Rekapitulace stavby'!AN20="","",'Rekapitulace stavby'!AN20)
D26: Poznámka:
D30: Cena bez DPH | J30: =ROUND(J82, 2) -> 0
F32: Základ daně | I32: Sazba daně | J32: Výše daně
D33: DPH | E33: základní | F33: =ROUND((SUM(BE82:BE102)), 2) -> 0 | I33: 0.21 | J33: =ROUND(((SUM(BE82:BE102))*I33), 2) -> 0
E34: snížená | F34: =ROUND((SUM(BF82:BF102)), 2) -> 0 | I34: 0.15 | J34: =ROUND(((SUM(BF82:BF102))*I34), 2) -> 0
E35: zákl. přenesená | F35: =ROUND((SUM(BG82:BG102)), 2) -> 0 | I35: 0.21 | J35: =0 -> 0
E36: sníž. přenesená | F36: =ROUND((SUM(BH82:BH102)), 2) -> 0 | I36: 0.15 | J36: =0 -> 0
E37: nulová | F37: =ROUND((SUM(BI82:BI102)), 2) -> 0 | I37: 0 | J37: =0 -> 0
D39: Cena s DPH | G39: v | H39: CZK | J39: =SUM(J30:J37) -> 0
C45: REKAPITULACE ČLENĚNÍ SOUPISU PRACÍ
C47: Stavba:
E48: =E7 -> SKLAD ŠKROBU P-001
C49: Objekt:
E50: =E9 -> 2023/003/i - SO-21 - bleskosvod a uzemnění
C52: Místo: | F52: =F12 | I52: Datum: | J52: =IF(J12="","",J12) -> 45167
C54: Zadavatel: | F54: =E15 | I54: Projektant: | J54: =E21
C55: Uchazeč: | F55: =IF(E18="","",E18) -> Vyplň údaj | I55: Zpracovatel: | J55: =E24 -> rostarek s.r.o.
C57: Kód dílu - Popis | J57: Cena celkem [CZK]
C59: Náklady stavby celkem | J59: =J82 -> 0 | AU59: -1
D60: D1 - BLESKOSVOD VČETNĚ MONTÁŽE A ZAPOJENÍ | J60: =J83 -> 0
D61: D2 - UZEMNĚNÍ VČETNĚ MONTÁŽE A ZAPOJENÍ | J61: =J95 -> 0
D62: D3 - OSTATNÍ | J62: =J99 -> 0
C69: SOUPIS PRACÍ
...

Sheet 2023-003-g - SO-22 - potr...
L2: >> skryté sloupce << | AT2: {eb70109f-0aaf-4741-af75-0f88da17f835}
AT3: 2
D4: KRYCÍ LIST SOUPISU PRACÍ | M4: v --- níže se nacházejí doplnkové a pomocné údaje k sestavám --- v | AT4: False
D6: Stavba:
E7: ='Rekapitulace stavby'!K6 -> SKLAD ŠKROBU P-001
D8: Objekt:
E9: 2023/003/g - SO-22 - potrubní a kabelový most
D11: KSO: | I11: CC-CZ:
D12: Místo: | I12: Datum: | J12: ='Rekapitulace stavby'!AN8 -> 45167
D14: Zadavatel: | I14: IČ: | J14: =IF('Rekapitulace stavby'!AN10="","",'Rekapitulace stavby'!AN10)
E15: =IF('Rekapitulace stavby'!E11="","",'Rekapitulace stavby'!E11) | I15: DIČ: | J15: =IF('Rekapitulace stavby'!AN11="","",'Rekapitulace stavby'!AN11)
D17: Uchazeč: | I17: IČ: | J17: ='Rekapitulace stavby'!AN13 -> Vyplň údaj
E18: ='Rekapitulace stavby'!E14 -> Vyplň údaj | I18: DIČ: | J18: ='Rekapitulace stavby'!AN14 -> Vyplň údaj
D20: Projektant: | I20: IČ: | J20: =IF('Rekapitulace stavby'!AN16="","",'Rekapitulace stavby'!AN16)
E21: =IF('Rekapitulace stavby'!E17="","",'Rekapitulace stavby'!E17) | I21: DIČ: | J21: =IF('Rekapitulace stavby'!AN17="","",'Rekapitulace stavby'!AN17)
D23: Zpracovatel: | I23: IČ: | J23: =IF('Rekapitulace stavby'!AN19="","",'Rekapitulace stavby'!AN19)
E24: =IF('Rekapitulace stavby'!E20="","",'Rekapitulace stavby'!E20) -> rostarek s.r.o. | I24: DIČ: | J24: =IF('Rekapitulace stavby'!AN20="","",'Rekapitulace stavby'!AN20)
D26: Poznámka:
D30: Cena bez DPH | J30: =ROUND(J87, 2) -> 0
F32: Základ daně | I32: Sazba daně | J32: Výše daně
D33: DPH | E33: základní | F33: =ROUND((SUM(BE87:BE149)), 2) -> 0 | I33: 0.21 | J33: =ROUND(((SUM(BE87:BE149))*I33), 2) -> 0
E34: snížená | F34: =ROUND((SUM(BF87:BF149)), 2) -> 0 | I34: 0.15 | J34: =ROUND(((SUM(BF87:BF149))*I34), 2) -> 0
E35: zákl. přenesená | F35: =ROUND((SUM(BG87:BG149)), 2) -> 0 | I35: 0.21 | J35: =0 -> 0
E36: sníž. přenesená | F36: =ROUND((SUM(BH87:BH149)), 2) -> 0 | I36: 0.15 | J36: =0 -> 0
E37: nulová | F37: =ROUND((SUM(BI87:BI149)), 2) -> 0 | I37: 0 | J37: =0 -> 0
D39: Cena s DPH | G39: v | H39: CZK | J39: =SUM(J30:J37) -> 0
C45: REKAPITULACE ČLENĚNÍ SOUPISU PRACÍ
C47: Stavba:
E48: =E7 -> SKLAD ŠKROBU P-001
C49: Objekt:
E50: =E9 -> 2023/003/g - SO-22 - potrubní a kabelový most
C52: Místo: | F52: =F12 | I52: Datum: | J52: =IF(J12="","",J12) -> 45167
C54: Zadavatel: | F54: =E15 | I54: Projektant: | J54: =E21
C55: Uchazeč: | F55: =IF(E18="","",E18) -> Vyplň údaj | I55: Zpracovatel: | J55: =E24 -> rostarek s.r.o.
C57: Kód dílu - Popis | J57: Cena celkem [CZK]
C59: Náklady stavby celkem | J59: =J87 -> 0 | AU59: -1
D60: HSV - Práce a dodávky HSV | J60: =J88 -> 0
D61: 1 - Zemní práce | J61: =J89 -> 0
D62: 2 - Zakládání | J62: =J112 -> 0
D63: 9 - Ostatní konstrukce a práce, bourání | J63: =J127 -> 0
...

Sheet a - příprava území
L2: >> skryté sloupce << | AT2: {66a5eeed-aeda-4080-92f4-4cf56af3aa82}
AT3: 2
D4: KRYCÍ LIST SOUPISU PRACÍ | M4: v --- níže se nacházejí doplnkové a pomocné údaje k sestavám --- v | AT4: False
D6: Stavba:
E7: ='Rekapitulace stavby'!K6 -> SKLAD ŠKROBU P-001
D8: Objekt:
E9: 2023/003/h - SO-23 - Nové zpevněné plochy
D10: Soupis:
E11: a - příprava území
D13: KSO: | I13: CC-CZ:
D14: Místo: | F14: Horažďovice | I14: Datum: | J14: ='Rekapitulace stavby'!AN8 -> 45167
D16: Zadavatel: | I16: IČ:
I17: DIČ:
D19: Uchazeč: | I19: IČ: | J19: ='Rekapitulace stavby'!AN13 -> Vyplň údaj
E20: ='Rekapitulace stavby'!E14 -> Vyplň údaj | I20: DIČ: | J20: ='Rekapitulace stavby'!AN14 -> Vyplň údaj
D22: Projektant: | I22: IČ:
E23: VIAPROJEKT s.r.o. HK | I23: DIČ:
D25: Zpracovatel: | I25: IČ:
E26: B.Burešová | I26: DIČ:
D28: Poznámka:
D32: Cena bez DPH | J32: =ROUND(J90, 2) -> 0
F34: Základ daně | I34: Sazba daně | J34: Výše daně
D35: DPH | E35: základní | F35: =ROUND((SUM(BE90:BE267)), 2) -> 0 | I35: 0.21 | J35: =ROUND(((SUM(BE90:BE267))*I35), 2) -> 0
E36: snížená | F36: =ROUND((SUM(BF90:BF267)), 2) -> 0 | I36: 0.15 | J36: =ROUND(((SUM(BF90:BF267))*I36), 2) -> 0
E37: zákl. přenesená | F37: =ROUND((SUM(BG90:BG267)), 2) -> 0 | I37: 0.21 | J37: =0 -> 0
E38: sníž. přenesená | F38: =ROUND((SUM(BH90:BH267)), 2) -> 0 | I38: 0.15 | J38: =0 -> 0
E39: nulová | F39: =ROUND((SUM(BI90:BI267)), 2) -> 0 | I39: 0 | J39: =0 -> 0
D41: Cena s DPH | G41: v | H41: CZK | J41: =SUM(J32:J39) -> 0
C47: REKAPITULACE ČLENĚNÍ SOUPISU PRACÍ
C49: Stavba:
E50: =E7 -> SKLAD ŠKROBU P-001
C51: Objekt:
E52: 2023/003/h - SO-23 - Nové zpevněné plochy
C53: Soupis:
E54: =E11 -> a - příprava území
C56: Místo: | F56: =F14 -> Horažďovice | I56: Datum: | J56: =IF(J14="","",J14) -> 45167
C58: Zadavatel: | F58: =E17 | I58: Projektant: | J58: =E23 -> VIAPROJEKT s.r.o. HK
C59: Uchazeč: | F59: =IF(E20="","",E20) -> Vyplň údaj | I59: Zpracovatel: | J59: =E26 -> B.Burešová
C61: Kód dílu - Popis | J61: Cena celkem [CZK]
C63: Náklady stavby celkem | J63: =J90 -> 0 | AU63: -1
...

Sheet n - návrh
L2: >> skryté sloupce << | AT2: {ec803a29-6402-4ec0-9cad-f33d115efa9a}
AT3: 2
D4: KRYCÍ LIST SOUPISU PRACÍ | M4: v --- níže se nacházejí doplnkové a pomocné údaje k sestavám --- v | AT4: False
D6: Stavba:
E7: ='Rekapitulace stavby'!K6 -> SKLAD ŠKROBU P-001
D8: Objekt:
E9: 2023/003/h - SO-23 - Nové zpevněné plochy
D10: Soupis:
E11: n - návrh
D13: KSO: | I13: CC-CZ:
D14: Místo: | F14: Horažďovice | I14: Datum: | J14: ='Rekapitulace stavby'!AN8 -> 45167
D16: Zadavatel: | I16: IČ:
I17: DIČ:
D19: Uchazeč: | I19: IČ: | J19: ='Rekapitulace stavby'!AN13 -> Vyplň údaj
E20: ='Rekapitulace stavby'!E14 -> Vyplň údaj | I20: DIČ: | J20: ='Rekapitulace stavby'!AN14 -> Vyplň údaj
D22: Projektant: | I22: IČ:
E23: VIAPROJEKT s.r.o. HK | I23: DIČ:
D25: Zpracovatel: | I25: IČ:
E26: B.Burešová | I26: DIČ:
D28: Poznámka:
D32: Cena bez DPH | J32: =ROUND(J94, 2) -> 0
F34: Základ daně | I34: Sazba daně | J34: Výše daně
D35: DPH | E35: základní | F35: =ROUND((SUM(BE94:BE379)), 2) -> 0 | I35: 0.21 | J35: =ROUND(((SUM(BE94:BE379))*I35), 2) -> 0
E36: snížená | F36: =ROUND((SUM(BF94:BF379)), 2) -> 0 | I36: 0.15 | J36: =ROUND(((SUM(BF94:BF379))*I36), 2) -> 0
E37: zákl. přenesená | F37: =ROUND((SUM(BG94:BG379)), 2) -> 0 | I37: 0.21 | J37: =0 -> 0
E38: sníž. přenesená | F38: =ROUND((SUM(BH94:BH379)), 2) -> 0 | I38: 0.15 | J38: =0 -> 0
E39: nulová | F39: =ROUND((SUM(BI94:BI379)), 2) -> 0 | I39: 0 | J39: =0 -> 0
D41: Cena s DPH | G41: v | H41: CZK | J41: =SUM(J32:J39) -> 0
C47: REKAPITULACE ČLENĚNÍ SOUPISU PRACÍ
C49: Stavba:
E50: =E7 -> SKLAD ŠKROBU P-001
C51: Objekt:
E52: 2023/003/h - SO-23 - Nové zpevněné plochy
C53: Soupis:
E54: =E11 -> n - návrh
C56: Místo: | F56: =F14 -> Horažďovice | I56: Datum: | J56: =IF(J14="","",J14) -> 45167
C58: Zadavatel: | F58: =E17 | I58: Projektant: | J58: =E23 -> VIAPROJEKT s.r.o. HK
C59: Uchazeč: | F59: =IF(E20="","",E20) -> Vyplň údaj | I59: Zpracovatel: | J59: =E26 -> B.Burešová
C61: Kód dílu - Popis | J61: Cena celkem [CZK]
C63: Náklady stavby celkem | J63: =J94 -> 0 | AU63: -1
...

Sheet 2023-003-e - SO-24 - dešť...
L2: >> skryté sloupce << | AT2: {fdf8f8f9-a610-4ff3-8905-8fc590894e53}
AT3: 2
D4: KRYCÍ LIST SOUPISU PRACÍ | M4: v --- níže se nacházejí doplnkové a pomocné údaje k sestavám --- v | AT4: False
D6: Stavba:
E7: ='Rekapitulace stavby'!K6 -> SKLAD ŠKROBU P-001
D8: Objekt:
E9: 2023/003/e - SO-24 - dešťová kanalizace
D11: KSO: | I11: CC-CZ:
D12: Místo: | I12: Datum: | J12: ='Rekapitulace stavby'!AN8 -> 45167
D14: Zadavatel: | I14: IČ: | J14: =IF('Rekapitulace stavby'!AN10="","",'Rekapitulace stavby'!AN10)
E15: =IF('Rekapitulace stavby'!E11="","",'Rekapitulace stavby'!E11) | I15: DIČ: | J15: =IF('Rekapitulace stavby'!AN11="","",'Rekapitulace stavby'!AN11)
D17: Uchazeč: | I17: IČ: | J17: ='Rekapitulace stavby'!AN13 -> Vyplň údaj
E18: ='Rekapitulace stavby'!E14 -> Vyplň údaj | I18: DIČ: | J18: ='Rekapitulace stavby'!AN14 -> Vyplň údaj
D20: Projektant: | I20: IČ: | J20: =IF('Rekapitulace stavby'!AN16="","",'Rekapitulace stavby'!AN16)
E21: =IF('Rekapitulace stavby'!E17="","",'Rekapitulace stavby'!E17) | I21: DIČ: | J21: =IF('Rekapitulace stavby'!AN17="","",'Rekapitulace stavby'!AN17)
D23: Zpracovatel: | I23: IČ: | J23: =IF('Rekapitulace stavby'!AN19="","",'Rekapitulace stavby'!AN19)
E24: =IF('Rekapitulace stavby'!E20="","",'Rekapitulace stavby'!E20) -> rostarek s.r.o. | I24: DIČ: | J24: =IF('Rekapitulace stavby'!AN20="","",'Rekapitulace stavby'!AN20)
D26: Poznámka:
D30: Cena bez DPH | J30: =ROUND(J84, 2) -> 0
F32: Základ daně | I32: Sazba daně | J32: Výše daně
D33: DPH | E33: základní | F33: =ROUND((SUM(BE84:BE252)), 2) -> 0 | I33: 0.21 | J33: =ROUND(((SUM(BE84:BE252))*I33), 2) -> 0
E34: snížená | F34: =ROUND((SUM(BF84:BF252)), 2) -> 0 | I34: 0.15 | J34: =ROUND(((SUM(BF84:BF252))*I34), 2) -> 0
E35: zákl. přenesená | F35: =ROUND((SUM(BG84:BG252)), 2) -> 0 | I35: 0.21 | J35: =0 -> 0
E36: sníž. přenesená | F36: =ROUND((SUM(BH84:BH252)), 2) -> 0 | I36: 0.15 | J36: =0 -> 0
E37: nulová | F37: =ROUND((SUM(BI84:BI252)), 2) -> 0 | I37: 0 | J37: =0 -> 0
D39: Cena s DPH | G39: v | H39: CZK | J39: =SUM(J30:J37) -> 0
C45: REKAPITULACE ČLENĚNÍ SOUPISU PRACÍ
C47: Stavba:
E48: =E7 -> SKLAD ŠKROBU P-001
C49: Objekt:
E50: =E9 -> 2023/003/e - SO-24 - dešťová kanalizace
C52: Místo: | F52: =F12 | I52: Datum: | J52: =IF(J12="","",J12) -> 45167
C54: Zadavatel: | F54: =E15 | I54: Projektant: | J54: =E21
C55: Uchazeč: | F55: =IF(E18="","",E18) -> Vyplň údaj | I55: Zpracovatel: | J55: =E24 -> rostarek s.r.o.
C57: Kód dílu - Popis | J57: Cena celkem [CZK]
C59: Náklady stavby celkem | J59: =J84 -> 0 | AU59: -1
D60: HSV - Práce a dodávky HSV | J60: =J85 -> 0
D61: 1 - Zemní práce | J61: =J86 -> 0
D62: 4 - Vodorovné konstrukce | J62: =J165 -> 0
D63: 8 - Trubní vedení | J63: =J204 -> 0
...

Sheet 2023-003-f - SO-25 - vodo...
L2: >> skryté sloupce << | AT2: {ae5bc6d7-4b3b-4857-a451-ada928935e96}
AT3: 2
D4: KRYCÍ LIST SOUPISU PRACÍ | M4: v --- níže se nacházejí doplnkové a pomocné údaje k sestavám --- v | AT4: False
D6: Stavba:
E7: ='Rekapitulace stavby'!K6 -> SKLAD ŠKROBU P-001
D8: Objekt:
E9: 2023/003/f - SO-25 - vodovodní přípojka
D11: KSO: | I11: CC-CZ:
D12: Místo: | I12: Datum: | J12: ='Rekapitulace stavby'!AN8 -> 45167
D14: Zadavatel: | I14: IČ: | J14: =IF('Rekapitulace stavby'!AN10="","",'Rekapitulace stavby'!AN10)
E15: =IF('Rekapitulace stavby'!E11="","",'Rekapitulace stavby'!E11) | I15: DIČ: | J15: =IF('Rekapitulace stavby'!AN11="","",'Rekapitulace stavby'!AN11)
D17: Uchazeč: | I17: IČ: | J17: ='Rekapitulace stavby'!AN13 -> Vyplň údaj
E18: ='Rekapitulace stavby'!E14 -> Vyplň údaj | I18: DIČ: | J18: ='Rekapitulace stavby'!AN14 -> Vyplň údaj
D20: Projektant: | I20: IČ: | J20: =IF('Rekapitulace stavby'!AN16="","",'Rekapitulace stavby'!AN16)
E21: =IF('Rekapitulace stavby'!E17="","",'Rekapitulace stavby'!E17) | I21: DIČ: | J21: =IF('Rekapitulace stavby'!AN17="","",'Rekapitulace stavby'!AN17)
D23: Zpracovatel: | I23: IČ: | J23: =IF('Rekapitulace stavby'!AN19="","",'Rekapitulace stavby'!AN19)
E24: =IF('Rekapitulace stavby'!E20="","",'Rekapitulace stavby'!E20) -> rostarek s.r.o. | I24: DIČ: | J24: =IF('Rekapitulace stavby'!AN20="","",'Rekapitulace stavby'!AN20)
D26: Poznámka:
D30: Cena bez DPH | J30: =ROUND(J84, 2) -> 0
F32: Základ daně | I32: Sazba daně | J32: Výše daně
D33: DPH | E33: základní | F33: =ROUND((SUM(BE84:BE146)), 2) -> 0 | I33: 0.21 | J33: =ROUND(((SUM(BE84:BE146))*I33), 2) -> 0
E34: snížená | F34: =ROUND((SUM(BF84:BF146)), 2) -> 0 | I34: 0.15 | J34: =ROUND(((SUM(BF84:BF146))*I34), 2) -> 0
E35: zákl. přenesená | F35: =ROUND((SUM(BG84:BG146)), 2) -> 0 | I35: 0.21 | J35: =0 -> 0
E36: sníž. přenesená | F36: =ROUND((SUM(BH84:BH146)), 2) -> 0 | I36: 0.15 | J36: =0 -> 0
E37: nulová | F37: =ROUND((SUM(BI84:BI146)), 2) -> 0 | I37: 0 | J37: =0 -> 0
D39: Cena s DPH | G39: v | H39: CZK | J39: =SUM(J30:J37) -> 0
C45: REKAPITULACE ČLENĚNÍ SOUPISU PRACÍ
C47: Stavba:
E48: =E7 -> SKLAD ŠKROBU P-001
C49: Objekt:
E50: =E9 -> 2023/003/f - SO-25 - vodovodní přípojka
C52: Místo: | F52: =F12 | I52: Datum: | J52: =IF(J12="","",J12) -> 45167
C54: Zadavatel: | F54: =E15 | I54: Projektant: | J54: =E21
C55: Uchazeč: | F55: =IF(E18="","",E18) -> Vyplň údaj | I55: Zpracovatel: | J55: =E24 -> rostarek s.r.o.
C57: Kód dílu - Popis | J57: Cena celkem [CZK]
C59: Náklady stavby celkem | J59: =J84 -> 0 | AU59: -1
D60: HSV - Práce a dodávky HSV | J60: =J85 -> 0
D61: 1 - Zemní práce | J61: =J86 -> 0
D62: 5 - Komunikace pozemní | J62: =J121 -> 0
D63: 8 - Trubní vedení | J63: =J129 -> 0
...

Sheet 2023-003-j - VRN
L2: >> skryté sloupce << | AT2: {e2ca333b-ff34-4067-a476-6cbb4c6d3b36}
AT3: 2
D4: KRYCÍ LIST SOUPISU PRACÍ | M4: v --- níže se nacházejí doplnkové a pomocné údaje k sestavám --- v | AT4: False
D6: Stavba:
E7: ='Rekapitulace stavby'!K6 -> SKLAD ŠKROBU P-001
D8: Objekt:
E9: 2023/003/j - VRN
D11: KSO: | I11: CC-CZ:
D12: Místo: | I12: Datum: | J12: ='Rekapitulace stavby'!AN8 -> 45167
D14: Zadavatel: | I14: IČ: | J14: =IF('Rekapitulace stavby'!AN10="","",'Rekapitulace stavby'!AN10)
E15: =IF('Rekapitulace stavby'!E11="","",'Rekapitulace stavby'!E11) | I15: DIČ: | J15: =IF('Rekapitulace stavby'!AN11="","",'Rekapitulace stavby'!AN11)
D17: Uchazeč: | I17: IČ: | J17: ='Rekapitulace stavby'!AN13 -> Vyplň údaj
E18: ='Rekapitulace stavby'!E14 -> Vyplň údaj | I18: DIČ: | J18: ='Rekapitulace stavby'!AN14 -> Vyplň údaj
D20: Projektant: | I20: IČ: | J20: =IF('Rekapitulace stavby'!AN16="","",'Rekapitulace stavby'!AN16)
E21: =IF('Rekapitulace stavby'!E17="","",'Rekapitulace stavby'!E17) | I21: DIČ: | J21: =IF('Rekapitulace stavby'!AN17="","",'Rekapitulace stavby'!AN17)
D23: Zpracovatel: | I23: IČ: | J23: =IF('Rekapitulace stavby'!AN19="","",'Rekapitulace stavby'!AN19)
E24: =IF('Rekapitulace stavby'!E20="","",'Rekapitulace stavby'!E20) -> rostarek s.r.o. | I24: DIČ: | J24: =IF('Rekapitulace stavby'!AN20="","",'Rekapitulace stavby'!AN20)
D26: Poznámka:
D30: Cena bez DPH | J30: =ROUND(J83, 2) -> 0
F32: Základ daně | I32: Sazba daně | J32: Výše daně
D33: DPH | E33: základní | F33: =ROUND((SUM(BE83:BE95)), 2) -> 0 | I33: 0.21 | J33: =ROUND(((SUM(BE83:BE95))*I33), 2) -> 0
E34: snížená | F34: =ROUND((SUM(BF83:BF95)), 2) -> 0 | I34: 0.15 | J34: =ROUND(((SUM(BF83:BF95))*I34), 2) -> 0
E35: zákl. přenesená | F35: =ROUND((SUM(BG83:BG95)), 2) -> 0 | I35: 0.21 | J35: =0 -> 0
E36: sníž. přenesená | F36: =ROUND((SUM(BH83:BH95)), 2) -> 0 | I36: 0.15 | J36: =0 -> 0
E37: nulová | F37: =ROUND((SUM(BI83:BI95)), 2) -> 0 | I37: 0 | J37: =0 -> 0
D39: Cena s DPH | G39: v | H39: CZK | J39: =SUM(J30:J37) -> 0
C45: REKAPITULACE ČLENĚNÍ SOUPISU PRACÍ
C47: Stavba:
E48: =E7 -> SKLAD ŠKROBU P-001
C49: Objekt:
E50: =E9 -> 2023/003/j - VRN
C52: Místo: | F52: =F12 | I52: Datum: | J52: =IF(J12="","",J12) -> 45167
C54: Zadavatel: | F54: =E15 | I54: Projektant: | J54: =E21
C55: Uchazeč: | F55: =IF(E18="","",E18) -> Vyplň údaj | I55: Zpracovatel: | J55: =E24 -> rostarek s.r.o.
C57: Kód dílu - Popis | J57: Cena celkem [CZK]
C59: Náklady stavby celkem | J59: =J83 -> 0 | AU59: -1
D60: VRN - Vedlejší rozpočtové náklady | J60: =J84 -> 0
D61: VRN1 - Průzkumné, geodetické a projektové práce | J61: =J85 -> 0
D62: VRN3 - Zařízení staveniště | J62: =J88 -> 0
D63: VRN4 - Inženýrská činnost | J63: =J91 -> 0
...

Sheet Pokyny pro vyplnění
C3: Struktura údajů, formát souboru a metodika pro zpracování
C4: Struktura
C6: Soubor je složen ze záložky Rekapitulace stavby a záložek s názvem soupisu prací pro jednotlivé objekty ve formátu XLSX. Každá ze záložek přitom obsahuje
C7: ještě samostatné sestavy vymezené orámovaním a nadpisem sestavy.
C9: Rekapitulace stavby obsahuje sestavu Rekapitulace stavby a Rekapitulace objektů stavby a soupisů prací.
D10: V sestavě Rekapitulace stavby jsou uvedeny informace identifikující předmět veřejné zakázky na stavební práce, KSO, CC-CZ, CZ-CPV, CZ-CPA a rekapitulaci
D11: celkové nabídkové ceny uchazeče.
D13: Termínem "uchazeč" (resp. zhotovitel) se myslí "účastník zadávacího řízení" ve smyslu zákona o zadávání veřejných zakázek.
D15: V sestavě Rekapitulace objektů stavby a soupisů prací je uvedena rekapitulace stavebních objektů, inženýrských objektů, provozních souborů,
D16: vedlejších a ostatních nákladů a ostatních nákladů s rekapitulací nabídkové ceny za jednotlivé soupisy prací. Na základě údaje Typ je možné
D17: identifikovat, zda se jedná o objekt nebo soupis prací pro daný objekt:
E18: STA | F18: Stavební objekt pozemní
E19: ING | F19: Stavební objekt inženýrský
E20: PRO | F20: Provozní soubor
E21: VON | F21: Vedlejší a ostatní náklady
E22: OST | F22: Ostatní
E23: Soupis | F23: Soupis prací pro daný typ objektu
C25: Soupis prací pro jednotlivé objekty obsahuje sestavy Krycí list soupisu prací, Rekapitulace členění soupisu prací, Soupis prací. Za soupis prací může být považován
C26: i objekt stavby v případě, že neobsahuje podřízenou zakázku.
D27: Krycí list soupisu obsahuje rekapitulaci informací o předmětu veřejné zakázky ze sestavy Rekapitulace stavby, informaci o zařazení objektu do KSO,
D28: CC-CZ, CZ-CPV, CZ-CPA a rekapitulaci celkové nabídkové ceny uchazeče za aktuální soupis prací.
D30: Rekapitulace členění soupisu prací obsahuje rekapitulaci soupisu prací ve všech úrovních členění soupisu tak, jak byla tato členění použita (např.
D31: stavební díly, funkční díly, případně jiné členění) s rekapitulací nabídkové ceny.
D33: Soupis prací obsahuje položky veškerých stavebních nebo montážních prací, dodávek materiálů a služeb nezbytných pro zhotovení stavebního objektu,
D34: inženýrského objektu, provozního souboru, vedlejších a ostatních nákladů.
D35: Pro položky soupisu prací se zobrazují následující informace:
E36: PČ | G36: Pořadové číslo položky v aktuálním soupisu
E37: TYP | G37: Typ položky: K - konstrukce, M - materiál, PP - plný popis, PSC - poznámka k souboru cen, P - poznámka k položce, VV - výkaz výměr
E38: Kód | G38: Kód položky
E39: Popis | G39: Zkrácený popis položky
E40: MJ | G40: Měrná jednotka položky
E41: Množství | G41: Množství v měrné jednotce
E42: J.cena | G42: Jednotková cena položky. Zadaní může obsahovat namísto J.ceny sloupce J.materiál a J.montáž, jejichž součet definuje
G43: J.cenu položky.
E44: Cena celkem | G44: Celková cena položky daná jako součin množství a j.ceny
E45: Cenová soustava | G45: Příslušnost položky do cenové soustavy
D47: Ke každé položce soupisu prací se na samostatných řádcích může zobrazovat:
E48: Plný popis položky
E49: Poznámka k souboru cen a poznámka zadavatele
E50: Výkaz výměr
...
